Workbook

Sheet Instrucciones
A1: Planilla de sueldo y finiquito México 2026
A3: 1 | B3: Las celdas amarillas son para tus datos. Las verdes se calculan solas, con las fórmulas de la ley. A la derecha de cada hoja está el paso a paso de la cuenta.
A4: 2 | B4: «Sueldo neto»: pones tu sueldo bruto y te dice cuánto ISR y cuánto IMSS te descuentan, y cuánto recibes.
A5: 3 | B5: «Aguinaldo»: calcula tu aguinaldo completo o proporcional, la parte que no paga ISR y el ISR estimado.
A6: 4 | B6: «Finiquito y liquidación»: pones tus fechas y tu sueldo, y te dice el finiquito (salarios, aguinaldo, vacaciones y primas) y, si te despidieron sin causa justificada, la liquidación.
A7: 5 | B7: «Tablas oficiales» tiene cada valor oficial que usan las fórmulas, con el enlace a su fuente y la fecha en que lo verificamos. Los valores son los vigentes al 8/10/2026.
A8: 6 | B8: Cuando cambia un valor oficial, actualizamos la planilla y el mismo enlace de descarga te baja la versión nueva.
A10: Da los mismos números que las calculadoras gratuitas de calcularya.com. Antes de publicar cada versión, una verificación automática recalcula este archivo y lo compara con ellas.
A11: Es una referencia de cálculo con sus fuentes, no asesoría legal. Tu contrato o tu empresa pueden darte más que el mínimo de ley.
A12: Las fechas van como dd/mm/aaaa. Si tu Excel está en inglés y las lee al revés, escríbelas como aaaa-mm-dd.

Sheet Sueldo neto
A1: Sueldo neto: ISR, subsidio y cuotas del IMSS
E3: Paso a paso
A4: TUS DATOS
A5: Sueldo bruto del periodo | B5: 10000 | E5: Salario diario y salario mínimo
A6: Cada cuánto te pagan | B6: Quincenal | E6: Días del periodo | F6: =IF(B6="Mensual",30.4,IF(B6="Quincenal",15,IF(B6="Semanal",7,10)))
A7: Dónde trabajas | B7: Resto del país | E7: Divisor del salario diario (LFT art. 89) | F7: =IF(B6="Mensual",30,F6)
A8: Años que llevas en la empresa | B8: 1 | C8: Sirve para estimar tu salario base de cotización del IMSS. | E8: Salario diario | F8: =ROUND(B5/F7,2)
A9: Salario base de cotización diario (opcional) | C9: Viene en tu recibo de nómina como SBC. Si lo dejas vacío, se estima con las prestaciones mínimas de ley. | E9: Salario mínimo diario de tu zona | F9: =INDEX('Tablas oficiales'!$C$4:$C$5,MATCH(B7,'Tablas oficiales'!$B$4:$B$5,0))
E10: ¿Ganas el salario mínimo? | F10: =IF(F8<=F9,"Sí","No")
A11: TU RECIBO
A12: Salario diario | B12: =F8 | E12: ISR
A13: Salario base de cotización (IMSS) | B13: =ROUND(F24,2) | E13: ISR según la tarifa del periodo | F13: =IF(F10="Sí",0,ROUND(IF(B6="Semanal",IF(B5<=0,0,INDEX('Tablas oficiales'!$E$8:$E$18,IFERROR(MATCH(B5,'Tablas oficiales'!$B$8:$B$18,1),1))+(B5-INDEX('Tablas oficiales'!$B$8:$B$18,IFERROR(MATCH(B5,'Tablas oficiales'!$B$8:$B$18,1),1)))*INDEX('Tablas oficiales'!$D$8:$D$18,IFERROR(MATCH(B5,'Tablas oficiales'!$B$8:$B$18,1),1))/100),IF(B6="Decenal",IF(B5<=0,0,INDEX('Tablas oficiales'!$E$22:$E$32,IFERROR(MATCH(B5,'Tablas oficiales'!$B$22:$B$32,1),1))+(B5-INDEX('Tablas oficiales'!$B$22:$B$32,IFERROR(MATCH(B5,'Tablas oficiales'!$B$22:$B$32,1),1)))*INDEX('Tablas oficiales'!$D$22:$D$32,IFERROR(MATCH(B5,'Tablas oficiales'!$B$22:$B$32,1),1))/100),IF(B6="Quincenal",IF(B5<=0,0,INDEX('Tablas oficiales'!$E$36:$E$46,IFERROR(MATCH(B5,'Tablas oficiales'!$B$36:$B$46,1),1))+(B5-INDEX('Tablas oficiales'!$B$36:$B$46,IFERROR(MATCH(B5,'Tablas oficiales'!$B$36:$B$46,1),1)))*INDEX('Tablas oficiales'!$D$36:$D$46,IFERROR(MATCH(B5,'Tablas oficiales'!$B$36:$B$46,1),1))/100),IF(B5<=0,0,INDEX('Tablas oficiales'!$E$50:$E$60,IFERROR(MATCH(B5,'Tablas oficiales'!$B$50:$B$60,1),1))+(B5-INDEX('Tablas oficiales'!$B$50:$B$60,IFERROR(MATCH(B5,'Tablas oficiales'!$B$50:$B$60,1),1)))*INDEX('Tablas oficiales'!$D$50:$D$60,IFERROR(MATCH(B5,'Tablas oficiales'!$B$50:$B$60,1),1))/100)))),2))
A14: ISR según la tarifa | B14: =F13 | E14: Subsidio para el empleo al mes | F14: ='Tablas oficiales'!$C$62*'Tablas oficiales'!$C$63/100
A15: Subsidio para el empleo | B15: =F17 | E15: Subsidio del periodo | F15: =IF(B6="Mensual",F14,F14/30.4*F6)
A16: ISR que te retienen | B16: =F18 | E16: Ingreso mensual | F16: =IF(B6="Mensual",B5,B5/F6*30.4)
A17: Cuotas del IMSS | B17: =F28 | E17: Subsidio que te toca | F17: =IF(F10="Sí",0,IF(F16<='Tablas oficiales'!$C$64,MIN(ROUND(F15,2),F13),0))
A18: Sueldo neto | B18: =ROUND(B5-F18-F28,2) | E18: ISR que te retienen | F18: =ROUND(F13-F17,2)
A20: Si ganas el salario mínimo no te retienen ISR y tu empresa paga tus cuotas del IMSS (LISR art. 96 y LSS art. 36). Si dejas vacío el SBC, se estima con 15 días de aguinaldo y la prima vacacional mínima. | E20: Cuotas del IMSS
E21: Días de vacaciones de tu año | F21: =IF(MAX(1,B8)<1,0,IF(MAX(1,B8)<=5,'Tablas oficiales'!$C$65+2*(MAX(1,B8)-1),'Tablas oficiales'!$C$65+8+2*ROUNDUP((MAX(1,B8)-5)/5,0)))
E22: Factor de integración | F22: =1+('Tablas oficiales'!$C$66+F21*'Tablas oficiales'!$C$67/100)/365
E23: SBC antes del tope | F23: =IF(ISNUMBER(B9),B9,ROUND(F8*F22,2))
E24: Salario base de cotización | F24: =MIN(MAX(F23,F9),'Tablas oficiales'!$C$69*'Tablas oficiales'!$C$68)
E25: Cuotas sobre el SBC (%) | F25: ='Tablas oficiales'!$C$71+'Tablas oficiales'!$C$72+'Tablas oficiales'!$C$73+'Tablas oficiales'!$C$74
E26: Excedente de 3 UMA | F26: =MAX(0,F24-'Tablas oficiales'!$C$75*'Tablas oficiales'!$C$68)
E27: IMSS por día | F27: =F24*F25/100+F26*'Tablas oficiales'!$C$70/100
E28: IMSS del periodo | F28: =IF(F10="Sí",0,ROUND(F27*F6,2))

Sheet Aguinaldo
A1: Aguinaldo: monto, parte exenta e ISR
E3: Paso a paso
A4: TUS DATOS
A5: Tu sueldo bruto | B5: 15000 | E5: Aguinaldo
A6: Ese sueldo es | B6: Al mes | E6: Salario diario | F6: =ROUND(B5/IF(B6="Al mes",30,IF(B6="A la quincena",15,IF(B6="A la semana",7,1))),2)
A7: Días que trabajaste este año | B7: 365 | C7: Si entraste a mitad de año, cuenta desde tu primer día. | E7: Días de aguinaldo | F7: =IF(ISNUMBER(B8),B8,'Tablas oficiales'!$C$66)
A8: Días de aguinaldo que da tu empresa (opcional) | C8: Déjalo vacío si no lo sabes: se usa el mínimo de ley. | E8: Aguinaldo bruto | F8: =ROUND(F6*F7*MIN(B7,365)/365,2)
A9: Dónde trabajas | B9: Resto del país | E9: Salario mínimo diario de tu zona | F9: =INDEX('Tablas oficiales'!$C$4:$C$5,MATCH(B9,'Tablas oficiales'!$B$4:$B$5,0))
E10: ¿Ganas el salario mínimo? | F10: =IF(F6<=F9,"Sí","No")
A11: TU AGUINALDO | E11: Tope exento (30 UMA) | F11: =ROUND('Tablas oficiales'!$C$76*'Tablas oficiales'!$C$68,2)
A12: =IF(AND(ISNUMBER(B8),B8<'Tablas oficiales'!$C$66),"La ley pide al menos "&'Tablas oficiales'!$C$66&" días de aguinaldo.","") | E12: Parte exenta | F12: =IF(F10="Sí",F8,MIN(F8,F11))
A13: Salario diario | B13: =F6 | E13: Parte gravada | F13: =ROUND(F8-F12,2)
A14: Días de aguinaldo por año completo | B14: =F7
A15: Aguinaldo bruto | B15: =F8 | E15: ISR del aguinaldo (artículo 96 de la LISR)
A16: Parte que no paga ISR | B16: =F12 | E16: Sueldo mensual (diario por 30.4) | F16: =ROUND(F6*30.4,2)
A17: Parte que paga ISR | B17: =F13 | E17: Subsidio para el empleo al mes | F17: ='Tablas oficiales'!$C$62*'Tablas oficiales'!$C$63/100
A18: ISR estimado | B18: =F23 | E18: Sueldo más aguinaldo gravado | F18: =F16+F13
A19: Aguinaldo que recibes | B19: =ROUND(F8-F23,2) | E19: ISR de sueldo más aguinaldo | F19: =ROUND(IF(F18<=0,0,INDEX('Tablas oficiales'!$E$50:$E$60,IFERROR(MATCH(F18,'Tablas oficiales'!$B$50:$B$60,1),1))+(F18-INDEX('Tablas oficiales'!$B$50:$B$60,IFERROR(MATCH(F18,'Tablas oficiales'!$B$50:$B$60,1),1)))*INDEX('Tablas oficiales'!$D$50:$D$60,IFERROR(MATCH(F18,'Tablas oficiales'!$B$50:$B$60,1),1))/100),2)
E20: Retención de sueldo más aguinaldo | F20: =ROUND(F19-IF(F18<='Tablas oficiales'!$C$64,MIN(ROUND(F17,2),F19),0),2)
A21: Se paga antes del 20 de diciembre (LFT art. 87). El ISR es una estimación: tu empresa puede usar otro método que permite la ley y el monto cambia un poco. | E21: ISR de solo el sueldo | F21: =ROUND(IF(F16<=0,0,INDEX('Tablas oficiales'!$E$50:$E$60,IFERROR(MATCH(F16,'Tablas oficiales'!$B$50:$B$60,1),1))+(F16-INDEX('Tablas oficiales'!$B$50:$B$60,IFERROR(MATCH(F16,'Tablas oficiales'!$B$50:$B$60,1),1)))*INDEX('Tablas oficiales'!$D$50:$D$60,IFERROR(MATCH(F16,'Tablas oficiales'!$B$50:$B$60,1),1))/100),2)
E22: Retención de solo el sueldo | F22: =ROUND(F21-IF(F16<='Tablas oficiales'!$C$64,MIN(ROUND(F17,2),F21),0),2)
E23: ISR del aguinaldo | F23: =IF(F13>0,ROUND(MAX(0,F20-F22),2),0)

Sheet Finiquito y liquidación
A1: Finiquito y liquidación por despido
E3: Paso a paso
A4: TUS DATOS
A5: Cómo termina tu trabajo | B5: Renuncié | E5: Antigüedad
A6: Tu sueldo bruto | B6: 15000 | E6: Años completos de servicio | F6: =IF(AND((YEAR(B9)-YEAR(B8))>0,DATE(YEAR(B8)+(YEAR(B9)-YEAR(B8)),MONTH(B8),MIN(DAY(B8),DAY(EOMONTH(DATE(YEAR(B8)+(YEAR(B9)-YEAR(B8)),MONTH(B8),1),0))))>B9+1),(YEAR(B9)-YEAR(B8))-1,(YEAR(B9)-YEAR(B8)))
A7: Ese sueldo es | B7: Al mes | E7: Días desde el último aniversario | F7: =B9+1-DATE(YEAR(B8)+F6,MONTH(B8),MIN(DAY(B8),DAY(EOMONTH(DATE(YEAR(B8)+F6,MONTH(B8),1),0))))
A8: Fecha en que entraste a trabajar | B8: 44986 | E8: Días trabajados este año | F8: =B9-MAX(B8,DATE(YEAR(B9),1,1))+1
A9: Último día de trabajo | B9: 46303 | E9: Antigüedad en años | F9: =F6+F7/365
A10: Dónde trabajas | B10: Resto del país | E10: Días de servicio | F10: =B9-B8+1
A11: Días trabajados que todavía no te pagan | B11: 0
A12: Días de vacaciones de años anteriores que no tomaste | B12: 0 | E12: Finiquito
A13: Días de aguinaldo que da tu empresa (opcional) | C13: Déjalo vacío si no lo sabes: se usa el mínimo de ley. | E13: Salario diario | F13: =ROUND(B6/IF(B7="Al mes",30,IF(B7="A la quincena",15,IF(B7="A la semana",7,1))),2)
A14: Prima vacacional que da tu empresa, en % (opcional) | C14: Déjalo vacío si no lo sabes: se usa el mínimo de ley. | E14: Días de aguinaldo | F14: =IF(ISNUMBER(B13),B13,'Tablas oficiales'!$C$66)
E15: Prima vacacional (%) | F15: =IF(ISNUMBER(B14),B14,'Tablas oficiales'!$C$67)
A16: TU FINIQUITO | E16: Días trabajados sin pagar | F16: =ROUND(F13*B11,2)
A17: =IF(AND(ISNUMBER(B13),B13<'Tablas oficiales'!$C$66),"La ley pide al menos "&'Tablas oficiales'!$C$66&" días de aguinaldo. ","")&IF(AND(ISNUMBER(B14),B14<'Tablas oficiales'!$C$67),"La prima vacacional no puede ser menor al "&'Tablas oficiales'!$C$67&" %.","") | E17: Aguinaldo proporcional | F17: =ROUND(F13*F14*MIN(F8,365)/365,2)
A18: Antigüedad | B18: =ROUND(F9,2) | C18: En años. | E18: Vacaciones del año en curso (días por año) | F18: =IF(F6+1<1,0,IF(F6+1<=5,'Tablas oficiales'!$C$65+2*(F6+1-1),'Tablas oficiales'!$C$65+8+2*ROUNDUP((F6+1-5)/5,0)))
A19: Salario diario | B19: =F13 | E19: Vacaciones proporcionales (días) | F19: =F18*F7/365
A20: Días trabajados sin pagar | B20: =F16 | E20: Vacaciones | F20: =ROUND(F13*(F19+B12),2)
A21: Aguinaldo proporcional | B21: =F17 | E21: Prima vacacional | F21: =ROUND(F20*F15/100,2)
A22: Vacaciones | B22: =F20 | E22: Salario mínimo diario de tu zona | F22: =INDEX('Tablas oficiales'!$C$4:$C$5,MATCH(B10,'Tablas oficiales'!$B$4:$B$5,0))
A23: Prima vacacional | B23: =F21 | E23: Salario para la prima de antigüedad | F23: =MIN(MAX(F13,F22),'Tablas oficiales'!$C$77*F22)
A24: Prima de antigüedad | B24: =F26 | C24: Al renunciar, solo con 15 años de servicio o más. | E24: Prima de antigüedad (12 días por año) | F24: =ROUND(F23*'Tablas oficiales'!$C$78*F9,2)
A25: Total del finiquito | B25: =ROUND(F16+F17+F20+F21+F26,2) | E25: ¿Se paga la prima de antigüedad? | F25: =IF(OR(B5="Me despidieron o terminó el contrato",F9>='Tablas oficiales'!$C$79),"Sí","No")
E26: Prima de antigüedad del finiquito | F26: =IF(F25="Sí",F24,0)
A27: SI TE DESPIDIERON SIN CAUSA JUSTIFICADA
A28: Salario diario integrado (opcional) | C28: Tu salario diario más la parte de aguinaldo, prima vacacional y otras prestaciones. Si lo dejas vacío, se usa tu salario diario. | E28: Liquidación
A29: Sumar los 20 días por año del artículo 50 | B29: No | C29: Proceden cuando la empresa se niega a reinstalarte o en los casos del artículo 49 de la ley. Muchas empresas los pagan al negociar. | E29: Salario diario para la indemnización | F29: =MAX(IF(ISNUMBER(B28),B28,F13),F13)
A30: Antigüedad | B30: =ROUND(F9,2) | C30: En años. | E30: Indemnización constitucional (3 meses) | F30: =ROUND(F29*'Tablas oficiales'!$C$80*30,2)
A31: Salario diario para la indemnización | B31: =ROUND(F29,2) | E31: Días por año de servicio | F31: =IF(B29="Sí",ROUND(F29*'Tablas oficiales'!$C$81*F9,2),0)
A32: Indemnización constitucional | B32: =F30 | E32: Pagos por separación | F32: =ROUND(F30+F31+F24,2)
A33: Días por año de servicio | B33: =F31 | E33: Años para la exención (más de 6 meses cuentan como año) | F33: =MAX(1,F6+IF(F7>182,1,0))
A34: Prima de antigüedad | B34: =F24 | E34: Parte exenta de ISR | F34: =MIN(F32,ROUND('Tablas oficiales'!$C$82*'Tablas oficiales'!$C$68*F33,2))
A35: Finiquito (salarios, aguinaldo y vacaciones) | B35: =F35 | E35: Finiquito sin prima de antigüedad | F35: =ROUND(F16+F17+F20+F21,2)
A36: Parte de la indemnización que no paga ISR | B36: =F34
A37: Total de la liquidación | B37: =ROUND(F32+F35,2)
A39: Los salarios vencidos (hasta 12 meses si llegas a juicio y lo ganas) no están incluidos. Son montos brutos: la parte de la indemnización que pasa el límite exento paga ISR.

Sheet Tablas oficiales
A1: Tablas oficiales de México
A2: Son los valores que usan las fórmulas de esta planilla, vigentes al 8/10/2026. Cada uno trae el enlace a la norma o al organismo que lo publica y la fecha en que lo verificamos.
A3: Dato | B3: Detalle | C3: Valor | D3: Unidad | E3: Vigente desde | F3: Fuente oficial | G3: Verificado el
A4: Salario mínimo general diario | B4: Resto del país | C4: 315.04 | D4: MXN | E4: 1/1/2026 | F4: https://dof.gob.mx/nota_detalle.php?codigo=5775534&fecha=09/12/2025 | G4: 7/10/2026
A5: Salario mínimo general diario | B5: Zona Libre de la Frontera Norte | C5: 440.87 | D5: MXN | E5: 1/1/2026 | F5: https://dof.gob.mx/nota_detalle.php?codigo=5775534&fecha=09/12/2025 | G5: 7/10/2026
A6: Tarifa de retención del ISR para pagos de 7 días | D6: MXN | E6: 1/1/2026 | F6: https://dof.gob.mx/nota_detalle.php?codigo=5777219&fecha=28/12/2025 | G6: 7/10/2026
B7: Desde | C7: Hasta | D7: Tasa % | E7: Cuota fija
B8: 0.01 | C8: 194.46 | D8: 1.92 | E8: 0
B9: 194.47 | C9: 1650.67 | D9: 6.4 | E9: 3.71
B10: 1650.68 | C10: 2900.87 | D10: 10.88 | E10: 96.95
B11: 2900.88 | C11: 3372.11 | D11: 16 | E11: 232.96
B12: 3372.12 | C12: 4037.32 | D12: 17.92 | E12: 308.35
B13: 4037.33 | C13: 8142.75 | D13: 21.36 | E13: 427.56
B14: 8142.76 | C14: 12834.08 | D14: 23.52 | E14: 1304.45
B15: 12834.09 | C15: 24502.45 | D15: 30 | E15: 2407.86
B16: 24502.46 | C16: 32669.91 | D16: 32 | E16: 5908.35
B17: 32669.92 | C17: 98009.66 | D17: 34 | E17: 8521.94
B18: 98009.67 | C18: 1e+15 | D18: 35 | E18: 30737.49
A20: Tarifa de retención del ISR para pagos de 10 días | D20: MXN | E20: 1/1/2026 | F20: https://dof.gob.mx/nota_detalle.php?codigo=5777219&fecha=28/12/2025 | G20: 7/10/2026
B21: Desde | C21: Hasta | D21: Tasa % | E21: Cuota fija
B22: 0.01 | C22: 277.8 | D22: 1.92 | E22: 0
B23: 277.81 | C23: 2358.1 | D23: 6.4 | E23: 5.3
B24: 2358.11 | C24: 4144.1 | D24: 10.88 | E24: 138.5
B25: 4144.11 | C25: 4817.3 | D25: 16 | E25: 332.8
B26: 4817.31 | C26: 5767.6 | D26: 17.92 | E26: 440.5
B27: 5767.61 | C27: 11632.5 | D27: 21.36 | E27: 610.8
B28: 11632.51 | C28: 18334.4 | D28: 23.52 | E28: 1863.5
B29: 18334.41 | C29: 35003.5 | D29: 30 | E29: 3439.8
B30: 35003.51 | C30: 46671.3 | D30: 32 | E30: 8440.5
B31: 46671.31 | C31: 140013.8 | D31: 34 | E31: 12174.2
B32: 140013.81 | C32: 1e+15 | D32: 35 | E32: 43910.7
A34: Tarifa de retención del ISR para pagos de 15 días | D34: MXN | E34: 1/1/2026 | F34: https://dof.gob.mx/nota_detalle.php?codigo=5777219&fecha=28/12/2025 | G34: 7/10/2026
B35: Desde | C35: Hasta | D35: Tasa % | E35: Cuota fija
B36: 0.01 | C36: 416.7 | D36: 1.92 | E36: 0
B37: 416.71 | C37: 3537.15 | D37: 6.4 | E37: 7.95
B38: 3537.16 | C38: 6216.15 | D38: 10.88 | E38: 207.75
B39: 6216.16 | C39: 7225.95 | D39: 16 | E39: 499.2
B40: 7225.96 | C40: 8651.4 | D40: 17.92 | E40: 660.75
B41: 8651.41 | C41: 17448.75 | D41: 21.36 | E41: 916.2
B42: 17448.76 | C42: 27501.6 | D42: 23.52 | E42: 2795.25
...
