Workbook

Sheet Instrucciones
A1: Planilla de prestaciones y liquidación Venezuela 2026
A3: 1 | B3: Las celdas amarillas son para tus datos. Las verdes se calculan solas, con las fórmulas de la ley. A la derecha de cada hoja está el paso a paso de la cuenta.
A4: 2 | B4: «Utilidades y vacaciones»: calcula las utilidades del año y el pago de vacaciones con su bono vacacional.
A5: 3 | B5: «Liquidación»: pones tus fechas y tu salario, y te dice las prestaciones sociales (garantía o retroactivo), la indemnización, las vacaciones y las utilidades fraccionadas.
A6: 4 | B6: «Tablas oficiales» tiene cada valor oficial que usan las fórmulas, con el enlace a su fuente y la fecha en que lo verificamos. Los valores son los vigentes al 16/10/2026.
A7: 5 | B7: Cuando cambia un valor oficial, actualizamos la planilla y el mismo enlace de descarga te baja la versión nueva.
A9: Da los mismos números que las calculadoras gratuitas de calcularya.com. Antes de publicar cada versión, una verificación automática recalcula este archivo y lo compara con ellas.
A10: Es una referencia de cálculo con sus fuentes, no asesoría legal. Tu contrato o tu empresa pueden darte más que el mínimo de ley.
A11: Las fechas van como dd/mm/aaaa. Si tu Excel está en inglés y las lee al revés, escríbelas como aaaa-mm-dd.

Sheet Utilidades y vacaciones
A1: Utilidades, vacaciones y bono vacacional
E3: Paso a paso
A4: TUS DATOS | E4: Salario diario (entre 30) | F4: =B6/'Tablas oficiales'!$C$4
A5: En qué moneda está tu salario | B5: Dólares ($) | C5: Los montos salen en la misma moneda. | E5: Utilidades | F5: =ROUND(B9*B10*F4/12,2)
A6: Salario mensual | B6: 200 | C6: Solo la parte salarial. El cestaticket y el bono de guerra económica no cuentan. | E6: Salario diario (si cobras en bolívares) | F6: =IF(B5="Bolívares (Bs.)",ROUND(F4,2),"")
E7: Salario diario (si cobras en dólares) | F7: =IF(B5="Bolívares (Bs.)","",ROUND(F4,2))
A8: UTILIDADES | E8: Utilidades (si cobras en bolívares) | F8: =IF(B5="Bolívares (Bs.)",F5,"")
A9: Días de utilidades que paga tu empresa al año | B9: 30 | C9: Si no lo sabes, deja el mínimo de ley. | E9: Utilidades (si cobras en dólares) | F9: =IF(B5="Bolívares (Bs.)","",F5)
A10: Meses completos trabajados en el año | B10: 12 | E10: Días de vacaciones | F10: =('Tablas oficiales'!$C$5+MIN(MAX(0,B17-1),'Tablas oficiales'!$C$6))
A11: Días de utilidades que te tocan | B11: =ROUND(B9*B10/12,2) | E11: Días de bono vacacional | F11: =MIN('Tablas oficiales'!$C$7+MAX(0,B17-1),'Tablas oficiales'!$C$8)
A12: Utilidades | B12: =F5 | E12: Pago de vacaciones | F12: =ROUND(F10*F4,2)
E13: Bono vacacional | F13: =ROUND(F11*F4,2)
A14: Van de 30 a 120 días de salario por año. Si no trabajaste el año completo, cobras la parte de los meses completos. | E14: Pago de vacaciones (si cobras en bolívares) | F14: =IF(B5="Bolívares (Bs.)",F12,"")
E15: Pago de vacaciones (si cobras en dólares) | F15: =IF(B5="Bolívares (Bs.)","",F12)
A16: VACACIONES Y BONO VACACIONAL | E16: Bono vacacional (si cobras en bolívares) | F16: =IF(B5="Bolívares (Bs.)",F13,"")
A17: Años de servicio que cumples con estas vacaciones | B17: 1 | C17: Si es tu primer año completo, pon 1. | E17: Bono vacacional (si cobras en dólares) | F17: =IF(B5="Bolívares (Bs.)","",F13)
A18: Días hábiles de vacaciones | B18: =F10 | E18: Vacaciones más bono (si cobras en bolívares) | F18: =IF(B5="Bolívares (Bs.)",ROUND(F12+F13,2),"")
A19: Días de bono vacacional | B19: =F11 | E19: Vacaciones más bono (si cobras en dólares) | F19: =IF(B5="Bolívares (Bs.)","",ROUND(F12+F13,2))
A20: Pago de vacaciones | B20: =F12
A21: Bono vacacional | B21: =F13
A22: Total | B22: =ROUND(F12+F13,2)
A24: 15 días hábiles el primer año y uno más por año, hasta 15 adicionales. El bono vacacional va de 15 a 30 días.

Sheet Liquidación
A1: Prestaciones sociales y liquidación
E3: Paso a paso
A4: TUS DATOS | E4: Tiempo trabajado: años completos | F4: =IF(EDATE(B7,12*(YEAR((B8+1))-YEAR(B7)))>(B8+1),(YEAR((B8+1))-YEAR(B7))-1,(YEAR((B8+1))-YEAR(B7)))
A5: En qué moneda está tu salario | B5: Dólares ($) | C5: Los montos salen en la misma moneda. | E5: Tiempo trabajado: último aniversario | F5: =EDATE(B7,12*F4)
A6: Último salario mensual | B6: 200 | C6: Solo la parte salarial. El cestaticket y el bono de guerra económica no cuentan. | E6: Tiempo trabajado: meses | F6: =MIN(12,IF(EDATE(F5,((YEAR((B8+1))-YEAR(F5))*12+MONTH((B8+1))-MONTH(F5)))>(B8+1),((YEAR((B8+1))-YEAR(F5))*12+MONTH((B8+1))-MONTH(F5))-1,((YEAR((B8+1))-YEAR(F5))*12+MONTH((B8+1))-MONTH(F5))))
A7: Fecha de ingreso | B7: 44256 | E7: Tiempo trabajado: días | F7: =(B8+1)-EDATE(F5,F6)
A8: Último día de trabajo | B8: 46311 | E8: Salario diario (entre 30) | F8: =B6/'Tablas oficiales'!$C$4
A9: Días de utilidades que paga tu empresa al año | B9: 30 | C9: Si no lo sabes, deja el mínimo de ley.
A10: Garantía de prestaciones depositada, sin intereses (opcional) | C10: Sale de tu fideicomiso o del informe trimestral de la empresa. Si lo dejas vacío, se estima con tu último salario. | E10: Prestaciones sociales
E11: Salario integral diario | F11: =ROUND(F8+F8*B9/360+F8*MIN('Tablas oficiales'!$C$7+MAX(0,(F4+1)-1),'Tablas oficiales'!$C$8)/360,2)
A12: PRESTACIONES SOCIALES | E12: Meses trabajados | F12: =F4*12+F6
A13: =IF(B8<B7,"La fecha de salida tiene que ser igual o posterior a la de ingreso.","")&IF(OR(B9<'Tablas oficiales'!$C$14,B9>'Tablas oficiales'!$C$15),"Las utilidades van de 30 a 120 días por año.","") | E13: Días de garantía | F13: =IF(F12<3,0,(INT(F12/3)+IF(OR(MOD(F12,3)>0,F7>0),1,0))*'Tablas oficiales'!$C$11+('Tablas oficiales'!$C$9*MIN(MAX(0,F4-1),INT('Tablas oficiales'!$C$10/'Tablas oficiales'!$C$9))*(MIN(MAX(0,F4-1),INT('Tablas oficiales'!$C$10/'Tablas oficiales'!$C$9))+1)/2+'Tablas oficiales'!$C$10*MAX(0,MAX(0,F4-1)-MIN(MAX(0,F4-1),INT('Tablas oficiales'!$C$10/'Tablas oficiales'!$C$9)))))
A14: Tiempo trabajado | B14: =F4&" años, "&F6&" meses y "&F7&" días" | E14: Días del cálculo retroactivo | F14: =IF(F12<3,MAX(1,F6+IF(F7>0,1,0))*'Tablas oficiales'!$C$12,(F4+IF(OR(F6>6,AND(F6=6,F7>0)),1,0))*'Tablas oficiales'!$C$13)
A15: Días de garantía | B15: =F13 | E15: Cálculo retroactivo | F15: =ROUND(F14*F11,2)
A16: Días del cálculo retroactivo | B16: =F14 | E16: Garantía | F16: =IF(F12<3,0,IF(ISNUMBER(B10),B10,ROUND(F13*F11,2)))
A17: Garantía | B17: =IF(F12<3,"",F16) | E17: Prestaciones sociales (la mayor) | F17: =MAX(F16,F15)
A18: Cálculo retroactivo | B18: =F15 | E18: Salario integral diario (si cobras en bolívares) | F18: =IF(B5="Bolívares (Bs.)",F11,"")
A19: Prestaciones sociales (la mayor de las dos) | B19: =F17 | E19: Salario integral diario (si cobras en dólares) | F19: =IF(B5="Bolívares (Bs.)","",F11)
E20: Garantía (si cobras en bolívares) | F20: =IF(B5="Bolívares (Bs.)",IF(F12<3,"",F16),"")
A21: LIQUIDACIÓN COMPLETA | E21: Garantía (si cobras en dólares) | F21: =IF(B5="Bolívares (Bs.)","",IF(F12<3,"",F16))
A22: Cómo terminó la relación de trabajo | B22: Despido sin causa justificada | C22: Despido sin causa justificada y sin pedir el reenganche. | E22: Retroactivo (si cobras en bolívares) | F22: =IF(B5="Bolívares (Bs.)",F15,"")
A23: Años de vacaciones vencidas que no disfrutaste ni te pagaron | B23: 0 | E23: Retroactivo (si cobras en dólares) | F23: =IF(B5="Bolívares (Bs.)","",F15)
A24: =IF(B23>F4,"No puedes tener más años de vacaciones vencidas que años trabajados.","") | E24: Prestaciones sociales (si cobras en bolívares) | F24: =IF(B5="Bolívares (Bs.)",F17,"")
A25: Prestaciones sociales | B25: =F17 | E25: Prestaciones sociales (si cobras en dólares) | F25: =IF(B5="Bolívares (Bs.)","",F17)
A26: Indemnización por despido | B26: =F28
A27: Vacaciones y bono vacacional | B27: =F30 | E27: Liquidación
A28: Meses de utilidades | B28: =F35 | E28: Indemnización por despido | F28: =IF(B22="Despido sin causa justificada",F17,0)
A29: Utilidades fraccionadas | B29: =F36 | E29: Días de vacaciones y bono a pagar | F29: =(('Tablas oficiales'!$C$5+MIN(MAX(0,(F4+1)-1),'Tablas oficiales'!$C$6))+MIN('Tablas oficiales'!$C$7+MAX(0,(F4+1)-1),'Tablas oficiales'!$C$8))*F6/12+IF(0<B23,('Tablas oficiales'!$C$5+MIN(MAX(0,(F4-0)-1),'Tablas oficiales'!$C$6))+MIN('Tablas oficiales'!$C$7+MAX(0,(F4-0)-1),'Tablas oficiales'!$C$8),0)+IF(1<B23,('Tablas oficiales'!$C$5+MIN(MAX(0,(F4-1)-1),'Tablas oficiales'!$C$6))+MIN('Tablas oficiales'!$C$7+MAX(0,(F4-1)-1),'Tablas oficiales'!$C$8),0)+IF(2<B23,('Tablas oficiales'!$C$5+MIN(MAX(0,(F4-2)-1),'Tablas oficiales'!$C$6))+MIN('Tablas oficiales'!$C$7+MAX(0,(F4-2)-1),'Tablas oficiales'!$C$8),0)+IF(3<B23,('Tablas oficiales'!$C$5+MIN(MAX(0,(F4-3)-1),'Tablas oficiales'!$C$6))+MIN('Tablas oficiales'!$C$7+MAX(0,(F4-3)-1),'Tablas oficiales'!$C$8),0)+IF(4<B23,('Tablas oficiales'!$C$5+MIN(MAX(0,(F4-4)-1),'Tablas oficiales'!$C$6))+MIN('Tablas oficiales'!$C$7+MAX(0,(F4-4)-1),'Tablas oficiales'!$C$8),0)+IF(5<B23,('Tablas oficiales'!$C$5+MIN(MAX(0,(F4-5)-1),'Tablas oficiales'!$C$6))+MIN('Tablas oficiales'!$C$7+MAX(0,(F4-5)-1),'Tablas oficiales'!$C$8),0)+IF(6<B23,('Tablas oficiales'!$C$5+MIN(MAX(0,(F4-6)-1),'Tablas oficiales'!$C$6))+MIN('Tablas oficiales'!$C$7+MAX(0,(F4-6)-1),'Tablas oficiales'!$C$8),0)+IF(7<B23,('Tablas oficiales'!$C$5+MIN(MAX(0,(F4-7)-1),'Tablas oficiales'!$C$6))+MIN('Tablas oficiales'!$C$7+MAX(0,(F4-7)-1),'Tablas oficiales'!$C$8),0)+IF(8<B23,('Tablas oficiales'!$C$5+MIN(MAX(0,(F4-8)-1),'Tablas oficiales'!$C$6))+MIN('Tablas oficiales'!$C$7+MAX(0,(F4-8)-1),'Tablas oficiales'!$C$8),0)+IF(9<B23,('Tablas oficiales'!$C$5+MIN(MAX(0,(F4-9)-1),'Tablas oficiales'!$C$6))+MIN('Tablas oficiales'!$C$7+MAX(0,(F4-9)-1),'Tablas oficiales'!$C$8),0)
A30: Total de la liquidación | B30: =ROUND(F17+F28+F30+F36,2) | E30: Vacaciones y bono | F30: =ROUND(F29*F8,2)
E31: Ejercicio de utilidades: años completos | F31: =IF(EDATE(MAX(B7,DATE(YEAR(B8),1,1)),12*(YEAR((B8+1))-YEAR(MAX(B7,DATE(YEAR(B8),1,1)))))>(B8+1),(YEAR((B8+1))-YEAR(MAX(B7,DATE(YEAR(B8),1,1))))-1,(YEAR((B8+1))-YEAR(MAX(B7,DATE(YEAR(B8),1,1)))))
A32: La indemnización por despido es igual a tus prestaciones sociales (art. 92 de la LOTTT). Las utilidades se toman del año calendario. No incluye intereses de prestaciones ni salarios pendientes. Los montos van en la moneda de tu salario. | E32: Ejercicio de utilidades: último aniversario | F32: =EDATE(MAX(B7,DATE(YEAR(B8),1,1)),12*F31)
E33: Ejercicio de utilidades: meses | F33: =MIN(12,IF(EDATE(F32,((YEAR((B8+1))-YEAR(F32))*12+MONTH((B8+1))-MONTH(F32)))>(B8+1),((YEAR((B8+1))-YEAR(F32))*12+MONTH((B8+1))-MONTH(F32))-1,((YEAR((B8+1))-YEAR(F32))*12+MONTH((B8+1))-MONTH(F32))))
E34: Ejercicio de utilidades: días | F34: =(B8+1)-EDATE(F32,F33)
E35: Meses completos del ejercicio | F35: =MIN(12,F31*12+F33)
E36: Utilidades fraccionadas | F36: =ROUND(B9*F35*F8/12,2)
E37: Prestaciones sociales (si cobras en bolívares) | F37: =IF(B5="Bolívares (Bs.)",F17,"")
E38: Prestaciones sociales (si cobras en dólares) | F38: =IF(B5="Bolívares (Bs.)","",F17)
E39: Indemnización (si cobras en bolívares) | F39: =IF(B5="Bolívares (Bs.)",F28,"")
E40: Indemnización (si cobras en dólares) | F40: =IF(B5="Bolívares (Bs.)","",F28)
E41: Vacaciones (si cobras en bolívares) | F41: =IF(B5="Bolívares (Bs.)",F30,"")
...

Sheet Tablas oficiales
A1: Tablas oficiales de Venezuela
A2: Son los valores que usan las fórmulas de esta planilla, vigentes al 16/10/2026. Cada uno trae el enlace a la norma o al organismo que lo publica y la fecha en que lo verificamos.
A3: Dato | B3: Detalle | C3: Valor | D3: Unidad | E3: Vigente desde | F3: Fuente oficial | G3: Verificado el
A4: Días por los que se divide el salario mensual | C4: 30 | D4: días | E4: 15/3/2022 | F4: https://www.presidencia.gob.ve/Site/Web/Principal/paginas/classMostrarEvento3.php?id_evento=20553 | G4: 7/10/2026
A5: Días hábiles de vacaciones al cumplir el primer año | C5: 15 | D5: días | E5: 7/5/2012 | F5: https://www.mpppst.gob.ve/mpppstweb/wp-content/uploads/2014/03/LEY_ORGANICA_DEL_TRABAJO_LOS_TRABAJADORES_Y_LAS_TRABAJADORAS.pdf | G5: 7/10/2026
A6: Tope de días adicionales de vacaciones (uno por año) | C6: 15 | D6: días | E6: 7/5/2012 | F6: https://www.mpppst.gob.ve/mpppstweb/wp-content/uploads/2014/03/LEY_ORGANICA_DEL_TRABAJO_LOS_TRABAJADORES_Y_LAS_TRABAJADORAS.pdf | G6: 7/10/2026
A7: Bono vacacional: días mínimos de salario normal | C7: 15 | D7: días | E7: 7/5/2012 | F7: https://www.mpppst.gob.ve/mpppstweb/wp-content/uploads/2014/03/LEY_ORGANICA_DEL_TRABAJO_LOS_TRABAJADORES_Y_LAS_TRABAJADORAS.pdf | G7: 7/10/2026
A8: Bono vacacional: tope de días de salario normal | C8: 30 | D8: días | E8: 7/5/2012 | F8: https://www.mpppst.gob.ve/mpppstweb/wp-content/uploads/2014/03/LEY_ORGANICA_DEL_TRABAJO_LOS_TRABAJADORES_Y_LAS_TRABAJADORAS.pdf | G8: 7/10/2026
A9: Días adicionales de garantía por año, después del primero | C9: 2 | D9: días | E9: 7/5/2012 | F9: https://www.mpppst.gob.ve/mpppstweb/wp-content/uploads/2014/03/LEY_ORGANICA_DEL_TRABAJO_LOS_TRABAJADORES_Y_LAS_TRABAJADORAS.pdf | G9: 7/10/2026
A10: Tope de días adicionales de garantía por año | C10: 30 | D10: días | E10: 7/5/2012 | F10: https://www.mpppst.gob.ve/mpppstweb/wp-content/uploads/2014/03/LEY_ORGANICA_DEL_TRABAJO_LOS_TRABAJADORES_Y_LAS_TRABAJADORAS.pdf | G10: 7/10/2026
A11: Días de garantía de prestaciones por trimestre | C11: 15 | D11: días | E11: 7/5/2012 | F11: https://www.mpppst.gob.ve/mpppstweb/wp-content/uploads/2014/03/LEY_ORGANICA_DEL_TRABAJO_LOS_TRABAJADORES_Y_LAS_TRABAJADORAS.pdf | G11: 7/10/2026
A12: Días de prestaciones por mes si la relación dura menos de tres meses | C12: 5 | D12: días | E12: 7/5/2012 | F12: https://www.mpppst.gob.ve/mpppstweb/wp-content/uploads/2014/03/LEY_ORGANICA_DEL_TRABAJO_LOS_TRABAJADORES_Y_LAS_TRABAJADORAS.pdf | G12: 7/10/2026
A13: Días de prestaciones por año en el cálculo final (retroactivo) | C13: 30 | D13: días | E13: 7/5/2012 | F13: https://www.mpppst.gob.ve/mpppstweb/wp-content/uploads/2014/03/LEY_ORGANICA_DEL_TRABAJO_LOS_TRABAJADORES_Y_LAS_TRABAJADORAS.pdf | G13: 7/10/2026
A14: Utilidades: mínimo de días de salario por año | C14: 30 | D14: días | E14: 7/5/2012 | F14: https://www.mpppst.gob.ve/mpppstweb/wp-content/uploads/2014/03/LEY_ORGANICA_DEL_TRABAJO_LOS_TRABAJADORES_Y_LAS_TRABAJADORAS.pdf | G14: 7/10/2026
A15: Utilidades: máximo de días de salario por año | C15: 120 | D15: días | E15: 7/5/2012 | F15: https://www.mpppst.gob.ve/mpppstweb/wp-content/uploads/2014/03/LEY_ORGANICA_DEL_TRABAJO_LOS_TRABAJADORES_Y_LAS_TRABAJADORAS.pdf | G15: 7/10/2026
