Workbook

Sheet Instrucciones
A1: Planilla de salario y liquidación Colombia 2026
A3: 1 | B3: Las celdas amarillas son para tus datos. Las verdes se calculan solas, con las fórmulas de la ley. A la derecha de cada hoja está el paso a paso de la cuenta.
A4: 2 | B4: «Salario neto»: pones tu salario y te dice los aportes a salud y pensión, la retención en la fuente y lo que te consignan.
A5: 3 | B5: «Prima y cesantías»: calcula la prima de servicios del semestre, las cesantías del año y sus intereses.
A6: 4 | B6: «Liquidación»: pones tus fechas y tu salario, y te dice cesantías, intereses, prima, vacaciones y, si te despidieron sin justa causa, la indemnización.
A7: 5 | B7: «Tablas oficiales» tiene cada valor oficial que usan las fórmulas, con el enlace a su fuente y la fecha en que lo verificamos. Los valores son los vigentes al 8/10/2026.
A8: 6 | B8: Cuando cambia un valor oficial, actualizamos la planilla y el mismo enlace de descarga te baja la versión nueva.
A10: Da los mismos números que las calculadoras gratuitas de calcularya.com. Antes de publicar cada versión, una verificación automática recalcula este archivo y lo compara con ellas.
A11: Es una referencia de cálculo con sus fuentes, no asesoría legal. Tu contrato o tu empresa pueden darte más que el mínimo de ley.
A12: Las fechas van como dd/mm/aaaa. Si tu Excel está en inglés y las lee al revés, escríbelas como aaaa-mm-dd.

Sheet Salario neto
A1: Salario neto: salud, pensión y retención en la fuente
E3: Paso a paso
A4: TUS DATOS
A5: Salario mensual | B5: 3000000 | E5: Aportes a seguridad social
A6: Recibes auxilio de transporte | B6: Sí | E6: Ingreso base de cotización (IBC) | F6: =MIN(MAX(B5,'Tablas oficiales'!$C$4),'Tablas oficiales'!$C$6*'Tablas oficiales'!$C$4)
A7: Tienes personas a cargo (dependientes) | B7: No | C7: Hijos, cónyuge o padres que dependen de ti. Baja la retención en la fuente. | E7: Pensión a tu cargo (%) | F7: ='Tablas oficiales'!$C$7*'Tablas oficiales'!$C$8/100
E8: Fondo de Solidaridad Pensional (%) | F8: =INDEX('Tablas oficiales'!$D$11:$D$17,IFERROR(MATCH(F6/'Tablas oficiales'!$C$4,'Tablas oficiales'!$B$11:$B$17,1),1))
A9: LO QUE TE CONSIGNAN | E9: Salud | F9: =ROUND(F6*'Tablas oficiales'!$C$19/100,0)
A10: Salario | B10: =B5 | E10: Pensión | F10: =ROUND(F6*F7/100,0)
A11: Auxilio de transporte | B11: =F23 | E11: Fondo de Solidaridad Pensional | F11: =ROUND(F6*F8/100,0)
A12: Salud (EPS) | B12: =F9
A13: Pensión | B13: =F10 | E13: Retención en la fuente (procedimiento 1)
A14: Fondo de Solidaridad Pensional | B14: =F11 | E14: Ingreso menos aportes obligatorios | F14: =MAX(0,B5-(F9+F10+F11))
A15: Retención en la fuente | B15: =F22 | E15: Deducción por dependientes | F15: =ROUND(IF(B7="Sí",MIN(B5*'Tablas oficiales'!$C$20/100,'Tablas oficiales'!$C$21*'Tablas oficiales'!$C$5),0),0)
A16: Total de descuentos | B16: =F24 | E16: Subtotal | F16: =MAX(0,F14-F15)
A17: Salario neto (lo que te consignan) | B17: =ROUND(B5+F23-F24,0) | E17: Renta exenta del 25 % | F17: =ROUND(MIN(F16*'Tablas oficiales'!$C$22/100,'Tablas oficiales'!$C$23/12*'Tablas oficiales'!$C$5),0)
E18: Límite del 40 % | F18: =MIN(F14*'Tablas oficiales'!$C$24/100,'Tablas oficiales'!$C$25/12*'Tablas oficiales'!$C$5)
A19: Los aportes se calculan sobre el salario, con un piso de un salario mínimo y un techo de 25. El auxilio de transporte se paga a quien gana hasta dos salarios mínimos y no lleva descuentos. | E19: Deducciones y rentas exentas que se restan | F19: =ROUND(MIN(F15+F17,F18),0)
E20: Base de retención | F20: =MAX(0,F14-F19)
E21: Base en UVT | F21: =F20/'Tablas oficiales'!$C$5
E22: Retención en la fuente | F22: =ROUND(IF(F21<=0,0,INDEX('Tablas oficiales'!$E$28:$E$34,IFERROR(MATCH(F21,'Tablas oficiales'!$B$28:$B$34,1),1))+(F21-INDEX('Tablas oficiales'!$B$28:$B$34,IFERROR(MATCH(F21,'Tablas oficiales'!$B$28:$B$34,1),1)))*INDEX('Tablas oficiales'!$D$28:$D$34,IFERROR(MATCH(F21,'Tablas oficiales'!$B$28:$B$34,1),1))/100)*'Tablas oficiales'!$C$5,0)
E23: Auxilio de transporte que entra | F23: =IF(AND(B6="Sí",B5<='Tablas oficiales'!$C$36*'Tablas oficiales'!$C$4),'Tablas oficiales'!$C$37,0)
E24: Total de descuentos | F24: =ROUND(F9+F10+F11+F22,0)

Sheet Prima y cesantías
A1: Prima de servicios, cesantías e intereses
E3: Paso a paso
A4: TUS DATOS | E4: Auxilio de transporte que entra | F4: =IF(AND(B6="Sí",B5<='Tablas oficiales'!$C$36*'Tablas oficiales'!$C$4),'Tablas oficiales'!$C$37,0)
A5: Salario mensual | B5: 2000000 | E5: Salario base (salario más auxilio) | F5: =B5+F4
A6: Recibes auxilio de transporte | B6: Sí | E6: Cesantías | F6: =ROUND(F5*B17/360,0)
E7: Intereses sobre las cesantías | F7: =ROUND(F6*'Tablas oficiales'!$C$38/100*B17/360,0)
A8: PRIMA DE SERVICIOS
A9: Días trabajados en el semestre | B9: 180 | C9: El semestre completo son 180 días (meses de 30 días).
A10: Auxilio de transporte incluido | B10: =F4
A11: Salario base de la prima | B11: =F5
A12: Prima de servicios del semestre | B12: =ROUND(F5*B9/360,0)
A14: Se paga la mitad antes del 30 de junio y la otra mitad antes del 20 de diciembre (CST art. 306).
A16: CESANTÍAS E INTERESES
A17: Días trabajados en el año | B17: 360 | C17: El año completo son 360 días (meses de 30 días).
A18: Salario base de las cesantías | B18: =F5
A19: Cesantías (van a tu fondo) | B19: =F6
A20: Intereses sobre las cesantías (te los pagan a ti) | B20: =F7
A21: Total | B21: =ROUND(F6+F7,0)
A23: Las cesantías se consignan al fondo antes del 14 de febrero. Los intereses te los paga la empresa directo, antes del 31 de enero.

Sheet Liquidación
A1: Liquidación del contrato de trabajo
E3: Paso a paso
A4: TUS DATOS
A5: Salario mensual | B5: 2500000 | E5: Cesantías y prima
A6: Fecha de ingreso | B6: 45323 | E6: Auxilio de transporte que entra | F6: =IF(AND(B10="Sí",B5<='Tablas oficiales'!$C$36*'Tablas oficiales'!$C$4),'Tablas oficiales'!$C$37,0)
A7: Último día de trabajo | B7: 46303 | E7: Salario base (salario más auxilio) | F7: =B5+F6
A8: Desde cuándo no tomas vacaciones (opcional) | C8: Si nunca tomaste vacaciones, déjalo vacío y se usa tu fecha de ingreso. | E8: Días para cesantías este año | F8: =((YEAR(B7)-YEAR(MAX(B6,DATE(YEAR(B7),1,1))))*360+(MONTH(B7)-MONTH(MAX(B6,DATE(YEAR(B7),1,1))))*30+(IF(AND(MONTH(B7)=2,DAY(B7)=DAY(EOMONTH(B7,0))),30,MIN(DAY(B7),30))-MIN(DAY(MAX(B6,DATE(YEAR(B7),1,1))),30))+1)
A9: Cómo terminó el contrato | B9: Renuncia o fin del plazo | C9: Renuncia también incluye el mutuo acuerdo. El despido sin justa causa es para contratos a término indefinido. | E9: Cesantías | F9: =ROUND(F7*F8/360,0)
A10: Recibes auxilio de transporte | B10: Sí | E10: Intereses sobre las cesantías | F10: =ROUND(F9*'Tablas oficiales'!$C$38/100*F8/360,0)
E11: Días para la prima del semestre | F11: =((YEAR(B7)-YEAR(MAX(B6,IF(MONTH(B7)<=6,DATE(YEAR(B7),1,1),DATE(YEAR(B7),7,1)))))*360+(MONTH(B7)-MONTH(MAX(B6,IF(MONTH(B7)<=6,DATE(YEAR(B7),1,1),DATE(YEAR(B7),7,1)))))*30+(IF(AND(MONTH(B7)=2,DAY(B7)=DAY(EOMONTH(B7,0))),30,MIN(DAY(B7),30))-MIN(DAY(MAX(B6,IF(MONTH(B7)<=6,DATE(YEAR(B7),1,1),DATE(YEAR(B7),7,1)))),30))+1)
A12: TU LIQUIDACIÓN | E12: Prima de servicios | F12: =ROUND(F7*F11/360,0)
A13: =IF(B7<B6,"La fecha de retiro tiene que ser posterior a la de ingreso.",IF(AND(ISNUMBER(B8),OR(B8<B6,B8>B7)),"La fecha de las vacaciones tiene que estar entre tu ingreso y tu retiro.",""))
A14: Salario base para cesantías y prima | B14: =F7 | E14: Vacaciones e indemnización
A15: Días para cesantías este año | B15: =F8 | E15: Días trabajados sin vacaciones | F15: =((YEAR(B7)-YEAR(IF(ISNUMBER(B8),B8,B6)))*360+(MONTH(B7)-MONTH(IF(ISNUMBER(B8),B8,B6)))*30+(IF(AND(MONTH(B7)=2,DAY(B7)=DAY(EOMONTH(B7,0))),30,MIN(DAY(B7),30))-MIN(DAY(IF(ISNUMBER(B8),B8,B6)),30))+1)
A16: Cesantías | B16: =F9 | E16: Vacaciones en dinero | F16: =ROUND(B5*F15/720,0)
A17: Intereses sobre las cesantías | B17: =F10 | E17: Días de servicio | F17: =((YEAR(B7)-YEAR(B6))*360+(MONTH(B7)-MONTH(B6))*30+(IF(AND(MONTH(B7)=2,DAY(B7)=DAY(EOMONTH(B7,0))),30,MIN(DAY(B7),30))-MIN(DAY(B6),30))+1)
A18: Días para la prima de este semestre | B18: =F11 | E18: ¿Ganas 10 salarios mínimos o más? | F18: =IF(B5>='Tablas oficiales'!$C$43*'Tablas oficiales'!$C$4,"Sí","No")
A19: Prima de servicios | B19: =F12 | E19: Días de indemnización | F19: =IF(F17<=360,IF(F18="Sí",'Tablas oficiales'!$C$41,'Tablas oficiales'!$C$39),IF(F18="Sí",'Tablas oficiales'!$C$41,'Tablas oficiales'!$C$39)+IF(F18="Sí",'Tablas oficiales'!$C$42,'Tablas oficiales'!$C$40)*(F17-360)/360)
A20: Días trabajados sin vacaciones | B20: =F15 | E20: Indemnización | F20: =IF(B9="Despido sin justa causa (indefinido)",ROUND(B5/30*F19,0),0)
A21: Vacaciones pendientes en dinero | B21: =F16
A22: Indemnización por despido sin justa causa | B22: =F20
A23: Total de la liquidación | B23: =ROUND(F9+F10+F12+F16+F20,0)
A25: Se cuenta con año comercial de 360 días. Las cesantías de años anteriores ya deberían estar en tu fondo, por eso solo se calculan las de este año. Las vacaciones no incluyen el auxilio de transporte.

Sheet Tablas oficiales
A1: Tablas oficiales de Colombia
A2: Son los valores que usan las fórmulas de esta planilla, vigentes al 8/10/2026. Cada uno trae el enlace a la norma o al organismo que lo publica y la fecha en que lo verificamos.
A3: Dato | B3: Detalle | C3: Valor | D3: Unidad | E3: Vigente desde | F3: Fuente oficial | G3: Verificado el
A4: Salario mínimo legal mensual vigente (SMMLV) | C4: 1750905 | D4: COP | E4: 1/1/2026 | F4: https://normativa.colpensiones.gov.co/compilacion/docs/decreto_1469_2025.htm | G4: 7/10/2026
A5: Unidad de Valor Tributario (UVT) | C5: 52374 | D5: COP | E5: 1/1/2026 | F5: https://normograma.dian.gov.co/dian/compilacion/docs/resolucion_dian_0238_2025.htm | G5: 7/10/2026
A6: Tope del ingreso base de cotización | C6: 25 | D6: SMMLV | E6: 29/1/2003 | F6: https://normativa.colpensiones.gov.co/compilacion/docs/ley_0100_1993.htm | G6: 7/10/2026
A7: Cotización total a pensión | C7: 16 | D7: % | E7: 1/1/2008 | F7: https://normativa.colpensiones.gov.co/compilacion/docs/decreto_4982_2007.htm | G7: 7/10/2026
A8: Parte de la cotización a pensión que paga el trabajador | C8: 25 | D8: % | E8: 29/1/2003 | F8: https://normativa.colpensiones.gov.co/compilacion/docs/ley_0797_2003.htm | G8: 7/10/2026
A9: Aporte al Fondo de Solidaridad Pensional según el salario | D9: SMMLV | E9: 29/1/2003 | F9: https://normativa.colpensiones.gov.co/compilacion/docs/ley_0797_2003.htm | G9: 7/10/2026
B10: Desde | C10: Hasta | D10: Tasa % | E10: Cuota fija
B11: 0 | C11: 4 | D11: 0 | E11: 0
B12: 4 | C12: 16 | D12: 1 | E12: 0
B13: 16 | C13: 17 | D13: 1.2 | E13: 0
B14: 17 | C14: 18 | D14: 1.4 | E14: 0
B15: 18 | C15: 19 | D15: 1.6 | E15: 0
B16: 19 | C16: 20 | D16: 1.8 | E16: 0
B17: 20 | C17: 1e+15 | D17: 2 | E17: 0
A19: Aporte a salud a cargo del trabajador | C19: 4 | D19: % | E19: 1/1/2007 | F19: https://normativa.colpensiones.gov.co/compilacion/docs/ley_0100_1993.htm | G19: 7/10/2026
A20: Deducción mensual por dependientes | C20: 10 | D20: % | E20: 1/1/2023 | F20: https://normograma.dian.gov.co/dian/compilacion/docs/estatuto_tributario.htm | G20: 7/10/2026
A21: Tope mensual de la deducción por dependientes | C21: 32 | D21: UVT | E21: 1/1/2023 | F21: https://normograma.dian.gov.co/dian/compilacion/docs/estatuto_tributario.htm | G21: 7/10/2026
A22: Renta exenta de los pagos laborales | C22: 25 | D22: % | E22: 1/1/2023 | F22: https://normograma.dian.gov.co/dian/compilacion/docs/estatuto_tributario.htm | G22: 7/10/2026
A23: Tope anual de la renta exenta del 25 % | C23: 790 | D23: UVT | E23: 1/1/2023 | F23: https://normograma.dian.gov.co/dian/compilacion/docs/estatuto_tributario.htm | G23: 7/10/2026
A24: Límite de rentas exentas y deducciones sobre el ingreso depurado | C24: 40 | D24: % | E24: 1/1/2023 | F24: https://normograma.dian.gov.co/dian/compilacion/docs/estatuto_tributario.htm | G24: 7/10/2026
A25: Tope anual de rentas exentas y deducciones | C25: 1340 | D25: UVT | E25: 1/1/2023 | F25: https://normograma.dian.gov.co/dian/compilacion/docs/estatuto_tributario.htm | G25: 7/10/2026
A26: Tabla de retención en la fuente por pagos laborales | D26: UVT | E26: 1/1/2023 | F26: https://normograma.dian.gov.co/dian/compilacion/docs/estatuto_tributario.htm | G26: 7/10/2026
B27: Desde | C27: Hasta | D27: Tasa % | E27: Cuota fija
B28: 0 | C28: 95 | D28: 0 | E28: 0
B29: 95 | C29: 150 | D29: 19 | E29: 0
B30: 150 | C30: 360 | D30: 28 | E30: 10
B31: 360 | C31: 640 | D31: 33 | E31: 69
B32: 640 | C32: 945 | D32: 35 | E32: 162
B33: 945 | C33: 2300 | D33: 37 | E33: 268
B34: 2300 | C34: 1e+15 | D34: 39 | E34: 770
A36: Salario máximo para recibir auxilio de transporte | C36: 2 | D36: SMMLV | E36: 1/1/2026 | F36: https://normativa.colpensiones.gov.co/compilacion/docs/decreto_1470_2025.htm | G36: 7/10/2026
A37: Auxilio de transporte mensual | C37: 249095 | D37: COP | E37: 1/1/2026 | F37: https://normativa.colpensiones.gov.co/compilacion/docs/decreto_1470_2025.htm | G37: 7/10/2026
A38: Intereses sobre las cesantías | C38: 12 | D38: % | E38: 1/1/1991 | F38: https://normativa.colpensiones.gov.co/compilacion/docs/ley_0050_1990.htm | G38: 7/10/2026
A39: Días de salario de la indemnización por despido sin justa causa | B39: Primer año, salario menor a 10 SMMLV | C39: 30 | D39: días | E39: 27/12/2002 | F39: https://normativa.colpensiones.gov.co/compilacion/docs/codigo_sustantivo_trabajo.htm | G39: 7/10/2026
A40: Días de salario de la indemnización por despido sin justa causa | B40: Cada año siguiente, salario menor a 10 SMMLV | C40: 20 | D40: días | E40: 27/12/2002 | F40: https://normativa.colpensiones.gov.co/compilacion/docs/codigo_sustantivo_trabajo.htm | G40: 7/10/2026
A41: Días de salario de la indemnización por despido sin justa causa | B41: Primer año, salario de 10 SMMLV o más | C41: 20 | D41: días | E41: 27/12/2002 | F41: https://normativa.colpensiones.gov.co/compilacion/docs/codigo_sustantivo_trabajo.htm | G41: 7/10/2026
A42: Días de salario de la indemnización por despido sin justa causa | B42: Cada año siguiente, salario de 10 SMMLV o más | C42: 15 | D42: días | E42: 27/12/2002 | F42: https://normativa.colpensiones.gov.co/compilacion/docs/codigo_sustantivo_trabajo.htm | G42: 7/10/2026
...
