Workbook

Sheet Instrucciones
A1: Cómo usar esta planilla
A3: 1 | B3: Andá a la hoja «Mi monotributo». Elegí tu actividad, tu categoría actual y si además trabajás en relación de dependencia.
A4: 2 | B4: Cargá lo que facturaste cada mes en la tabla amarilla. Viene armada con los 12 meses que se evalúan en la próxima recategorización (febrero de 2027); si querés mirar otro período, cambiá los nombres de los meses.
A5: 3 | B5: Si tenés local, completá superficie, energía y alquileres. No son opcionales para ARCA: la categoría la define el MAYOR de los parámetros, no solo la facturación.
A6: 4 | B6: Las celdas verdes te dicen qué categoría te corresponde, qué parámetro la define, cuánto margen te queda antes de saltar a la siguiente y cuánto vas a pagar por mes.
A7: 5 | B7: La hoja «Categorías 2026» es la tabla oficial de ARCA. «Fuentes» tiene los links y la fecha en que se verificó.
A9: LO QUE TENÉS QUE SABER
B10: • La recategorización es dos veces por año, en febrero y en agosto, y el trámite se puede hacer hasta el día 5. En cada una se evalúan los últimos 12 meses de actividad.
B11: • Ley 24.977, Anexo, art. 9: estás bien categorizado cuando te encuadrás en la categoría que corresponde al MAYOR valor de tus parámetros —ingresos brutos, superficie, energía o alquileres—. Por eso la planilla calcula la categoría por cada uno y se queda con la más alta.
B12: • Si cualquiera de los parámetros supera el máximo de la categoría K, quedás excluido del régimen. En venta de cosas muebles, también si el precio unitario de venta supera el máximo que fija ARCA.
B13: • Si además trabajás en relación de dependencia, tu empleo ya aporta jubilación y obra social: pagás solo el impuesto integrado.
B14: • Las categorías se actualizan dos veces por año por inflación. Esta planilla tiene la tabla vigente desde el 1 de agosto de 2026; la próxima actualización es en febrero 2027 y te llega por mail sin costo.
A16: Da los mismos números que la calculadora gratis de calcular.ar/monotributo: misma tabla oficial, misma regla. Antes de publicar cada versión, una verificación automática recalcula este archivo y lo compara contra la calculadora. Si alguna vez difieren, escribinos.

Sheet Mi monotributo
A1: Mi monotributo — facturación, categoría y cuota
A2: Tabla de ARCA vigente desde el 1 de agosto de 2026 · Regla del art. 9 del Anexo de la Ley 24.977
A4: TUS DATOS
A5: Actividad principal | B5: Servicios
A6: Tu categoría actual | B6: C
A7: ¿Trabajás además en relación de dependencia? | B7: No
A9: FACTURACIÓN DE LOS ÚLTIMOS 12 MESES
A10: Mes | B10: Facturado
A11: febrero 2026
A12: marzo 2026
A13: abril 2026
A14: mayo 2026
A15: junio 2026
A16: julio 2026
A17: agosto 2026
A18: septiembre 2026
A19: octubre 2026
A20: noviembre 2026
A21: diciembre 2026
A22: enero 2027
A24: SI TENÉS LOCAL O VENDÉS COSAS (si no, dejalo en 0)
A25: Superficie afectada a la actividad (m²) | B25: 0
A26: Energía eléctrica consumida en los últimos 12 meses (kW) | B26: 0
A27: Alquileres devengados en los últimos 12 meses | B27: 0
A28: Precio unitario de venta más alto (solo venta de cosas) | B28: 0
A30: RESULTADO
A31: Facturación de los últimos 12 meses | B31: =SUM(B11:B22)
A32: Promedio mensual | B32: =ROUND(B31/12,2)
A33: Categoría según facturación | B33: =IF(D33>11,"Excluido",INDEX('Categorías 2026'!$A$3:$A$13,D33)) | D33: =IF(B31>INDEX('Categorías 2026'!$B$3:$B$13,11),99,COUNTIF('Categorías 2026'!$B$3:$B$13,"<"&B31)+1)
A34: Categoría según superficie | B34: =IF(D34>11,"Excluido",INDEX('Categorías 2026'!$A$3:$A$13,D34)) | D34: =IF(MAX(B25,0)>INDEX('Categorías 2026'!$C$3:$C$13,11),99,COUNTIF('Categorías 2026'!$C$3:$C$13,"<"&MAX(B25,0))+1)
A35: Categoría según energía | B35: =IF(D35>11,"Excluido",INDEX('Categorías 2026'!$A$3:$A$13,D35)) | D35: =IF(MAX(B26,0)>INDEX('Categorías 2026'!$D$3:$D$13,11),99,COUNTIF('Categorías 2026'!$D$3:$D$13,"<"&MAX(B26,0))+1)
A36: Categoría según alquileres | B36: =IF(D36>11,"Excluido",INDEX('Categorías 2026'!$A$3:$A$13,D36)) | D36: =IF(MAX(B27,0)>INDEX('Categorías 2026'!$E$3:$E$13,11),99,COUNTIF('Categorías 2026'!$E$3:$E$13,"<"&MAX(B27,0))+1)
A37: CATEGORÍA QUE TE CORRESPONDE | B37: =IF(D37>11,"Excluido del régimen",INDEX('Categorías 2026'!$A$3:$A$13,D37)) | D37: =MAX(D33:D36)
A38: Qué parámetro la define | B38: =IF(D37>11,IF(D33>11,"La facturación",IF(D34>11,"La superficie",IF(D35>11,"La energía","Los alquileres"))),IF(D37=D33,"La facturación",IF(D37=D34,"La superficie",IF(D37=D35,"La energía","Los alquileres"))))
A39: Tope de facturación de esa categoría | B39: =IF(D37>11,0,INDEX('Categorías 2026'!$B$3:$B$13,D37))
A40: Margen para seguir facturando sin cambiar de categoría | B40: =IF(D37>11,0,ROUND(B39-B31,2))
A41: CUOTA MENSUAL QUE TE CORRESPONDE | B41: =IF(D37>11,0,ROUND(IF(B5="Venta de cosas muebles",INDEX('Categorías 2026'!$H$3:$H$13,D37),INDEX('Categorías 2026'!$G$3:$G$13,D37))+IF(B7="Sí",0,INDEX('Categorías 2026'!$I$3:$I$13,D37)+INDEX('Categorías 2026'!$J$3:$J$13,D37)),2))
A42: Cuota de tu categoría actual | B42: =IFERROR(ROUND(IF(B5="Venta de cosas muebles",INDEX('Categorías 2026'!$H$3:$H$13,D42),INDEX('Categorías 2026'!$G$3:$G$13,D42))+IF(B7="Sí",0,INDEX('Categorías 2026'!$I$3:$I$13,D42)+INDEX('Categorías 2026'!$J$3:$J$13,D42)),2),0) | D42: =MATCH(B6,'Categorías 2026'!$A$3:$A$13,0)
A43: ¿Qué pasa en la recategorización? | B43: =IF(D37>11,"Quedás excluido: tenés que pasar al régimen general",IF(D37>D42,"Subís de categoría",IF(D37<D42,"Bajás de categoría","Te mantenés en la misma")))
A44: Diferencia de cuota por mes | B44: =IF(D37>11,0,ROUND(B41-B42,2))
...

Sheet Categorías 2026
A1: Categorías del Monotributo — vigentes desde el 1 de agosto de 2026 (ARCA)
A2: Cat. | B2: Ingresos brutos anuales | C2: Superficie (m²) | D2: Energía anual (kW) | E2: Alquileres anuales | F2: Precio unitario máx. | G2: Impuesto · servicios | H2: Impuesto · venta | I2: Jubilación (SIPA) | J2: Obra social | K2: Total · servicios | L2: Total · venta
A3: A | B3: 12009410 | C3: 30 | D3: 3330 | E3: 2792886.1 | F3: 716840.77 | G3: 5585.77 | H3: 5585.77 | I3: 18246.86 | J3: 25694.55 | K3: 49527.18 | L3: 49527.18
A4: B | B4: 17595183 | C4: 45 | D4: 5000 | E4: 2792886.1 | F4: 716840.77 | G4: 10612.98 | H4: 10612.98 | I4: 20071.55 | J4: 25694.55 | K4: 56379.08 | L4: 56379.08
A5: C | B5: 24670494 | C5: 60 | D5: 6700 | E5: 3816944.4 | F5: 716840.77 | G5: 18246.86 | H5: 16757.32 | I5: 22078.71 | J5: 25694.55 | K5: 66020.12 | L5: 64530.58
A6: D | B6: 30628651 | C6: 85 | D6: 10000 | E6: 3816944.4 | F6: 716840.77 | G6: 29790.79 | H6: 27742.67 | I6: 24286.58 | J6: 30535.56 | K6: 84612.93 | L6: 82564.81
A7: E | B7: 36028231 | C7: 110 | D7: 13000 | E7: 4841002.7 | F7: 716840.77 | G7: 55857.73 | H7: 44313.79 | I7: 26715.24 | J7: 37238.48 | K7: 119811.45 | L7: 108267.51
A8: F | B8: 45151659 | C8: 150 | D8: 16500 | E8: 4841002.7 | F8: 716840.77 | G8: 78573.2 | H8: 57719.64 | I8: 29386.76 | J8: 42824.25 | K8: 150784.21 | L8: 129930.65
A9: G | B9: 53995799 | C9: 200 | D9: 20000 | E9: 5771964.7 | F9: 716840.77 | G9: 142995.76 | H9: 71497.87 | I9: 41141.46 | J9: 46175.72 | K9: 230312.94 | L9: 158815.05
A10: H | B10: 81924660 | C10: 200 | D10: 20000 | E10: 8378658.5 | F10: 716840.77 | G10: 409623.31 | H10: 204811.64 | I10: 57598.04 | J10: 55485.33 | K10: 522706.68 | L10: 317895.01
A11: I | B11: 91699762 | C11: 200 | D11: 20000 | E11: 8378658.5 | F11: 716840.77 | G11: 814591.79 | H11: 325836.71 | I11: 80637.26 | J11: 68518.81 | K11: 963747.86 | L11: 474992.78
A12: J | B12: 1.0501252e+08 | C12: 200 | D12: 20000 | E12: 8378658.5 | F12: 716840.77 | G12: 977510.14 | H12: 391004.07 | I12: 112892.16 | J12: 76897.46 | K12: 1167299.8 | L12: 580793.69
A13: K | B13: 1.2661084e+08 | C13: 200 | D13: 20000 | E13: 8378658.5 | F13: 716840.77 | G13: 1368514.2 | H13: 456171.4 | I13: 158049.02 | J13: 87882.82 | K13: 1614446 | L13: 702103.24
A15: Tabla oficial de ARCA (https://www.afip.gob.ar/monotributo/categorias.asp), verificada el 29 de julio de 2026. La columna «Cat.» la usa la hoja «Mi monotributo»: no la borres.

Sheet Fuentes
A1: Fuentes oficiales
A2: Todos los datos de esta planilla se verificaron el 29 de julio de 2026 contra los documentos oficiales de abajo. Ningún blog, ningún resumen de terceros.
A4: Documento | B4: Link
A5: ARCA — Categorías del Monotributo (montos y parámetros vigentes) | B5: https://www.afip.gob.ar/monotributo/categorias.asp
A6: ARCA — Recategorización | B6: https://www.afip.gob.ar/monotributo/ayuda/recategorizacion.asp
A7: Ley 24.977 — Régimen Simplificado (texto actualizado, art. 9 del Anexo: la categoría la define el mayor de los parámetros) | B7: https://servicios.infoleg.gob.ar/infolegInternet/anexos/50000-54999/51609/texact.htm
A9: Planilla de calcular.ar. Las actualizaciones del año están incluidas en el precio: cuando ARCA actualiza las categorías (febrero y agosto), regeneramos la planilla y el mismo enlace de descarga te baja la versión al día.
