Workbook

Sheet Cómo usarla
A1: Cómo usar la planilla de alquileres
A3: 1 | B3: Abrí la hoja «Contrato 1» y reemplazá el ejemplo con los datos de tu contrato: dirección, inquilino, mes y año de inicio, alquiler inicial, índice y cada cuántos meses se ajusta. Sólo se tocan las celdas amarillas.
A4: 2 | B4: Si alquilás más de una propiedad, usá «Contrato 2», «Contrato 3»… hasta 6. La hoja «Mis contratos» las junta todas: cuánto cobrás hoy, cuándo toca el próximo aumento y qué hacer.
A5: 3 | B5: Cuando se aplica un aumento, abrí «Aviso de aumento», elegí el contrato y copiá el mensaje: trae el monto nuevo, la cuenta y la fuente oficial.
A6: 4 | B6: Cada mes, en «Recibo» elegís el contrato y el mes: el importe sale solo. Imprimís la hoja y tenés dos copias, una para tu inquilino y otra para vos.
A7: 5 | B7: La hoja «IPC» tiene la serie oficial del INDEC y la hoja «Fuentes», de dónde sale cada dato.
A9: COLORES
B10: Amarillo: lo completás vos.
B11: Verde: lo calcula la planilla. Están protegidas para que no se pisen sin querer (Revisar > Desproteger hoja, si alguna vez lo necesitás).
A13: LO QUE CONVIENE SABER
B14: • Desde el DNU 70/2023 el índice y la periodicidad del ajuste se pactan libremente (art. 1199 del Código Civil y Comercial). Lo más común en los contratos nuevos es el IPC del INDEC cada 3 o 4 meses.
B15: • El ajuste multiplica el alquiler por la variación del IPC del período. Los porcentajes mensuales se componen, no se suman: tres meses de 2% dan 6,12%, no 6%.
B16: • El INDEC publica el IPC de cada mes entre el 10 y el 15 del mes siguiente. Por eso hay dos formas de tomar los meses: los completos antes del ajuste (la de esta planilla y la de calcular.ar, por defecto) o los últimos publicados, que corren un mes atrás. Elegí la que diga tu contrato en «Meses del IPC que toma».
B17: • Si tu contrato ajusta por ICL (BCRA), Casa Propia u otro índice, elegí «Otro índice» y cargá el % de cada ajuste en el cronograma. El resto (recibo, aviso, tablero) funciona igual.
B18: • Los contratos firmados entre julio de 2020 y diciembre de 2023, con la ley 27.551, en general siguen con su esquema original (ajuste anual por ICL) hasta que terminan.
A20: CÓMO SE MANTIENE AL DÍA
B21: • El enlace de descarga que te llegó por mail no vence y siempre baja la última versión, con el IPC al día. Para pasar tus contratos: copiá las celdas amarillas de cada «Contrato» y pegalas en el mismo lugar de la versión nueva.
B22: • ¿Preferís no cambiar de archivo? Cuando salga un IPC nuevo, cargá el % del mes en la columna amarilla de la hoja «IPC» y todo se recalcula.
A24: Esta planilla da los mismos números que la calculadora gratuita de calcular.ar/inflacion/alquiler: es la misma serie oficial y la misma cuenta. Si alguna vez no coinciden, escribinos y lo corregimos. No es asesoramiento legal: la letra de tu contrato manda.

Sheet Mis contratos
A1: Mis contratos de alquiler
A2: ="IPC oficial del INDEC cargado hasta "&IPC!$J$4&". Cuando salga el siguiente, bajá la versión nueva desde el mismo enlace o cargalo en la hoja IPC."
A4: Contrato | B4: Propiedad | C4: Inquilino/a | D4: Alquiler hoy | E4: Rige desde | F4: Próximo ajuste | G4: Próximo estimado | H4: Qué hacer
A5: Contrato 1 | B5: =IF('Contrato 1'!$B$5="","",'Contrato 1'!$B$5&"") | C5: =IF('Contrato 1'!$B$6="","",'Contrato 1'!$B$6&"") | D5: ='Contrato 1'!$B$17 | E5: ='Contrato 1'!$B$18&"" | F5: ='Contrato 1'!$B$21&"" | G5: ='Contrato 1'!$B$22 | H5: =IF('Contrato 1'!$N$5=1,'Contrato 1'!$B$24,"Sin cargar todavía: completá la hoja «Contrato 1».")
A6: Contrato 2 | B6: =IF('Contrato 2'!$B$5="","",'Contrato 2'!$B$5&"") | C6: =IF('Contrato 2'!$B$6="","",'Contrato 2'!$B$6&"") | D6: ='Contrato 2'!$B$17 | E6: ='Contrato 2'!$B$18&"" | F6: ='Contrato 2'!$B$21&"" | G6: ='Contrato 2'!$B$22 | H6: =IF('Contrato 2'!$N$5=1,'Contrato 2'!$B$24,"Sin cargar todavía: completá la hoja «Contrato 2».")
A7: Contrato 3 | B7: =IF('Contrato 3'!$B$5="","",'Contrato 3'!$B$5&"") | C7: =IF('Contrato 3'!$B$6="","",'Contrato 3'!$B$6&"") | D7: ='Contrato 3'!$B$17 | E7: ='Contrato 3'!$B$18&"" | F7: ='Contrato 3'!$B$21&"" | G7: ='Contrato 3'!$B$22 | H7: =IF('Contrato 3'!$N$5=1,'Contrato 3'!$B$24,"Sin cargar todavía: completá la hoja «Contrato 3».")
A8: Contrato 4 | B8: =IF('Contrato 4'!$B$5="","",'Contrato 4'!$B$5&"") | C8: =IF('Contrato 4'!$B$6="","",'Contrato 4'!$B$6&"") | D8: ='Contrato 4'!$B$17 | E8: ='Contrato 4'!$B$18&"" | F8: ='Contrato 4'!$B$21&"" | G8: ='Contrato 4'!$B$22 | H8: =IF('Contrato 4'!$N$5=1,'Contrato 4'!$B$24,"Sin cargar todavía: completá la hoja «Contrato 4».")
A9: Contrato 5 | B9: =IF('Contrato 5'!$B$5="","",'Contrato 5'!$B$5&"") | C9: =IF('Contrato 5'!$B$6="","",'Contrato 5'!$B$6&"") | D9: ='Contrato 5'!$B$17 | E9: ='Contrato 5'!$B$18&"" | F9: ='Contrato 5'!$B$21&"" | G9: ='Contrato 5'!$B$22 | H9: =IF('Contrato 5'!$N$5=1,'Contrato 5'!$B$24,"Sin cargar todavía: completá la hoja «Contrato 5».")
A10: Contrato 6 | B10: =IF('Contrato 6'!$B$5="","",'Contrato 6'!$B$5&"") | C10: =IF('Contrato 6'!$B$6="","",'Contrato 6'!$B$6&"") | D10: ='Contrato 6'!$B$17 | E10: ='Contrato 6'!$B$18&"" | F10: ='Contrato 6'!$B$21&"" | G10: ='Contrato 6'!$B$22 | H10: =IF('Contrato 6'!$N$5=1,'Contrato 6'!$B$24,"Sin cargar todavía: completá la hoja «Contrato 6».")
A12: Esta hoja no se completa: junta lo que cargaste en cada «Contrato». Para el recibo del mes andá a la hoja «Recibo»; para avisarle el aumento a tu inquilino, a «Aviso de aumento».

Sheet Contrato 1
A1: Contrato 1
A2: Este contrato viene cargado con un ejemplo: reemplazá las celdas amarillas con los datos del tuyo. Las verdes se calculan solas.
A4: DATOS DEL CONTRATO
A5: Propiedad (dirección) | B5: Av. Corrientes 1234, 3° B (ejemplo) | N5: =IF(AND(N6>0,ISNUMBER(B9),ISNUMBER(B11),B11>0,ISNUMBER(B13),B13>=1,ISNUMBER(B10),B10>=1),1,0)
A6: Inquilino/a | B6: Laura Gómez (ejemplo) | N6: =IFERROR(MATCH(B8,IPC!$J$5:$J$16,0),0)
A7: Tu nombre (para el recibo y el aviso) | N7: =IF(N5=1,B9*12+N6-1,0)
A8: Mes de inicio del contrato | B8: septiembre | C8: El primer mes en que se cobró el valor inicial. | N8: =IF(N5=1,INT(B13),1)
A9: Año de inicio | B9: 2025 | N9: =IF(B14="Los últimos publicados",1,0)
A10: Duración (meses) | B10: 24 | N10: =IF(B12="Otro índice (cargo el %)",0,1)
A11: Alquiler inicial (el del primer mes) | B11: 500000 | N11: =IF(N5=1,MIN(INT((B10-1)/N8),60),0)
A12: Índice de ajuste | B12: IPC (INDEC) | C12: Si tu contrato ajusta por ICL, Casa Propia u otro índice, elegí «Otro» y cargá el % de cada ajuste en el cronograma (columna F). | N12: =IPC!$J$3
A13: Se ajusta cada (meses) | B13: 3 | C13: Trimestral = 3, cuatrimestral = 4, semestral = 6, anual = 12. | N13: =IPC!$J$2
A14: Meses del IPC que toma | B14: Los completos antes del ajuste | C14: «Completos»: un ajuste de julio usa el IPC de abril a junio (como la calculadora de calcular.ar). «Últimos publicados»: usa el de marzo a mayo, porque el de junio sale a mitad de julio. Fijate qué dice tu contrato. | N14: =IF(N5=0,0,IF(N10=0,1,IF(AND(N7-1-N9>=N13,N7-1-N9<=N12),1,0)))
N15: =COUNT(G29:G88)
A16: CÓMO VIENE EL CONTRATO | N16: =IF(N5=1,INDEX(G28:G88,N15+1),"")
A17: Alquiler que se cobra hoy | B17: =N16 | N17: =N15+1
A18: Rige desde | B18: =IF(N5=1,INDEX(B28:B88,N15+1),"") | N18: =IF(AND(N5=1,N17<=N11),1,0)
A19: Ajustes aplicados | B19: =IF(N5=1,N15,"") | N19: =N7+N17*N8-1-N9
A20: Aumento desde el inicio | B20: =IF(N5=1,N16/B11-1,"") | N20: =N19-N12
A21: Próximo ajuste | B21: =IF(N18=1,INDEX(B28:B88,N17+1),IF(N5=1,"No quedan ajustes antes de que termine","")) | N21: =INDEX(IPC!$D$5:$D$173,(N12)-IPC!$J$2+1)/INDEX(IPC!$D$5:$D$173,(N12-1)-IPC!$J$2+1)-1
A22: Próximo alquiler estimado | B22: =N22 | N22: =IF(AND(N18=1,N10=1,N14=1,N20>0,N20<=12),N16*INDEX(IPC!$D$5:$D$173,(N12)-IPC!$J$2+1)*(1+N21)^N20/INDEX(IPC!$D$5:$D$173,(N19-N8)-IPC!$J$2+1),"")
A23: Último mes del contrato | B23: =IF(N5=1,INDEX(IPC!$J$5:$J$16,MOD(N7+B10-1,12)+1)&" de "&INT((N7+B10-1)/12),"") | N23: =IF(ISNUMBER(N22),ROUND(N22,0),"")
A24: Qué hacer ahora | B24: =IF(N5=0,"Completá las celdas amarillas de arriba y acá aparece el cronograma de aumentos.",IF(N14=0,"Todavía no está publicado el IPC de "&INDEX(IPC!$J$5:$J$16,MOD(N7-1-N9,12)+1)&" de "&INT((N7-1-N9)/12)&", que es la base de este contrato. Mientras tanto se cobra el valor inicial.",IF(N18=0,"No quedan ajustes: el contrato termina en "&INDEX(IPC!$J$5:$J$16,MOD(N7+B10-1,12)+1)&" de "&INT((N7+B10-1)/12)&".",IF(N10=1,"El próximo ajuste rige desde "&B21&". Se calcula cuando el INDEC publique el IPC de "&INDEX(IPC!$J$5:$J$16,MOD(N19,12)+1)&" de "&INT((N19)/12)&" (sale entre el 10 y el 15 del mes siguiente)"&IF(ISNUMBER(N22),". Si la inflación siguiera como el último mes, el alquiler quedaría en unos $ "&N24&".","."),"El próximo ajuste rige desde "&B21&": cuando lo tengas, cargá el % del índice pactado en la columna F del cronograma.")))) | N24: =IF(ISNUMBER(N23),IF(N23>=1000000000,INT(N23/1000000000)&"."&RIGHT("00"&INT(MOD(N23,1000000000)/1000000),3)&"."&RIGHT("00"&INT(MOD(N23,1000000)/1000),3)&"."&RIGHT("00"&INT(MOD(N23,1000)/1),3),IF(N23>=1000000,INT(N23/1000000)&"."&RIGHT("00"&INT(MOD(N23,1000000)/1000),3)&"."&RIGHT("00"&INT(MOD(N23,1000)/1),3),IF(N23>=1000,INT(N23/1000)&"."&RIGHT("00"&INT(MOD(N23,1000)/1),3),""&N23))),"")
A26: CRONOGRAMA DE AJUSTES
A27: Ajuste | B27: Rige desde | C27: Mes del IPC base | D27: Mes del IPC final | E27: Variación | F27: % a mano (otro índice) | G27: Alquiler | H27: Estado
A28: =IF($N$5=1,"Valor inicial","") | B28: =IF($N$5=1,INDEX(IPC!$J$5:$J$16,MOD(J28,12)+1)&" de "&INT((J28)/12),"") | G28: =IF($N$5=1,B11,"") | H28: =IF($N$5=1,"Valor inicial del contrato","") | J28: =IF($N$5=1,$N$7+0*$N$8,"") | K28: =IF($N$5=1,J28-1-$N$9,"") | L28: =IF($N$5=1,K28-$N$8,"")
A29: =IF(AND($N$5=1,1<=$N$11),"1° ajuste","") | B29: =IF(AND($N$5=1,1<=$N$11),INDEX(IPC!$J$5:$J$16,MOD(J29,12)+1)&" de "&INT((J29)/12),"") | C29: =IF(AND(AND($N$5=1,1<=$N$11),$N$10=1),INDEX(IPC!$J$5:$J$16,MOD(L29,12)+1)&" de "&INT((L29)/12),"") | D29: =IF(AND(AND($N$5=1,1<=$N$11),$N$10=1),INDEX(IPC!$J$5:$J$16,MOD(K29,12)+1)&" de "&INT((K29)/12),"") | E29: =IF(NOT(AND($N$5=1,1<=$N$11)),"",IF($N$10=1,IF(AND($N$14=1,K29<=$N$12),INDEX(IPC!$D$5:$D$173,(K29)-IPC!$J$2+1)/INDEX(IPC!$D$5:$D$173,(L29)-IPC!$J$2+1)-1,""),IF(ISNUMBER(F29),F29/100,""))) | G29: =IF(AND(AND($N$5=1,1<=$N$11),ISNUMBER(G28),ISNUMBER(E29)),G28*(1+E29),"") | H29: =IF(NOT(AND($N$5=1,1<=$N$11)),"",IF(ISNUMBER(G29),"Aplicado",IF(ISNUMBER(G28),IF($N$10=1,"Falta el IPC de "&INDEX(IPC!$J$5:$J$16,MOD($N$12+1,12)+1)&" de "&INT(($N$12+1)/12),"Cargá el % de este ajuste en la columna F"),""))) | J29: =IF($N$5=1,$N$7+1*$N$8,"") | K29: =IF($N$5=1,J29-1-$N$9,"") | L29: =IF($N$5=1,K29-$N$8,"")
A30: =IF(AND($N$5=1,2<=$N$11),"2° ajuste","") | B30: =IF(AND($N$5=1,2<=$N$11),INDEX(IPC!$J$5:$J$16,MOD(J30,12)+1)&" de "&INT((J30)/12),"") | C30: =IF(AND(AND($N$5=1,2<=$N$11),$N$10=1),INDEX(IPC!$J$5:$J$16,MOD(L30,12)+1)&" de "&INT((L30)/12),"") | D30: =IF(AND(AND($N$5=1,2<=$N$11),$N$10=1),INDEX(IPC!$J$5:$J$16,MOD(K30,12)+1)&" de "&INT((K30)/12),"") | E30: =IF(NOT(AND($N$5=1,2<=$N$11)),"",IF($N$10=1,IF(AND($N$14=1,K30<=$N$12),INDEX(IPC!$D$5:$D$173,(K30)-IPC!$J$2+1)/INDEX(IPC!$D$5:$D$173,(L30)-IPC!$J$2+1)-1,""),IF(ISNUMBER(F30),F30/100,""))) | G30: =IF(AND(AND($N$5=1,2<=$N$11),ISNUMBER(G29),ISNUMBER(E30)),G29*(1+E30),"") | H30: =IF(NOT(AND($N$5=1,2<=$N$11)),"",IF(ISNUMBER(G30),"Aplicado",IF(ISNUMBER(G29),IF($N$10=1,"Falta el IPC de "&INDEX(IPC!$J$5:$J$16,MOD($N$12+1,12)+1)&" de "&INT(($N$12+1)/12),"Cargá el % de este ajuste en la columna F"),""))) | J30: =IF($N$5=1,$N$7+2*$N$8,"") | K30: =IF($N$5=1,J30-1-$N$9,"") | L30: =IF($N$5=1,K30-$N$8,"")
A31: =IF(AND($N$5=1,3<=$N$11),"3° ajuste","") | B31: =IF(AND($N$5=1,3<=$N$11),INDEX(IPC!$J$5:$J$16,MOD(J31,12)+1)&" de "&INT((J31)/12),"") | C31: =IF(AND(AND($N$5=1,3<=$N$11),$N$10=1),INDEX(IPC!$J$5:$J$16,MOD(L31,12)+1)&" de "&INT((L31)/12),"") | D31: =IF(AND(AND($N$5=1,3<=$N$11),$N$10=1),INDEX(IPC!$J$5:$J$16,MOD(K31,12)+1)&" de "&INT((K31)/12),"") | E31: =IF(NOT(AND($N$5=1,3<=$N$11)),"",IF($N$10=1,IF(AND($N$14=1,K31<=$N$12),INDEX(IPC!$D$5:$D$173,(K31)-IPC!$J$2+1)/INDEX(IPC!$D$5:$D$173,(L31)-IPC!$J$2+1)-1,""),IF(ISNUMBER(F31),F31/100,""))) | G31: =IF(AND(AND($N$5=1,3<=$N$11),ISNUMBER(G30),ISNUMBER(E31)),G30*(1+E31),"") | H31: =IF(NOT(AND($N$5=1,3<=$N$11)),"",IF(ISNUMBER(G31),"Aplicado",IF(ISNUMBER(G30),IF($N$10=1,"Falta el IPC de "&INDEX(IPC!$J$5:$J$16,MOD($N$12+1,12)+1)&" de "&INT(($N$12+1)/12),"Cargá el % de este ajuste en la columna F"),""))) | J31: =IF($N$5=1,$N$7+3*$N$8,"") | K31: =IF($N$5=1,J31-1-$N$9,"") | L31: =IF($N$5=1,K31-$N$8,"")
A32: =IF(AND($N$5=1,4<=$N$11),"4° ajuste","") | B32: =IF(AND($N$5=1,4<=$N$11),INDEX(IPC!$J$5:$J$16,MOD(J32,12)+1)&" de "&INT((J32)/12),"") | C32: =IF(AND(AND($N$5=1,4<=$N$11),$N$10=1),INDEX(IPC!$J$5:$J$16,MOD(L32,12)+1)&" de "&INT((L32)/12),"") | D32: =IF(AND(AND($N$5=1,4<=$N$11),$N$10=1),INDEX(IPC!$J$5:$J$16,MOD(K32,12)+1)&" de "&INT((K32)/12),"") | E32: =IF(NOT(AND($N$5=1,4<=$N$11)),"",IF($N$10=1,IF(AND($N$14=1,K32<=$N$12),INDEX(IPC!$D$5:$D$173,(K32)-IPC!$J$2+1)/INDEX(IPC!$D$5:$D$173,(L32)-IPC!$J$2+1)-1,""),IF(ISNUMBER(F32),F32/100,""))) | G32: =IF(AND(AND($N$5=1,4<=$N$11),ISNUMBER(G31),ISNUMBER(E32)),G31*(1+E32),"") | H32: =IF(NOT(AND($N$5=1,4<=$N$11)),"",IF(ISNUMBER(G32),"Aplicado",IF(ISNUMBER(G31),IF($N$10=1,"Falta el IPC de "&INDEX(IPC!$J$5:$J$16,MOD($N$12+1,12)+1)&" de "&INT(($N$12+1)/12),"Cargá el % de este ajuste en la columna F"),""))) | J32: =IF($N$5=1,$N$7+4*$N$8,"") | K32: =IF($N$5=1,J32-1-$N$9,"") | L32: =IF($N$5=1,K32-$N$8,"")
A33: =IF(AND($N$5=1,5<=$N$11),"5° ajuste","") | B33: =IF(AND($N$5=1,5<=$N$11),INDEX(IPC!$J$5:$J$16,MOD(J33,12)+1)&" de "&INT((J33)/12),"") | C33: =IF(AND(AND($N$5=1,5<=$N$11),$N$10=1),INDEX(IPC!$J$5:$J$16,MOD(L33,12)+1)&" de "&INT((L33)/12),"") | D33: =IF(AND(AND($N$5=1,5<=$N$11),$N$10=1),INDEX(IPC!$J$5:$J$16,MOD(K33,12)+1)&" de "&INT((K33)/12),"") | E33: =IF(NOT(AND($N$5=1,5<=$N$11)),"",IF($N$10=1,IF(AND($N$14=1,K33<=$N$12),INDEX(IPC!$D$5:$D$173,(K33)-IPC!$J$2+1)/INDEX(IPC!$D$5:$D$173,(L33)-IPC!$J$2+1)-1,""),IF(ISNUMBER(F33),F33/100,""))) | G33: =IF(AND(AND($N$5=1,5<=$N$11),ISNUMBER(G32),ISNUMBER(E33)),G32*(1+E33),"") | H33: =IF(NOT(AND($N$5=1,5<=$N$11)),"",IF(ISNUMBER(G33),"Aplicado",IF(ISNUMBER(G32),IF($N$10=1,"Falta el IPC de "&INDEX(IPC!$J$5:$J$16,MOD($N$12+1,12)+1)&" de "&INT(($N$12+1)/12),"Cargá el % de este ajuste en la columna F"),""))) | J33: =IF($N$5=1,$N$7+5*$N$8,"") | K33: =IF($N$5=1,J33-1-$N$9,"") | L33: =IF($N$5=1,K33-$N$8,"")
A34: =IF(AND($N$5=1,6<=$N$11),"6° ajuste","") | B34: =IF(AND($N$5=1,6<=$N$11),INDEX(IPC!$J$5:$J$16,MOD(J34,12)+1)&" de "&INT((J34)/12),"") | C34: =IF(AND(AND($N$5=1,6<=$N$11),$N$10=1),INDEX(IPC!$J$5:$J$16,MOD(L34,12)+1)&" de "&INT((L34)/12),"") | D34: =IF(AND(AND($N$5=1,6<=$N$11),$N$10=1),INDEX(IPC!$J$5:$J$16,MOD(K34,12)+1)&" de "&INT((K34)/12),"") | E34: =IF(NOT(AND($N$5=1,6<=$N$11)),"",IF($N$10=1,IF(AND($N$14=1,K34<=$N$12),INDEX(IPC!$D$5:$D$173,(K34)-IPC!$J$2+1)/INDEX(IPC!$D$5:$D$173,(L34)-IPC!$J$2+1)-1,""),IF(ISNUMBER(F34),F34/100,""))) | G34: =IF(AND(AND($N$5=1,6<=$N$11),ISNUMBER(G33),ISNUMBER(E34)),G33*(1+E34),"") | H34: =IF(NOT(AND($N$5=1,6<=$N$11)),"",IF(ISNUMBER(G34),"Aplicado",IF(ISNUMBER(G33),IF($N$10=1,"Falta el IPC de "&INDEX(IPC!$J$5:$J$16,MOD($N$12+1,12)+1)&" de "&INT(($N$12+1)/12),"Cargá el % de este ajuste en la columna F"),""))) | J34: =IF($N$5=1,$N$7+6*$N$8,"") | K34: =IF($N$5=1,J34-1-$N$9,"") | L34: =IF($N$5=1,K34-$N$8,"")
A35: =IF(AND($N$5=1,7<=$N$11),"7° ajuste","") | B35: =IF(AND($N$5=1,7<=$N$11),INDEX(IPC!$J$5:$J$16,MOD(J35,12)+1)&" de "&INT((J35)/12),"") | C35: =IF(AND(AND($N$5=1,7<=$N$11),$N$10=1),INDEX(IPC!$J$5:$J$16,MOD(L35,12)+1)&" de "&INT((L35)/12),"") | D35: =IF(AND(AND($N$5=1,7<=$N$11),$N$10=1),INDEX(IPC!$J$5:$J$16,MOD(K35,12)+1)&" de "&INT((K35)/12),"") | E35: =IF(NOT(AND($N$5=1,7<=$N$11)),"",IF($N$10=1,IF(AND($N$14=1,K35<=$N$12),INDEX(IPC!$D$5:$D$173,(K35)-IPC!$J$2+1)/INDEX(IPC!$D$5:$D$173,(L35)-IPC!$J$2+1)-1,""),IF(ISNUMBER(F35),F35/100,""))) | G35: =IF(AND(AND($N$5=1,7<=$N$11),ISNUMBER(G34),ISNUMBER(E35)),G34*(1+E35),"") | H35: =IF(NOT(AND($N$5=1,7<=$N$11)),"",IF(ISNUMBER(G35),"Aplicado",IF(ISNUMBER(G34),IF($N$10=1,"Falta el IPC de "&INDEX(IPC!$J$5:$J$16,MOD($N$12+1,12)+1)&" de "&INT(($N$12+1)/12),"Cargá el % de este ajuste en la columna F"),""))) | J35: =IF($N$5=1,$N$7+7*$N$8,"") | K35: =IF($N$5=1,J35-1-$N$9,"") | L35: =IF($N$5=1,K35-$N$8,"")
A36: =IF(AND($N$5=1,8<=$N$11),"8° ajuste","") | B36: =IF(AND($N$5=1,8<=$N$11),INDEX(IPC!$J$5:$J$16,MOD(J36,12)+1)&" de "&INT((J36)/12),"") | C36: =IF(AND(AND($N$5=1,8<=$N$11),$N$10=1),INDEX(IPC!$J$5:$J$16,MOD(L36,12)+1)&" de "&INT((L36)/12),"") | D36: =IF(AND(AND($N$5=1,8<=$N$11),$N$10=1),INDEX(IPC!$J$5:$J$16,MOD(K36,12)+1)&" de "&INT((K36)/12),"") | E36: =IF(NOT(AND($N$5=1,8<=$N$11)),"",IF($N$10=1,IF(AND($N$14=1,K36<=$N$12),INDEX(IPC!$D$5:$D$173,(K36)-IPC!$J$2+1)/INDEX(IPC!$D$5:$D$173,(L36)-IPC!$J$2+1)-1,""),IF(ISNUMBER(F36),F36/100,""))) | G36: =IF(AND(AND($N$5=1,8<=$N$11),ISNUMBER(G35),ISNUMBER(E36)),G35*(1+E36),"") | H36: =IF(NOT(AND($N$5=1,8<=$N$11)),"",IF(ISNUMBER(G36),"Aplicado",IF(ISNUMBER(G35),IF($N$10=1,"Falta el IPC de "&INDEX(IPC!$J$5:$J$16,MOD($N$12+1,12)+1)&" de "&INT(($N$12+1)/12),"Cargá el % de este ajuste en la columna F"),""))) | J36: =IF($N$5=1,$N$7+8*$N$8,"") | K36: =IF($N$5=1,J36-1-$N$9,"") | L36: =IF($N$5=1,K36-$N$8,"")
A37: =IF(AND($N$5=1,9<=$N$11),"9° ajuste","") | B37: =IF(AND($N$5=1,9<=$N$11),INDEX(IPC!$J$5:$J$16,MOD(J37,12)+1)&" de "&INT((J37)/12),"") | C37: =IF(AND(AND($N$5=1,9<=$N$11),$N$10=1),INDEX(IPC!$J$5:$J$16,MOD(L37,12)+1)&" de "&INT((L37)/12),"") | D37: =IF(AND(AND($N$5=1,9<=$N$11),$N$10=1),INDEX(IPC!$J$5:$J$16,MOD(K37,12)+1)&" de "&INT((K37)/12),"") | E37: =IF(NOT(AND($N$5=1,9<=$N$11)),"",IF($N$10=1,IF(AND($N$14=1,K37<=$N$12),INDEX(IPC!$D$5:$D$173,(K37)-IPC!$J$2+1)/INDEX(IPC!$D$5:$D$173,(L37)-IPC!$J$2+1)-1,""),IF(ISNUMBER(F37),F37/100,""))) | G37: =IF(AND(AND($N$5=1,9<=$N$11),ISNUMBER(G36),ISNUMBER(E37)),G36*(1+E37),"") | H37: =IF(NOT(AND($N$5=1,9<=$N$11)),"",IF(ISNUMBER(G37),"Aplicado",IF(ISNUMBER(G36),IF($N$10=1,"Falta el IPC de "&INDEX(IPC!$J$5:$J$16,MOD($N$12+1,12)+1)&" de "&INT(($N$12+1)/12),"Cargá el % de este ajuste en la columna F"),""))) | J37: =IF($N$5=1,$N$7+9*$N$8,"") | K37: =IF($N$5=1,J37-1-$N$9,"") | L37: =IF($N$5=1,K37-$N$8,"")
A38: =IF(AND($N$5=1,10<=$N$11),"10° ajuste","") | B38: =IF(AND($N$5=1,10<=$N$11),INDEX(IPC!$J$5:$J$16,MOD(J38,12)+1)&" de "&INT((J38)/12),"") | C38: =IF(AND(AND($N$5=1,10<=$N$11),$N$10=1),INDEX(IPC!$J$5:$J$16,MOD(L38,12)+1)&" de "&INT((L38)/12),"") | D38: =IF(AND(AND($N$5=1,10<=$N$11),$N$10=1),INDEX(IPC!$J$5:$J$16,MOD(K38,12)+1)&" de "&INT((K38)/12),"") | E38: =IF(NOT(AND($N$5=1,10<=$N$11)),"",IF($N$10=1,IF(AND($N$14=1,K38<=$N$12),INDEX(IPC!$D$5:$D$173,(K38)-IPC!$J$2+1)/INDEX(IPC!$D$5:$D$173,(L38)-IPC!$J$2+1)-1,""),IF(ISNUMBER(F38),F38/100,""))) | G38: =IF(AND(AND($N$5=1,10<=$N$11),ISNUMBER(G37),ISNUMBER(E38)),G37*(1+E38),"") | H38: =IF(NOT(AND($N$5=1,10<=$N$11)),"",IF(ISNUMBER(G38),"Aplicado",IF(ISNUMBER(G37),IF($N$10=1,"Falta el IPC de "&INDEX(IPC!$J$5:$J$16,MOD($N$12+1,12)+1)&" de "&INT(($N$12+1)/12),"Cargá el % de este ajuste en la columna F"),""))) | J38: =IF($N$5=1,$N$7+10*$N$8,"") | K38: =IF($N$5=1,J38-1-$N$9,"") | L38: =IF($N$5=1,K38-$N$8,"")
A39: =IF(AND($N$5=1,11<=$N$11),"11° ajuste","") | B39: =IF(AND($N$5=1,11<=$N$11),INDEX(IPC!$J$5:$J$16,MOD(J39,12)+1)&" de "&INT((J39)/12),"") | C39: =IF(AND(AND($N$5=1,11<=$N$11),$N$10=1),INDEX(IPC!$J$5:$J$16,MOD(L39,12)+1)&" de "&INT((L39)/12),"") | D39: =IF(AND(AND($N$5=1,11<=$N$11),$N$10=1),INDEX(IPC!$J$5:$J$16,MOD(K39,12)+1)&" de "&INT((K39)/12),"") | E39: =IF(NOT(AND($N$5=1,11<=$N$11)),"",IF($N$10=1,IF(AND($N$14=1,K39<=$N$12),INDEX(IPC!$D$5:$D$173,(K39)-IPC!$J$2+1)/INDEX(IPC!$D$5:$D$173,(L39)-IPC!$J$2+1)-1,""),IF(ISNUMBER(F39),F39/100,""))) | G39: =IF(AND(AND($N$5=1,11<=$N$11),ISNUMBER(G38),ISNUMBER(E39)),G38*(1+E39),"") | H39: =IF(NOT(AND($N$5=1,11<=$N$11)),"",IF(ISNUMBER(G39),"Aplicado",IF(ISNUMBER(G38),IF($N$10=1,"Falta el IPC de "&INDEX(IPC!$J$5:$J$16,MOD($N$12+1,12)+1)&" de "&INT(($N$12+1)/12),"Cargá el % de este ajuste en la columna F"),""))) | J39: =IF($N$5=1,$N$7+11*$N$8,"") | K39: =IF($N$5=1,J39-1-$N$9,"") | L39: =IF($N$5=1,K39-$N$8,"")
A40: =IF(AND($N$5=1,12<=$N$11),"12° ajuste","") | B40: =IF(AND($N$5=1,12<=$N$11),INDEX(IPC!$J$5:$J$16,MOD(J40,12)+1)&" de "&INT((J40)/12),"") | C40: =IF(AND(AND($N$5=1,12<=$N$11),$N$10=1),INDEX(IPC!$J$5:$J$16,MOD(L40,12)+1)&" de "&INT((L40)/12),"") | D40: =IF(AND(AND($N$5=1,12<=$N$11),$N$10=1),INDEX(IPC!$J$5:$J$16,MOD(K40,12)+1)&" de "&INT((K40)/12),"") | E40: =IF(NOT(AND($N$5=1,12<=$N$11)),"",IF($N$10=1,IF(AND($N$14=1,K40<=$N$12),INDEX(IPC!$D$5:$D$173,(K40)-IPC!$J$2+1)/INDEX(IPC!$D$5:$D$173,(L40)-IPC!$J$2+1)-1,""),IF(ISNUMBER(F40),F40/100,""))) | G40: =IF(AND(AND($N$5=1,12<=$N$11),ISNUMBER(G39),ISNUMBER(E40)),G39*(1+E40),"") | H40: =IF(NOT(AND($N$5=1,12<=$N$11)),"",IF(ISNUMBER(G40),"Aplicado",IF(ISNUMBER(G39),IF($N$10=1,"Falta el IPC de "&INDEX(IPC!$J$5:$J$16,MOD($N$12+1,12)+1)&" de "&INT(($N$12+1)/12),"Cargá el % de este ajuste en la columna F"),""))) | J40: =IF($N$5=1,$N$7+12*$N$8,"") | K40: =IF($N$5=1,J40-1-$N$9,"") | L40: =IF($N$5=1,K40-$N$8,"")
A41: =IF(AND($N$5=1,13<=$N$11),"13° ajuste","") | B41: =IF(AND($N$5=1,13<=$N$11),INDEX(IPC!$J$5:$J$16,MOD(J41,12)+1)&" de "&INT((J41)/12),"") | C41: =IF(AND(AND($N$5=1,13<=$N$11),$N$10=1),INDEX(IPC!$J$5:$J$16,MOD(L41,12)+1)&" de "&INT((L41)/12),"") | D41: =IF(AND(AND($N$5=1,13<=$N$11),$N$10=1),INDEX(IPC!$J$5:$J$16,MOD(K41,12)+1)&" de "&INT((K41)/12),"") | E41: =IF(NOT(AND($N$5=1,13<=$N$11)),"",IF($N$10=1,IF(AND($N$14=1,K41<=$N$12),INDEX(IPC!$D$5:$D$173,(K41)-IPC!$J$2+1)/INDEX(IPC!$D$5:$D$173,(L41)-IPC!$J$2+1)-1,""),IF(ISNUMBER(F41),F41/100,""))) | G41: =IF(AND(AND($N$5=1,13<=$N$11),ISNUMBER(G40),ISNUMBER(E41)),G40*(1+E41),"") | H41: =IF(NOT(AND($N$5=1,13<=$N$11)),"",IF(ISNUMBER(G41),"Aplicado",IF(ISNUMBER(G40),IF($N$10=1,"Falta el IPC de "&INDEX(IPC!$J$5:$J$16,MOD($N$12+1,12)+1)&" de "&INT(($N$12+1)/12),"Cargá el % de este ajuste en la columna F"),""))) | J41: =IF($N$5=1,$N$7+13*$N$8,"") | K41: =IF($N$5=1,J41-1-$N$9,"") | L41: =IF($N$5=1,K41-$N$8,"")
A42: =IF(AND($N$5=1,14<=$N$11),"14° ajuste","") | B42: =IF(AND($N$5=1,14<=$N$11),INDEX(IPC!$J$5:$J$16,MOD(J42,12)+1)&" de "&INT((J42)/12),"") | C42: =IF(AND(AND($N$5=1,14<=$N$11),$N$10=1),INDEX(IPC!$J$5:$J$16,MOD(L42,12)+1)&" de "&INT((L42)/12),"") | D42: =IF(AND(AND($N$5=1,14<=$N$11),$N$10=1),INDEX(IPC!$J$5:$J$16,MOD(K42,12)+1)&" de "&INT((K42)/12),"") | E42: =IF(NOT(AND($N$5=1,14<=$N$11)),"",IF($N$10=1,IF(AND($N$14=1,K42<=$N$12),INDEX(IPC!$D$5:$D$173,(K42)-IPC!$J$2+1)/INDEX(IPC!$D$5:$D$173,(L42)-IPC!$J$2+1)-1,""),IF(ISNUMBER(F42),F42/100,""))) | G42: =IF(AND(AND($N$5=1,14<=$N$11),ISNUMBER(G41),ISNUMBER(E42)),G41*(1+E42),"") | H42: =IF(NOT(AND($N$5=1,14<=$N$11)),"",IF(ISNUMBER(G42),"Aplicado",IF(ISNUMBER(G41),IF($N$10=1,"Falta el IPC de "&INDEX(IPC!$J$5:$J$16,MOD($N$12+1,12)+1)&" de "&INT(($N$12+1)/12),"Cargá el % de este ajuste en la columna F"),""))) | J42: =IF($N$5=1,$N$7+14*$N$8,"") | K42: =IF($N$5=1,J42-1-$N$9,"") | L42: =IF($N$5=1,K42-$N$8,"")
...

Sheet Contrato 2
A1: Contrato 2
A2: Completá las celdas amarillas con los datos del contrato. Las verdes se calculan solas.
A4: DATOS DEL CONTRATO
A5: Propiedad (dirección) | N5: =IF(AND(N6>0,ISNUMBER(B9),ISNUMBER(B11),B11>0,ISNUMBER(B13),B13>=1,ISNUMBER(B10),B10>=1),1,0)
A6: Inquilino/a | N6: =IFERROR(MATCH(B8,IPC!$J$5:$J$16,0),0)
A7: Tu nombre (para el recibo y el aviso) | N7: =IF(N5=1,B9*12+N6-1,0)
A8: Mes de inicio del contrato | C8: El primer mes en que se cobró el valor inicial. | N8: =IF(N5=1,INT(B13),1)
A9: Año de inicio | N9: =IF(B14="Los últimos publicados",1,0)
A10: Duración (meses) | B10: 24 | N10: =IF(B12="Otro índice (cargo el %)",0,1)
A11: Alquiler inicial (el del primer mes) | N11: =IF(N5=1,MIN(INT((B10-1)/N8),60),0)
A12: Índice de ajuste | B12: IPC (INDEC) | C12: Si tu contrato ajusta por ICL, Casa Propia u otro índice, elegí «Otro» y cargá el % de cada ajuste en el cronograma (columna F). | N12: =IPC!$J$3
A13: Se ajusta cada (meses) | B13: 3 | C13: Trimestral = 3, cuatrimestral = 4, semestral = 6, anual = 12. | N13: =IPC!$J$2
A14: Meses del IPC que toma | B14: Los completos antes del ajuste | C14: «Completos»: un ajuste de julio usa el IPC de abril a junio (como la calculadora de calcular.ar). «Últimos publicados»: usa el de marzo a mayo, porque el de junio sale a mitad de julio. Fijate qué dice tu contrato. | N14: =IF(N5=0,0,IF(N10=0,1,IF(AND(N7-1-N9>=N13,N7-1-N9<=N12),1,0)))
N15: =COUNT(G29:G88)
A16: CÓMO VIENE EL CONTRATO | N16: =IF(N5=1,INDEX(G28:G88,N15+1),"")
A17: Alquiler que se cobra hoy | B17: =N16 | N17: =N15+1
A18: Rige desde | B18: =IF(N5=1,INDEX(B28:B88,N15+1),"") | N18: =IF(AND(N5=1,N17<=N11),1,0)
A19: Ajustes aplicados | B19: =IF(N5=1,N15,"") | N19: =N7+N17*N8-1-N9
A20: Aumento desde el inicio | B20: =IF(N5=1,N16/B11-1,"") | N20: =N19-N12
A21: Próximo ajuste | B21: =IF(N18=1,INDEX(B28:B88,N17+1),IF(N5=1,"No quedan ajustes antes de que termine","")) | N21: =INDEX(IPC!$D$5:$D$173,(N12)-IPC!$J$2+1)/INDEX(IPC!$D$5:$D$173,(N12-1)-IPC!$J$2+1)-1
A22: Próximo alquiler estimado | B22: =N22 | N22: =IF(AND(N18=1,N10=1,N14=1,N20>0,N20<=12),N16*INDEX(IPC!$D$5:$D$173,(N12)-IPC!$J$2+1)*(1+N21)^N20/INDEX(IPC!$D$5:$D$173,(N19-N8)-IPC!$J$2+1),"")
A23: Último mes del contrato | B23: =IF(N5=1,INDEX(IPC!$J$5:$J$16,MOD(N7+B10-1,12)+1)&" de "&INT((N7+B10-1)/12),"") | N23: =IF(ISNUMBER(N22),ROUND(N22,0),"")
A24: Qué hacer ahora | B24: =IF(N5=0,"Completá las celdas amarillas de arriba y acá aparece el cronograma de aumentos.",IF(N14=0,"Todavía no está publicado el IPC de "&INDEX(IPC!$J$5:$J$16,MOD(N7-1-N9,12)+1)&" de "&INT((N7-1-N9)/12)&", que es la base de este contrato. Mientras tanto se cobra el valor inicial.",IF(N18=0,"No quedan ajustes: el contrato termina en "&INDEX(IPC!$J$5:$J$16,MOD(N7+B10-1,12)+1)&" de "&INT((N7+B10-1)/12)&".",IF(N10=1,"El próximo ajuste rige desde "&B21&". Se calcula cuando el INDEC publique el IPC de "&INDEX(IPC!$J$5:$J$16,MOD(N19,12)+1)&" de "&INT((N19)/12)&" (sale entre el 10 y el 15 del mes siguiente)"&IF(ISNUMBER(N22),". Si la inflación siguiera como el último mes, el alquiler quedaría en unos $ "&N24&".","."),"El próximo ajuste rige desde "&B21&": cuando lo tengas, cargá el % del índice pactado en la columna F del cronograma.")))) | N24: =IF(ISNUMBER(N23),IF(N23>=1000000000,INT(N23/1000000000)&"."&RIGHT("00"&INT(MOD(N23,1000000000)/1000000),3)&"."&RIGHT("00"&INT(MOD(N23,1000000)/1000),3)&"."&RIGHT("00"&INT(MOD(N23,1000)/1),3),IF(N23>=1000000,INT(N23/1000000)&"."&RIGHT("00"&INT(MOD(N23,1000000)/1000),3)&"."&RIGHT("00"&INT(MOD(N23,1000)/1),3),IF(N23>=1000,INT(N23/1000)&"."&RIGHT("00"&INT(MOD(N23,1000)/1),3),""&N23))),"")
A26: CRONOGRAMA DE AJUSTES
A27: Ajuste | B27: Rige desde | C27: Mes del IPC base | D27: Mes del IPC final | E27: Variación | F27: % a mano (otro índice) | G27: Alquiler | H27: Estado
A28: =IF($N$5=1,"Valor inicial","") | B28: =IF($N$5=1,INDEX(IPC!$J$5:$J$16,MOD(J28,12)+1)&" de "&INT((J28)/12),"") | G28: =IF($N$5=1,B11,"") | H28: =IF($N$5=1,"Valor inicial del contrato","") | J28: =IF($N$5=1,$N$7+0*$N$8,"") | K28: =IF($N$5=1,J28-1-$N$9,"") | L28: =IF($N$5=1,K28-$N$8,"")
A29: =IF(AND($N$5=1,1<=$N$11),"1° ajuste","") | B29: =IF(AND($N$5=1,1<=$N$11),INDEX(IPC!$J$5:$J$16,MOD(J29,12)+1)&" de "&INT((J29)/12),"") | C29: =IF(AND(AND($N$5=1,1<=$N$11),$N$10=1),INDEX(IPC!$J$5:$J$16,MOD(L29,12)+1)&" de "&INT((L29)/12),"") | D29: =IF(AND(AND($N$5=1,1<=$N$11),$N$10=1),INDEX(IPC!$J$5:$J$16,MOD(K29,12)+1)&" de "&INT((K29)/12),"") | E29: =IF(NOT(AND($N$5=1,1<=$N$11)),"",IF($N$10=1,IF(AND($N$14=1,K29<=$N$12),INDEX(IPC!$D$5:$D$173,(K29)-IPC!$J$2+1)/INDEX(IPC!$D$5:$D$173,(L29)-IPC!$J$2+1)-1,""),IF(ISNUMBER(F29),F29/100,""))) | G29: =IF(AND(AND($N$5=1,1<=$N$11),ISNUMBER(G28),ISNUMBER(E29)),G28*(1+E29),"") | H29: =IF(NOT(AND($N$5=1,1<=$N$11)),"",IF(ISNUMBER(G29),"Aplicado",IF(ISNUMBER(G28),IF($N$10=1,"Falta el IPC de "&INDEX(IPC!$J$5:$J$16,MOD($N$12+1,12)+1)&" de "&INT(($N$12+1)/12),"Cargá el % de este ajuste en la columna F"),""))) | J29: =IF($N$5=1,$N$7+1*$N$8,"") | K29: =IF($N$5=1,J29-1-$N$9,"") | L29: =IF($N$5=1,K29-$N$8,"")
A30: =IF(AND($N$5=1,2<=$N$11),"2° ajuste","") | B30: =IF(AND($N$5=1,2<=$N$11),INDEX(IPC!$J$5:$J$16,MOD(J30,12)+1)&" de "&INT((J30)/12),"") | C30: =IF(AND(AND($N$5=1,2<=$N$11),$N$10=1),INDEX(IPC!$J$5:$J$16,MOD(L30,12)+1)&" de "&INT((L30)/12),"") | D30: =IF(AND(AND($N$5=1,2<=$N$11),$N$10=1),INDEX(IPC!$J$5:$J$16,MOD(K30,12)+1)&" de "&INT((K30)/12),"") | E30: =IF(NOT(AND($N$5=1,2<=$N$11)),"",IF($N$10=1,IF(AND($N$14=1,K30<=$N$12),INDEX(IPC!$D$5:$D$173,(K30)-IPC!$J$2+1)/INDEX(IPC!$D$5:$D$173,(L30)-IPC!$J$2+1)-1,""),IF(ISNUMBER(F30),F30/100,""))) | G30: =IF(AND(AND($N$5=1,2<=$N$11),ISNUMBER(G29),ISNUMBER(E30)),G29*(1+E30),"") | H30: =IF(NOT(AND($N$5=1,2<=$N$11)),"",IF(ISNUMBER(G30),"Aplicado",IF(ISNUMBER(G29),IF($N$10=1,"Falta el IPC de "&INDEX(IPC!$J$5:$J$16,MOD($N$12+1,12)+1)&" de "&INT(($N$12+1)/12),"Cargá el % de este ajuste en la columna F"),""))) | J30: =IF($N$5=1,$N$7+2*$N$8,"") | K30: =IF($N$5=1,J30-1-$N$9,"") | L30: =IF($N$5=1,K30-$N$8,"")
A31: =IF(AND($N$5=1,3<=$N$11),"3° ajuste","") | B31: =IF(AND($N$5=1,3<=$N$11),INDEX(IPC!$J$5:$J$16,MOD(J31,12)+1)&" de "&INT((J31)/12),"") | C31: =IF(AND(AND($N$5=1,3<=$N$11),$N$10=1),INDEX(IPC!$J$5:$J$16,MOD(L31,12)+1)&" de "&INT((L31)/12),"") | D31: =IF(AND(AND($N$5=1,3<=$N$11),$N$10=1),INDEX(IPC!$J$5:$J$16,MOD(K31,12)+1)&" de "&INT((K31)/12),"") | E31: =IF(NOT(AND($N$5=1,3<=$N$11)),"",IF($N$10=1,IF(AND($N$14=1,K31<=$N$12),INDEX(IPC!$D$5:$D$173,(K31)-IPC!$J$2+1)/INDEX(IPC!$D$5:$D$173,(L31)-IPC!$J$2+1)-1,""),IF(ISNUMBER(F31),F31/100,""))) | G31: =IF(AND(AND($N$5=1,3<=$N$11),ISNUMBER(G30),ISNUMBER(E31)),G30*(1+E31),"") | H31: =IF(NOT(AND($N$5=1,3<=$N$11)),"",IF(ISNUMBER(G31),"Aplicado",IF(ISNUMBER(G30),IF($N$10=1,"Falta el IPC de "&INDEX(IPC!$J$5:$J$16,MOD($N$12+1,12)+1)&" de "&INT(($N$12+1)/12),"Cargá el % de este ajuste en la columna F"),""))) | J31: =IF($N$5=1,$N$7+3*$N$8,"") | K31: =IF($N$5=1,J31-1-$N$9,"") | L31: =IF($N$5=1,K31-$N$8,"")
A32: =IF(AND($N$5=1,4<=$N$11),"4° ajuste","") | B32: =IF(AND($N$5=1,4<=$N$11),INDEX(IPC!$J$5:$J$16,MOD(J32,12)+1)&" de "&INT((J32)/12),"") | C32: =IF(AND(AND($N$5=1,4<=$N$11),$N$10=1),INDEX(IPC!$J$5:$J$16,MOD(L32,12)+1)&" de "&INT((L32)/12),"") | D32: =IF(AND(AND($N$5=1,4<=$N$11),$N$10=1),INDEX(IPC!$J$5:$J$16,MOD(K32,12)+1)&" de "&INT((K32)/12),"") | E32: =IF(NOT(AND($N$5=1,4<=$N$11)),"",IF($N$10=1,IF(AND($N$14=1,K32<=$N$12),INDEX(IPC!$D$5:$D$173,(K32)-IPC!$J$2+1)/INDEX(IPC!$D$5:$D$173,(L32)-IPC!$J$2+1)-1,""),IF(ISNUMBER(F32),F32/100,""))) | G32: =IF(AND(AND($N$5=1,4<=$N$11),ISNUMBER(G31),ISNUMBER(E32)),G31*(1+E32),"") | H32: =IF(NOT(AND($N$5=1,4<=$N$11)),"",IF(ISNUMBER(G32),"Aplicado",IF(ISNUMBER(G31),IF($N$10=1,"Falta el IPC de "&INDEX(IPC!$J$5:$J$16,MOD($N$12+1,12)+1)&" de "&INT(($N$12+1)/12),"Cargá el % de este ajuste en la columna F"),""))) | J32: =IF($N$5=1,$N$7+4*$N$8,"") | K32: =IF($N$5=1,J32-1-$N$9,"") | L32: =IF($N$5=1,K32-$N$8,"")
A33: =IF(AND($N$5=1,5<=$N$11),"5° ajuste","") | B33: =IF(AND($N$5=1,5<=$N$11),INDEX(IPC!$J$5:$J$16,MOD(J33,12)+1)&" de "&INT((J33)/12),"") | C33: =IF(AND(AND($N$5=1,5<=$N$11),$N$10=1),INDEX(IPC!$J$5:$J$16,MOD(L33,12)+1)&" de "&INT((L33)/12),"") | D33: =IF(AND(AND($N$5=1,5<=$N$11),$N$10=1),INDEX(IPC!$J$5:$J$16,MOD(K33,12)+1)&" de "&INT((K33)/12),"") | E33: =IF(NOT(AND($N$5=1,5<=$N$11)),"",IF($N$10=1,IF(AND($N$14=1,K33<=$N$12),INDEX(IPC!$D$5:$D$173,(K33)-IPC!$J$2+1)/INDEX(IPC!$D$5:$D$173,(L33)-IPC!$J$2+1)-1,""),IF(ISNUMBER(F33),F33/100,""))) | G33: =IF(AND(AND($N$5=1,5<=$N$11),ISNUMBER(G32),ISNUMBER(E33)),G32*(1+E33),"") | H33: =IF(NOT(AND($N$5=1,5<=$N$11)),"",IF(ISNUMBER(G33),"Aplicado",IF(ISNUMBER(G32),IF($N$10=1,"Falta el IPC de "&INDEX(IPC!$J$5:$J$16,MOD($N$12+1,12)+1)&" de "&INT(($N$12+1)/12),"Cargá el % de este ajuste en la columna F"),""))) | J33: =IF($N$5=1,$N$7+5*$N$8,"") | K33: =IF($N$5=1,J33-1-$N$9,"") | L33: =IF($N$5=1,K33-$N$8,"")
A34: =IF(AND($N$5=1,6<=$N$11),"6° ajuste","") | B34: =IF(AND($N$5=1,6<=$N$11),INDEX(IPC!$J$5:$J$16,MOD(J34,12)+1)&" de "&INT((J34)/12),"") | C34: =IF(AND(AND($N$5=1,6<=$N$11),$N$10=1),INDEX(IPC!$J$5:$J$16,MOD(L34,12)+1)&" de "&INT((L34)/12),"") | D34: =IF(AND(AND($N$5=1,6<=$N$11),$N$10=1),INDEX(IPC!$J$5:$J$16,MOD(K34,12)+1)&" de "&INT((K34)/12),"") | E34: =IF(NOT(AND($N$5=1,6<=$N$11)),"",IF($N$10=1,IF(AND($N$14=1,K34<=$N$12),INDEX(IPC!$D$5:$D$173,(K34)-IPC!$J$2+1)/INDEX(IPC!$D$5:$D$173,(L34)-IPC!$J$2+1)-1,""),IF(ISNUMBER(F34),F34/100,""))) | G34: =IF(AND(AND($N$5=1,6<=$N$11),ISNUMBER(G33),ISNUMBER(E34)),G33*(1+E34),"") | H34: =IF(NOT(AND($N$5=1,6<=$N$11)),"",IF(ISNUMBER(G34),"Aplicado",IF(ISNUMBER(G33),IF($N$10=1,"Falta el IPC de "&INDEX(IPC!$J$5:$J$16,MOD($N$12+1,12)+1)&" de "&INT(($N$12+1)/12),"Cargá el % de este ajuste en la columna F"),""))) | J34: =IF($N$5=1,$N$7+6*$N$8,"") | K34: =IF($N$5=1,J34-1-$N$9,"") | L34: =IF($N$5=1,K34-$N$8,"")
A35: =IF(AND($N$5=1,7<=$N$11),"7° ajuste","") | B35: =IF(AND($N$5=1,7<=$N$11),INDEX(IPC!$J$5:$J$16,MOD(J35,12)+1)&" de "&INT((J35)/12),"") | C35: =IF(AND(AND($N$5=1,7<=$N$11),$N$10=1),INDEX(IPC!$J$5:$J$16,MOD(L35,12)+1)&" de "&INT((L35)/12),"") | D35: =IF(AND(AND($N$5=1,7<=$N$11),$N$10=1),INDEX(IPC!$J$5:$J$16,MOD(K35,12)+1)&" de "&INT((K35)/12),"") | E35: =IF(NOT(AND($N$5=1,7<=$N$11)),"",IF($N$10=1,IF(AND($N$14=1,K35<=$N$12),INDEX(IPC!$D$5:$D$173,(K35)-IPC!$J$2+1)/INDEX(IPC!$D$5:$D$173,(L35)-IPC!$J$2+1)-1,""),IF(ISNUMBER(F35),F35/100,""))) | G35: =IF(AND(AND($N$5=1,7<=$N$11),ISNUMBER(G34),ISNUMBER(E35)),G34*(1+E35),"") | H35: =IF(NOT(AND($N$5=1,7<=$N$11)),"",IF(ISNUMBER(G35),"Aplicado",IF(ISNUMBER(G34),IF($N$10=1,"Falta el IPC de "&INDEX(IPC!$J$5:$J$16,MOD($N$12+1,12)+1)&" de "&INT(($N$12+1)/12),"Cargá el % de este ajuste en la columna F"),""))) | J35: =IF($N$5=1,$N$7+7*$N$8,"") | K35: =IF($N$5=1,J35-1-$N$9,"") | L35: =IF($N$5=1,K35-$N$8,"")
A36: =IF(AND($N$5=1,8<=$N$11),"8° ajuste","") | B36: =IF(AND($N$5=1,8<=$N$11),INDEX(IPC!$J$5:$J$16,MOD(J36,12)+1)&" de "&INT((J36)/12),"") | C36: =IF(AND(AND($N$5=1,8<=$N$11),$N$10=1),INDEX(IPC!$J$5:$J$16,MOD(L36,12)+1)&" de "&INT((L36)/12),"") | D36: =IF(AND(AND($N$5=1,8<=$N$11),$N$10=1),INDEX(IPC!$J$5:$J$16,MOD(K36,12)+1)&" de "&INT((K36)/12),"") | E36: =IF(NOT(AND($N$5=1,8<=$N$11)),"",IF($N$10=1,IF(AND($N$14=1,K36<=$N$12),INDEX(IPC!$D$5:$D$173,(K36)-IPC!$J$2+1)/INDEX(IPC!$D$5:$D$173,(L36)-IPC!$J$2+1)-1,""),IF(ISNUMBER(F36),F36/100,""))) | G36: =IF(AND(AND($N$5=1,8<=$N$11),ISNUMBER(G35),ISNUMBER(E36)),G35*(1+E36),"") | H36: =IF(NOT(AND($N$5=1,8<=$N$11)),"",IF(ISNUMBER(G36),"Aplicado",IF(ISNUMBER(G35),IF($N$10=1,"Falta el IPC de "&INDEX(IPC!$J$5:$J$16,MOD($N$12+1,12)+1)&" de "&INT(($N$12+1)/12),"Cargá el % de este ajuste en la columna F"),""))) | J36: =IF($N$5=1,$N$7+8*$N$8,"") | K36: =IF($N$5=1,J36-1-$N$9,"") | L36: =IF($N$5=1,K36-$N$8,"")
A37: =IF(AND($N$5=1,9<=$N$11),"9° ajuste","") | B37: =IF(AND($N$5=1,9<=$N$11),INDEX(IPC!$J$5:$J$16,MOD(J37,12)+1)&" de "&INT((J37)/12),"") | C37: =IF(AND(AND($N$5=1,9<=$N$11),$N$10=1),INDEX(IPC!$J$5:$J$16,MOD(L37,12)+1)&" de "&INT((L37)/12),"") | D37: =IF(AND(AND($N$5=1,9<=$N$11),$N$10=1),INDEX(IPC!$J$5:$J$16,MOD(K37,12)+1)&" de "&INT((K37)/12),"") | E37: =IF(NOT(AND($N$5=1,9<=$N$11)),"",IF($N$10=1,IF(AND($N$14=1,K37<=$N$12),INDEX(IPC!$D$5:$D$173,(K37)-IPC!$J$2+1)/INDEX(IPC!$D$5:$D$173,(L37)-IPC!$J$2+1)-1,""),IF(ISNUMBER(F37),F37/100,""))) | G37: =IF(AND(AND($N$5=1,9<=$N$11),ISNUMBER(G36),ISNUMBER(E37)),G36*(1+E37),"") | H37: =IF(NOT(AND($N$5=1,9<=$N$11)),"",IF(ISNUMBER(G37),"Aplicado",IF(ISNUMBER(G36),IF($N$10=1,"Falta el IPC de "&INDEX(IPC!$J$5:$J$16,MOD($N$12+1,12)+1)&" de "&INT(($N$12+1)/12),"Cargá el % de este ajuste en la columna F"),""))) | J37: =IF($N$5=1,$N$7+9*$N$8,"") | K37: =IF($N$5=1,J37-1-$N$9,"") | L37: =IF($N$5=1,K37-$N$8,"")
A38: =IF(AND($N$5=1,10<=$N$11),"10° ajuste","") | B38: =IF(AND($N$5=1,10<=$N$11),INDEX(IPC!$J$5:$J$16,MOD(J38,12)+1)&" de "&INT((J38)/12),"") | C38: =IF(AND(AND($N$5=1,10<=$N$11),$N$10=1),INDEX(IPC!$J$5:$J$16,MOD(L38,12)+1)&" de "&INT((L38)/12),"") | D38: =IF(AND(AND($N$5=1,10<=$N$11),$N$10=1),INDEX(IPC!$J$5:$J$16,MOD(K38,12)+1)&" de "&INT((K38)/12),"") | E38: =IF(NOT(AND($N$5=1,10<=$N$11)),"",IF($N$10=1,IF(AND($N$14=1,K38<=$N$12),INDEX(IPC!$D$5:$D$173,(K38)-IPC!$J$2+1)/INDEX(IPC!$D$5:$D$173,(L38)-IPC!$J$2+1)-1,""),IF(ISNUMBER(F38),F38/100,""))) | G38: =IF(AND(AND($N$5=1,10<=$N$11),ISNUMBER(G37),ISNUMBER(E38)),G37*(1+E38),"") | H38: =IF(NOT(AND($N$5=1,10<=$N$11)),"",IF(ISNUMBER(G38),"Aplicado",IF(ISNUMBER(G37),IF($N$10=1,"Falta el IPC de "&INDEX(IPC!$J$5:$J$16,MOD($N$12+1,12)+1)&" de "&INT(($N$12+1)/12),"Cargá el % de este ajuste en la columna F"),""))) | J38: =IF($N$5=1,$N$7+10*$N$8,"") | K38: =IF($N$5=1,J38-1-$N$9,"") | L38: =IF($N$5=1,K38-$N$8,"")
A39: =IF(AND($N$5=1,11<=$N$11),"11° ajuste","") | B39: =IF(AND($N$5=1,11<=$N$11),INDEX(IPC!$J$5:$J$16,MOD(J39,12)+1)&" de "&INT((J39)/12),"") | C39: =IF(AND(AND($N$5=1,11<=$N$11),$N$10=1),INDEX(IPC!$J$5:$J$16,MOD(L39,12)+1)&" de "&INT((L39)/12),"") | D39: =IF(AND(AND($N$5=1,11<=$N$11),$N$10=1),INDEX(IPC!$J$5:$J$16,MOD(K39,12)+1)&" de "&INT((K39)/12),"") | E39: =IF(NOT(AND($N$5=1,11<=$N$11)),"",IF($N$10=1,IF(AND($N$14=1,K39<=$N$12),INDEX(IPC!$D$5:$D$173,(K39)-IPC!$J$2+1)/INDEX(IPC!$D$5:$D$173,(L39)-IPC!$J$2+1)-1,""),IF(ISNUMBER(F39),F39/100,""))) | G39: =IF(AND(AND($N$5=1,11<=$N$11),ISNUMBER(G38),ISNUMBER(E39)),G38*(1+E39),"") | H39: =IF(NOT(AND($N$5=1,11<=$N$11)),"",IF(ISNUMBER(G39),"Aplicado",IF(ISNUMBER(G38),IF($N$10=1,"Falta el IPC de "&INDEX(IPC!$J$5:$J$16,MOD($N$12+1,12)+1)&" de "&INT(($N$12+1)/12),"Cargá el % de este ajuste en la columna F"),""))) | J39: =IF($N$5=1,$N$7+11*$N$8,"") | K39: =IF($N$5=1,J39-1-$N$9,"") | L39: =IF($N$5=1,K39-$N$8,"")
A40: =IF(AND($N$5=1,12<=$N$11),"12° ajuste","") | B40: =IF(AND($N$5=1,12<=$N$11),INDEX(IPC!$J$5:$J$16,MOD(J40,12)+1)&" de "&INT((J40)/12),"") | C40: =IF(AND(AND($N$5=1,12<=$N$11),$N$10=1),INDEX(IPC!$J$5:$J$16,MOD(L40,12)+1)&" de "&INT((L40)/12),"") | D40: =IF(AND(AND($N$5=1,12<=$N$11),$N$10=1),INDEX(IPC!$J$5:$J$16,MOD(K40,12)+1)&" de "&INT((K40)/12),"") | E40: =IF(NOT(AND($N$5=1,12<=$N$11)),"",IF($N$10=1,IF(AND($N$14=1,K40<=$N$12),INDEX(IPC!$D$5:$D$173,(K40)-IPC!$J$2+1)/INDEX(IPC!$D$5:$D$173,(L40)-IPC!$J$2+1)-1,""),IF(ISNUMBER(F40),F40/100,""))) | G40: =IF(AND(AND($N$5=1,12<=$N$11),ISNUMBER(G39),ISNUMBER(E40)),G39*(1+E40),"") | H40: =IF(NOT(AND($N$5=1,12<=$N$11)),"",IF(ISNUMBER(G40),"Aplicado",IF(ISNUMBER(G39),IF($N$10=1,"Falta el IPC de "&INDEX(IPC!$J$5:$J$16,MOD($N$12+1,12)+1)&" de "&INT(($N$12+1)/12),"Cargá el % de este ajuste en la columna F"),""))) | J40: =IF($N$5=1,$N$7+12*$N$8,"") | K40: =IF($N$5=1,J40-1-$N$9,"") | L40: =IF($N$5=1,K40-$N$8,"")
A41: =IF(AND($N$5=1,13<=$N$11),"13° ajuste","") | B41: =IF(AND($N$5=1,13<=$N$11),INDEX(IPC!$J$5:$J$16,MOD(J41,12)+1)&" de "&INT((J41)/12),"") | C41: =IF(AND(AND($N$5=1,13<=$N$11),$N$10=1),INDEX(IPC!$J$5:$J$16,MOD(L41,12)+1)&" de "&INT((L41)/12),"") | D41: =IF(AND(AND($N$5=1,13<=$N$11),$N$10=1),INDEX(IPC!$J$5:$J$16,MOD(K41,12)+1)&" de "&INT((K41)/12),"") | E41: =IF(NOT(AND($N$5=1,13<=$N$11)),"",IF($N$10=1,IF(AND($N$14=1,K41<=$N$12),INDEX(IPC!$D$5:$D$173,(K41)-IPC!$J$2+1)/INDEX(IPC!$D$5:$D$173,(L41)-IPC!$J$2+1)-1,""),IF(ISNUMBER(F41),F41/100,""))) | G41: =IF(AND(AND($N$5=1,13<=$N$11),ISNUMBER(G40),ISNUMBER(E41)),G40*(1+E41),"") | H41: =IF(NOT(AND($N$5=1,13<=$N$11)),"",IF(ISNUMBER(G41),"Aplicado",IF(ISNUMBER(G40),IF($N$10=1,"Falta el IPC de "&INDEX(IPC!$J$5:$J$16,MOD($N$12+1,12)+1)&" de "&INT(($N$12+1)/12),"Cargá el % de este ajuste en la columna F"),""))) | J41: =IF($N$5=1,$N$7+13*$N$8,"") | K41: =IF($N$5=1,J41-1-$N$9,"") | L41: =IF($N$5=1,K41-$N$8,"")
A42: =IF(AND($N$5=1,14<=$N$11),"14° ajuste","") | B42: =IF(AND($N$5=1,14<=$N$11),INDEX(IPC!$J$5:$J$16,MOD(J42,12)+1)&" de "&INT((J42)/12),"") | C42: =IF(AND(AND($N$5=1,14<=$N$11),$N$10=1),INDEX(IPC!$J$5:$J$16,MOD(L42,12)+1)&" de "&INT((L42)/12),"") | D42: =IF(AND(AND($N$5=1,14<=$N$11),$N$10=1),INDEX(IPC!$J$5:$J$16,MOD(K42,12)+1)&" de "&INT((K42)/12),"") | E42: =IF(NOT(AND($N$5=1,14<=$N$11)),"",IF($N$10=1,IF(AND($N$14=1,K42<=$N$12),INDEX(IPC!$D$5:$D$173,(K42)-IPC!$J$2+1)/INDEX(IPC!$D$5:$D$173,(L42)-IPC!$J$2+1)-1,""),IF(ISNUMBER(F42),F42/100,""))) | G42: =IF(AND(AND($N$5=1,14<=$N$11),ISNUMBER(G41),ISNUMBER(E42)),G41*(1+E42),"") | H42: =IF(NOT(AND($N$5=1,14<=$N$11)),"",IF(ISNUMBER(G42),"Aplicado",IF(ISNUMBER(G41),IF($N$10=1,"Falta el IPC de "&INDEX(IPC!$J$5:$J$16,MOD($N$12+1,12)+1)&" de "&INT(($N$12+1)/12),"Cargá el % de este ajuste en la columna F"),""))) | J42: =IF($N$5=1,$N$7+14*$N$8,"") | K42: =IF($N$5=1,J42-1-$N$9,"") | L42: =IF($N$5=1,K42-$N$8,"")
...

Sheet Contrato 3
A1: Contrato 3
A2: Completá las celdas amarillas con los datos del contrato. Las verdes se calculan solas.
A4: DATOS DEL CONTRATO
A5: Propiedad (dirección) | N5: =IF(AND(N6>0,ISNUMBER(B9),ISNUMBER(B11),B11>0,ISNUMBER(B13),B13>=1,ISNUMBER(B10),B10>=1),1,0)
A6: Inquilino/a | N6: =IFERROR(MATCH(B8,IPC!$J$5:$J$16,0),0)
A7: Tu nombre (para el recibo y el aviso) | N7: =IF(N5=1,B9*12+N6-1,0)
A8: Mes de inicio del contrato | C8: El primer mes en que se cobró el valor inicial. | N8: =IF(N5=1,INT(B13),1)
A9: Año de inicio | N9: =IF(B14="Los últimos publicados",1,0)
A10: Duración (meses) | B10: 24 | N10: =IF(B12="Otro índice (cargo el %)",0,1)
A11: Alquiler inicial (el del primer mes) | N11: =IF(N5=1,MIN(INT((B10-1)/N8),60),0)
A12: Índice de ajuste | B12: IPC (INDEC) | C12: Si tu contrato ajusta por ICL, Casa Propia u otro índice, elegí «Otro» y cargá el % de cada ajuste en el cronograma (columna F). | N12: =IPC!$J$3
A13: Se ajusta cada (meses) | B13: 3 | C13: Trimestral = 3, cuatrimestral = 4, semestral = 6, anual = 12. | N13: =IPC!$J$2
A14: Meses del IPC que toma | B14: Los completos antes del ajuste | C14: «Completos»: un ajuste de julio usa el IPC de abril a junio (como la calculadora de calcular.ar). «Últimos publicados»: usa el de marzo a mayo, porque el de junio sale a mitad de julio. Fijate qué dice tu contrato. | N14: =IF(N5=0,0,IF(N10=0,1,IF(AND(N7-1-N9>=N13,N7-1-N9<=N12),1,0)))
N15: =COUNT(G29:G88)
A16: CÓMO VIENE EL CONTRATO | N16: =IF(N5=1,INDEX(G28:G88,N15+1),"")
A17: Alquiler que se cobra hoy | B17: =N16 | N17: =N15+1
A18: Rige desde | B18: =IF(N5=1,INDEX(B28:B88,N15+1),"") | N18: =IF(AND(N5=1,N17<=N11),1,0)
A19: Ajustes aplicados | B19: =IF(N5=1,N15,"") | N19: =N7+N17*N8-1-N9
A20: Aumento desde el inicio | B20: =IF(N5=1,N16/B11-1,"") | N20: =N19-N12
A21: Próximo ajuste | B21: =IF(N18=1,INDEX(B28:B88,N17+1),IF(N5=1,"No quedan ajustes antes de que termine","")) | N21: =INDEX(IPC!$D$5:$D$173,(N12)-IPC!$J$2+1)/INDEX(IPC!$D$5:$D$173,(N12-1)-IPC!$J$2+1)-1
A22: Próximo alquiler estimado | B22: =N22 | N22: =IF(AND(N18=1,N10=1,N14=1,N20>0,N20<=12),N16*INDEX(IPC!$D$5:$D$173,(N12)-IPC!$J$2+1)*(1+N21)^N20/INDEX(IPC!$D$5:$D$173,(N19-N8)-IPC!$J$2+1),"")
A23: Último mes del contrato | B23: =IF(N5=1,INDEX(IPC!$J$5:$J$16,MOD(N7+B10-1,12)+1)&" de "&INT((N7+B10-1)/12),"") | N23: =IF(ISNUMBER(N22),ROUND(N22,0),"")
A24: Qué hacer ahora | B24: =IF(N5=0,"Completá las celdas amarillas de arriba y acá aparece el cronograma de aumentos.",IF(N14=0,"Todavía no está publicado el IPC de "&INDEX(IPC!$J$5:$J$16,MOD(N7-1-N9,12)+1)&" de "&INT((N7-1-N9)/12)&", que es la base de este contrato. Mientras tanto se cobra el valor inicial.",IF(N18=0,"No quedan ajustes: el contrato termina en "&INDEX(IPC!$J$5:$J$16,MOD(N7+B10-1,12)+1)&" de "&INT((N7+B10-1)/12)&".",IF(N10=1,"El próximo ajuste rige desde "&B21&". Se calcula cuando el INDEC publique el IPC de "&INDEX(IPC!$J$5:$J$16,MOD(N19,12)+1)&" de "&INT((N19)/12)&" (sale entre el 10 y el 15 del mes siguiente)"&IF(ISNUMBER(N22),". Si la inflación siguiera como el último mes, el alquiler quedaría en unos $ "&N24&".","."),"El próximo ajuste rige desde "&B21&": cuando lo tengas, cargá el % del índice pactado en la columna F del cronograma.")))) | N24: =IF(ISNUMBER(N23),IF(N23>=1000000000,INT(N23/1000000000)&"."&RIGHT("00"&INT(MOD(N23,1000000000)/1000000),3)&"."&RIGHT("00"&INT(MOD(N23,1000000)/1000),3)&"."&RIGHT("00"&INT(MOD(N23,1000)/1),3),IF(N23>=1000000,INT(N23/1000000)&"."&RIGHT("00"&INT(MOD(N23,1000000)/1000),3)&"."&RIGHT("00"&INT(MOD(N23,1000)/1),3),IF(N23>=1000,INT(N23/1000)&"."&RIGHT("00"&INT(MOD(N23,1000)/1),3),""&N23))),"")
A26: CRONOGRAMA DE AJUSTES
A27: Ajuste | B27: Rige desde | C27: Mes del IPC base | D27: Mes del IPC final | E27: Variación | F27: % a mano (otro índice) | G27: Alquiler | H27: Estado
A28: =IF($N$5=1,"Valor inicial","") | B28: =IF($N$5=1,INDEX(IPC!$J$5:$J$16,MOD(J28,12)+1)&" de "&INT((J28)/12),"") | G28: =IF($N$5=1,B11,"") | H28: =IF($N$5=1,"Valor inicial del contrato","") | J28: =IF($N$5=1,$N$7+0*$N$8,"") | K28: =IF($N$5=1,J28-1-$N$9,"") | L28: =IF($N$5=1,K28-$N$8,"")
A29: =IF(AND($N$5=1,1<=$N$11),"1° ajuste","") | B29: =IF(AND($N$5=1,1<=$N$11),INDEX(IPC!$J$5:$J$16,MOD(J29,12)+1)&" de "&INT((J29)/12),"") | C29: =IF(AND(AND($N$5=1,1<=$N$11),$N$10=1),INDEX(IPC!$J$5:$J$16,MOD(L29,12)+1)&" de "&INT((L29)/12),"") | D29: =IF(AND(AND($N$5=1,1<=$N$11),$N$10=1),INDEX(IPC!$J$5:$J$16,MOD(K29,12)+1)&" de "&INT((K29)/12),"") | E29: =IF(NOT(AND($N$5=1,1<=$N$11)),"",IF($N$10=1,IF(AND($N$14=1,K29<=$N$12),INDEX(IPC!$D$5:$D$173,(K29)-IPC!$J$2+1)/INDEX(IPC!$D$5:$D$173,(L29)-IPC!$J$2+1)-1,""),IF(ISNUMBER(F29),F29/100,""))) | G29: =IF(AND(AND($N$5=1,1<=$N$11),ISNUMBER(G28),ISNUMBER(E29)),G28*(1+E29),"") | H29: =IF(NOT(AND($N$5=1,1<=$N$11)),"",IF(ISNUMBER(G29),"Aplicado",IF(ISNUMBER(G28),IF($N$10=1,"Falta el IPC de "&INDEX(IPC!$J$5:$J$16,MOD($N$12+1,12)+1)&" de "&INT(($N$12+1)/12),"Cargá el % de este ajuste en la columna F"),""))) | J29: =IF($N$5=1,$N$7+1*$N$8,"") | K29: =IF($N$5=1,J29-1-$N$9,"") | L29: =IF($N$5=1,K29-$N$8,"")
A30: =IF(AND($N$5=1,2<=$N$11),"2° ajuste","") | B30: =IF(AND($N$5=1,2<=$N$11),INDEX(IPC!$J$5:$J$16,MOD(J30,12)+1)&" de "&INT((J30)/12),"") | C30: =IF(AND(AND($N$5=1,2<=$N$11),$N$10=1),INDEX(IPC!$J$5:$J$16,MOD(L30,12)+1)&" de "&INT((L30)/12),"") | D30: =IF(AND(AND($N$5=1,2<=$N$11),$N$10=1),INDEX(IPC!$J$5:$J$16,MOD(K30,12)+1)&" de "&INT((K30)/12),"") | E30: =IF(NOT(AND($N$5=1,2<=$N$11)),"",IF($N$10=1,IF(AND($N$14=1,K30<=$N$12),INDEX(IPC!$D$5:$D$173,(K30)-IPC!$J$2+1)/INDEX(IPC!$D$5:$D$173,(L30)-IPC!$J$2+1)-1,""),IF(ISNUMBER(F30),F30/100,""))) | G30: =IF(AND(AND($N$5=1,2<=$N$11),ISNUMBER(G29),ISNUMBER(E30)),G29*(1+E30),"") | H30: =IF(NOT(AND($N$5=1,2<=$N$11)),"",IF(ISNUMBER(G30),"Aplicado",IF(ISNUMBER(G29),IF($N$10=1,"Falta el IPC de "&INDEX(IPC!$J$5:$J$16,MOD($N$12+1,12)+1)&" de "&INT(($N$12+1)/12),"Cargá el % de este ajuste en la columna F"),""))) | J30: =IF($N$5=1,$N$7+2*$N$8,"") | K30: =IF($N$5=1,J30-1-$N$9,"") | L30: =IF($N$5=1,K30-$N$8,"")
A31: =IF(AND($N$5=1,3<=$N$11),"3° ajuste","") | B31: =IF(AND($N$5=1,3<=$N$11),INDEX(IPC!$J$5:$J$16,MOD(J31,12)+1)&" de "&INT((J31)/12),"") | C31: =IF(AND(AND($N$5=1,3<=$N$11),$N$10=1),INDEX(IPC!$J$5:$J$16,MOD(L31,12)+1)&" de "&INT((L31)/12),"") | D31: =IF(AND(AND($N$5=1,3<=$N$11),$N$10=1),INDEX(IPC!$J$5:$J$16,MOD(K31,12)+1)&" de "&INT((K31)/12),"") | E31: =IF(NOT(AND($N$5=1,3<=$N$11)),"",IF($N$10=1,IF(AND($N$14=1,K31<=$N$12),INDEX(IPC!$D$5:$D$173,(K31)-IPC!$J$2+1)/INDEX(IPC!$D$5:$D$173,(L31)-IPC!$J$2+1)-1,""),IF(ISNUMBER(F31),F31/100,""))) | G31: =IF(AND(AND($N$5=1,3<=$N$11),ISNUMBER(G30),ISNUMBER(E31)),G30*(1+E31),"") | H31: =IF(NOT(AND($N$5=1,3<=$N$11)),"",IF(ISNUMBER(G31),"Aplicado",IF(ISNUMBER(G30),IF($N$10=1,"Falta el IPC de "&INDEX(IPC!$J$5:$J$16,MOD($N$12+1,12)+1)&" de "&INT(($N$12+1)/12),"Cargá el % de este ajuste en la columna F"),""))) | J31: =IF($N$5=1,$N$7+3*$N$8,"") | K31: =IF($N$5=1,J31-1-$N$9,"") | L31: =IF($N$5=1,K31-$N$8,"")
A32: =IF(AND($N$5=1,4<=$N$11),"4° ajuste","") | B32: =IF(AND($N$5=1,4<=$N$11),INDEX(IPC!$J$5:$J$16,MOD(J32,12)+1)&" de "&INT((J32)/12),"") | C32: =IF(AND(AND($N$5=1,4<=$N$11),$N$10=1),INDEX(IPC!$J$5:$J$16,MOD(L32,12)+1)&" de "&INT((L32)/12),"") | D32: =IF(AND(AND($N$5=1,4<=$N$11),$N$10=1),INDEX(IPC!$J$5:$J$16,MOD(K32,12)+1)&" de "&INT((K32)/12),"") | E32: =IF(NOT(AND($N$5=1,4<=$N$11)),"",IF($N$10=1,IF(AND($N$14=1,K32<=$N$12),INDEX(IPC!$D$5:$D$173,(K32)-IPC!$J$2+1)/INDEX(IPC!$D$5:$D$173,(L32)-IPC!$J$2+1)-1,""),IF(ISNUMBER(F32),F32/100,""))) | G32: =IF(AND(AND($N$5=1,4<=$N$11),ISNUMBER(G31),ISNUMBER(E32)),G31*(1+E32),"") | H32: =IF(NOT(AND($N$5=1,4<=$N$11)),"",IF(ISNUMBER(G32),"Aplicado",IF(ISNUMBER(G31),IF($N$10=1,"Falta el IPC de "&INDEX(IPC!$J$5:$J$16,MOD($N$12+1,12)+1)&" de "&INT(($N$12+1)/12),"Cargá el % de este ajuste en la columna F"),""))) | J32: =IF($N$5=1,$N$7+4*$N$8,"") | K32: =IF($N$5=1,J32-1-$N$9,"") | L32: =IF($N$5=1,K32-$N$8,"")
A33: =IF(AND($N$5=1,5<=$N$11),"5° ajuste","") | B33: =IF(AND($N$5=1,5<=$N$11),INDEX(IPC!$J$5:$J$16,MOD(J33,12)+1)&" de "&INT((J33)/12),"") | C33: =IF(AND(AND($N$5=1,5<=$N$11),$N$10=1),INDEX(IPC!$J$5:$J$16,MOD(L33,12)+1)&" de "&INT((L33)/12),"") | D33: =IF(AND(AND($N$5=1,5<=$N$11),$N$10=1),INDEX(IPC!$J$5:$J$16,MOD(K33,12)+1)&" de "&INT((K33)/12),"") | E33: =IF(NOT(AND($N$5=1,5<=$N$11)),"",IF($N$10=1,IF(AND($N$14=1,K33<=$N$12),INDEX(IPC!$D$5:$D$173,(K33)-IPC!$J$2+1)/INDEX(IPC!$D$5:$D$173,(L33)-IPC!$J$2+1)-1,""),IF(ISNUMBER(F33),F33/100,""))) | G33: =IF(AND(AND($N$5=1,5<=$N$11),ISNUMBER(G32),ISNUMBER(E33)),G32*(1+E33),"") | H33: =IF(NOT(AND($N$5=1,5<=$N$11)),"",IF(ISNUMBER(G33),"Aplicado",IF(ISNUMBER(G32),IF($N$10=1,"Falta el IPC de "&INDEX(IPC!$J$5:$J$16,MOD($N$12+1,12)+1)&" de "&INT(($N$12+1)/12),"Cargá el % de este ajuste en la columna F"),""))) | J33: =IF($N$5=1,$N$7+5*$N$8,"") | K33: =IF($N$5=1,J33-1-$N$9,"") | L33: =IF($N$5=1,K33-$N$8,"")
A34: =IF(AND($N$5=1,6<=$N$11),"6° ajuste","") | B34: =IF(AND($N$5=1,6<=$N$11),INDEX(IPC!$J$5:$J$16,MOD(J34,12)+1)&" de "&INT((J34)/12),"") | C34: =IF(AND(AND($N$5=1,6<=$N$11),$N$10=1),INDEX(IPC!$J$5:$J$16,MOD(L34,12)+1)&" de "&INT((L34)/12),"") | D34: =IF(AND(AND($N$5=1,6<=$N$11),$N$10=1),INDEX(IPC!$J$5:$J$16,MOD(K34,12)+1)&" de "&INT((K34)/12),"") | E34: =IF(NOT(AND($N$5=1,6<=$N$11)),"",IF($N$10=1,IF(AND($N$14=1,K34<=$N$12),INDEX(IPC!$D$5:$D$173,(K34)-IPC!$J$2+1)/INDEX(IPC!$D$5:$D$173,(L34)-IPC!$J$2+1)-1,""),IF(ISNUMBER(F34),F34/100,""))) | G34: =IF(AND(AND($N$5=1,6<=$N$11),ISNUMBER(G33),ISNUMBER(E34)),G33*(1+E34),"") | H34: =IF(NOT(AND($N$5=1,6<=$N$11)),"",IF(ISNUMBER(G34),"Aplicado",IF(ISNUMBER(G33),IF($N$10=1,"Falta el IPC de "&INDEX(IPC!$J$5:$J$16,MOD($N$12+1,12)+1)&" de "&INT(($N$12+1)/12),"Cargá el % de este ajuste en la columna F"),""))) | J34: =IF($N$5=1,$N$7+6*$N$8,"") | K34: =IF($N$5=1,J34-1-$N$9,"") | L34: =IF($N$5=1,K34-$N$8,"")
A35: =IF(AND($N$5=1,7<=$N$11),"7° ajuste","") | B35: =IF(AND($N$5=1,7<=$N$11),INDEX(IPC!$J$5:$J$16,MOD(J35,12)+1)&" de "&INT((J35)/12),"") | C35: =IF(AND(AND($N$5=1,7<=$N$11),$N$10=1),INDEX(IPC!$J$5:$J$16,MOD(L35,12)+1)&" de "&INT((L35)/12),"") | D35: =IF(AND(AND($N$5=1,7<=$N$11),$N$10=1),INDEX(IPC!$J$5:$J$16,MOD(K35,12)+1)&" de "&INT((K35)/12),"") | E35: =IF(NOT(AND($N$5=1,7<=$N$11)),"",IF($N$10=1,IF(AND($N$14=1,K35<=$N$12),INDEX(IPC!$D$5:$D$173,(K35)-IPC!$J$2+1)/INDEX(IPC!$D$5:$D$173,(L35)-IPC!$J$2+1)-1,""),IF(ISNUMBER(F35),F35/100,""))) | G35: =IF(AND(AND($N$5=1,7<=$N$11),ISNUMBER(G34),ISNUMBER(E35)),G34*(1+E35),"") | H35: =IF(NOT(AND($N$5=1,7<=$N$11)),"",IF(ISNUMBER(G35),"Aplicado",IF(ISNUMBER(G34),IF($N$10=1,"Falta el IPC de "&INDEX(IPC!$J$5:$J$16,MOD($N$12+1,12)+1)&" de "&INT(($N$12+1)/12),"Cargá el % de este ajuste en la columna F"),""))) | J35: =IF($N$5=1,$N$7+7*$N$8,"") | K35: =IF($N$5=1,J35-1-$N$9,"") | L35: =IF($N$5=1,K35-$N$8,"")
A36: =IF(AND($N$5=1,8<=$N$11),"8° ajuste","") | B36: =IF(AND($N$5=1,8<=$N$11),INDEX(IPC!$J$5:$J$16,MOD(J36,12)+1)&" de "&INT((J36)/12),"") | C36: =IF(AND(AND($N$5=1,8<=$N$11),$N$10=1),INDEX(IPC!$J$5:$J$16,MOD(L36,12)+1)&" de "&INT((L36)/12),"") | D36: =IF(AND(AND($N$5=1,8<=$N$11),$N$10=1),INDEX(IPC!$J$5:$J$16,MOD(K36,12)+1)&" de "&INT((K36)/12),"") | E36: =IF(NOT(AND($N$5=1,8<=$N$11)),"",IF($N$10=1,IF(AND($N$14=1,K36<=$N$12),INDEX(IPC!$D$5:$D$173,(K36)-IPC!$J$2+1)/INDEX(IPC!$D$5:$D$173,(L36)-IPC!$J$2+1)-1,""),IF(ISNUMBER(F36),F36/100,""))) | G36: =IF(AND(AND($N$5=1,8<=$N$11),ISNUMBER(G35),ISNUMBER(E36)),G35*(1+E36),"") | H36: =IF(NOT(AND($N$5=1,8<=$N$11)),"",IF(ISNUMBER(G36),"Aplicado",IF(ISNUMBER(G35),IF($N$10=1,"Falta el IPC de "&INDEX(IPC!$J$5:$J$16,MOD($N$12+1,12)+1)&" de "&INT(($N$12+1)/12),"Cargá el % de este ajuste en la columna F"),""))) | J36: =IF($N$5=1,$N$7+8*$N$8,"") | K36: =IF($N$5=1,J36-1-$N$9,"") | L36: =IF($N$5=1,K36-$N$8,"")
A37: =IF(AND($N$5=1,9<=$N$11),"9° ajuste","") | B37: =IF(AND($N$5=1,9<=$N$11),INDEX(IPC!$J$5:$J$16,MOD(J37,12)+1)&" de "&INT((J37)/12),"") | C37: =IF(AND(AND($N$5=1,9<=$N$11),$N$10=1),INDEX(IPC!$J$5:$J$16,MOD(L37,12)+1)&" de "&INT((L37)/12),"") | D37: =IF(AND(AND($N$5=1,9<=$N$11),$N$10=1),INDEX(IPC!$J$5:$J$16,MOD(K37,12)+1)&" de "&INT((K37)/12),"") | E37: =IF(NOT(AND($N$5=1,9<=$N$11)),"",IF($N$10=1,IF(AND($N$14=1,K37<=$N$12),INDEX(IPC!$D$5:$D$173,(K37)-IPC!$J$2+1)/INDEX(IPC!$D$5:$D$173,(L37)-IPC!$J$2+1)-1,""),IF(ISNUMBER(F37),F37/100,""))) | G37: =IF(AND(AND($N$5=1,9<=$N$11),ISNUMBER(G36),ISNUMBER(E37)),G36*(1+E37),"") | H37: =IF(NOT(AND($N$5=1,9<=$N$11)),"",IF(ISNUMBER(G37),"Aplicado",IF(ISNUMBER(G36),IF($N$10=1,"Falta el IPC de "&INDEX(IPC!$J$5:$J$16,MOD($N$12+1,12)+1)&" de "&INT(($N$12+1)/12),"Cargá el % de este ajuste en la columna F"),""))) | J37: =IF($N$5=1,$N$7+9*$N$8,"") | K37: =IF($N$5=1,J37-1-$N$9,"") | L37: =IF($N$5=1,K37-$N$8,"")
A38: =IF(AND($N$5=1,10<=$N$11),"10° ajuste","") | B38: =IF(AND($N$5=1,10<=$N$11),INDEX(IPC!$J$5:$J$16,MOD(J38,12)+1)&" de "&INT((J38)/12),"") | C38: =IF(AND(AND($N$5=1,10<=$N$11),$N$10=1),INDEX(IPC!$J$5:$J$16,MOD(L38,12)+1)&" de "&INT((L38)/12),"") | D38: =IF(AND(AND($N$5=1,10<=$N$11),$N$10=1),INDEX(IPC!$J$5:$J$16,MOD(K38,12)+1)&" de "&INT((K38)/12),"") | E38: =IF(NOT(AND($N$5=1,10<=$N$11)),"",IF($N$10=1,IF(AND($N$14=1,K38<=$N$12),INDEX(IPC!$D$5:$D$173,(K38)-IPC!$J$2+1)/INDEX(IPC!$D$5:$D$173,(L38)-IPC!$J$2+1)-1,""),IF(ISNUMBER(F38),F38/100,""))) | G38: =IF(AND(AND($N$5=1,10<=$N$11),ISNUMBER(G37),ISNUMBER(E38)),G37*(1+E38),"") | H38: =IF(NOT(AND($N$5=1,10<=$N$11)),"",IF(ISNUMBER(G38),"Aplicado",IF(ISNUMBER(G37),IF($N$10=1,"Falta el IPC de "&INDEX(IPC!$J$5:$J$16,MOD($N$12+1,12)+1)&" de "&INT(($N$12+1)/12),"Cargá el % de este ajuste en la columna F"),""))) | J38: =IF($N$5=1,$N$7+10*$N$8,"") | K38: =IF($N$5=1,J38-1-$N$9,"") | L38: =IF($N$5=1,K38-$N$8,"")
A39: =IF(AND($N$5=1,11<=$N$11),"11° ajuste","") | B39: =IF(AND($N$5=1,11<=$N$11),INDEX(IPC!$J$5:$J$16,MOD(J39,12)+1)&" de "&INT((J39)/12),"") | C39: =IF(AND(AND($N$5=1,11<=$N$11),$N$10=1),INDEX(IPC!$J$5:$J$16,MOD(L39,12)+1)&" de "&INT((L39)/12),"") | D39: =IF(AND(AND($N$5=1,11<=$N$11),$N$10=1),INDEX(IPC!$J$5:$J$16,MOD(K39,12)+1)&" de "&INT((K39)/12),"") | E39: =IF(NOT(AND($N$5=1,11<=$N$11)),"",IF($N$10=1,IF(AND($N$14=1,K39<=$N$12),INDEX(IPC!$D$5:$D$173,(K39)-IPC!$J$2+1)/INDEX(IPC!$D$5:$D$173,(L39)-IPC!$J$2+1)-1,""),IF(ISNUMBER(F39),F39/100,""))) | G39: =IF(AND(AND($N$5=1,11<=$N$11),ISNUMBER(G38),ISNUMBER(E39)),G38*(1+E39),"") | H39: =IF(NOT(AND($N$5=1,11<=$N$11)),"",IF(ISNUMBER(G39),"Aplicado",IF(ISNUMBER(G38),IF($N$10=1,"Falta el IPC de "&INDEX(IPC!$J$5:$J$16,MOD($N$12+1,12)+1)&" de "&INT(($N$12+1)/12),"Cargá el % de este ajuste en la columna F"),""))) | J39: =IF($N$5=1,$N$7+11*$N$8,"") | K39: =IF($N$5=1,J39-1-$N$9,"") | L39: =IF($N$5=1,K39-$N$8,"")
A40: =IF(AND($N$5=1,12<=$N$11),"12° ajuste","") | B40: =IF(AND($N$5=1,12<=$N$11),INDEX(IPC!$J$5:$J$16,MOD(J40,12)+1)&" de "&INT((J40)/12),"") | C40: =IF(AND(AND($N$5=1,12<=$N$11),$N$10=1),INDEX(IPC!$J$5:$J$16,MOD(L40,12)+1)&" de "&INT((L40)/12),"") | D40: =IF(AND(AND($N$5=1,12<=$N$11),$N$10=1),INDEX(IPC!$J$5:$J$16,MOD(K40,12)+1)&" de "&INT((K40)/12),"") | E40: =IF(NOT(AND($N$5=1,12<=$N$11)),"",IF($N$10=1,IF(AND($N$14=1,K40<=$N$12),INDEX(IPC!$D$5:$D$173,(K40)-IPC!$J$2+1)/INDEX(IPC!$D$5:$D$173,(L40)-IPC!$J$2+1)-1,""),IF(ISNUMBER(F40),F40/100,""))) | G40: =IF(AND(AND($N$5=1,12<=$N$11),ISNUMBER(G39),ISNUMBER(E40)),G39*(1+E40),"") | H40: =IF(NOT(AND($N$5=1,12<=$N$11)),"",IF(ISNUMBER(G40),"Aplicado",IF(ISNUMBER(G39),IF($N$10=1,"Falta el IPC de "&INDEX(IPC!$J$5:$J$16,MOD($N$12+1,12)+1)&" de "&INT(($N$12+1)/12),"Cargá el % de este ajuste en la columna F"),""))) | J40: =IF($N$5=1,$N$7+12*$N$8,"") | K40: =IF($N$5=1,J40-1-$N$9,"") | L40: =IF($N$5=1,K40-$N$8,"")
A41: =IF(AND($N$5=1,13<=$N$11),"13° ajuste","") | B41: =IF(AND($N$5=1,13<=$N$11),INDEX(IPC!$J$5:$J$16,MOD(J41,12)+1)&" de "&INT((J41)/12),"") | C41: =IF(AND(AND($N$5=1,13<=$N$11),$N$10=1),INDEX(IPC!$J$5:$J$16,MOD(L41,12)+1)&" de "&INT((L41)/12),"") | D41: =IF(AND(AND($N$5=1,13<=$N$11),$N$10=1),INDEX(IPC!$J$5:$J$16,MOD(K41,12)+1)&" de "&INT((K41)/12),"") | E41: =IF(NOT(AND($N$5=1,13<=$N$11)),"",IF($N$10=1,IF(AND($N$14=1,K41<=$N$12),INDEX(IPC!$D$5:$D$173,(K41)-IPC!$J$2+1)/INDEX(IPC!$D$5:$D$173,(L41)-IPC!$J$2+1)-1,""),IF(ISNUMBER(F41),F41/100,""))) | G41: =IF(AND(AND($N$5=1,13<=$N$11),ISNUMBER(G40),ISNUMBER(E41)),G40*(1+E41),"") | H41: =IF(NOT(AND($N$5=1,13<=$N$11)),"",IF(ISNUMBER(G41),"Aplicado",IF(ISNUMBER(G40),IF($N$10=1,"Falta el IPC de "&INDEX(IPC!$J$5:$J$16,MOD($N$12+1,12)+1)&" de "&INT(($N$12+1)/12),"Cargá el % de este ajuste en la columna F"),""))) | J41: =IF($N$5=1,$N$7+13*$N$8,"") | K41: =IF($N$5=1,J41-1-$N$9,"") | L41: =IF($N$5=1,K41-$N$8,"")
A42: =IF(AND($N$5=1,14<=$N$11),"14° ajuste","") | B42: =IF(AND($N$5=1,14<=$N$11),INDEX(IPC!$J$5:$J$16,MOD(J42,12)+1)&" de "&INT((J42)/12),"") | C42: =IF(AND(AND($N$5=1,14<=$N$11),$N$10=1),INDEX(IPC!$J$5:$J$16,MOD(L42,12)+1)&" de "&INT((L42)/12),"") | D42: =IF(AND(AND($N$5=1,14<=$N$11),$N$10=1),INDEX(IPC!$J$5:$J$16,MOD(K42,12)+1)&" de "&INT((K42)/12),"") | E42: =IF(NOT(AND($N$5=1,14<=$N$11)),"",IF($N$10=1,IF(AND($N$14=1,K42<=$N$12),INDEX(IPC!$D$5:$D$173,(K42)-IPC!$J$2+1)/INDEX(IPC!$D$5:$D$173,(L42)-IPC!$J$2+1)-1,""),IF(ISNUMBER(F42),F42/100,""))) | G42: =IF(AND(AND($N$5=1,14<=$N$11),ISNUMBER(G41),ISNUMBER(E42)),G41*(1+E42),"") | H42: =IF(NOT(AND($N$5=1,14<=$N$11)),"",IF(ISNUMBER(G42),"Aplicado",IF(ISNUMBER(G41),IF($N$10=1,"Falta el IPC de "&INDEX(IPC!$J$5:$J$16,MOD($N$12+1,12)+1)&" de "&INT(($N$12+1)/12),"Cargá el % de este ajuste en la columna F"),""))) | J42: =IF($N$5=1,$N$7+14*$N$8,"") | K42: =IF($N$5=1,J42-1-$N$9,"") | L42: =IF($N$5=1,K42-$N$8,"")
...

Sheet Contrato 4
A1: Contrato 4
A2: Completá las celdas amarillas con los datos del contrato. Las verdes se calculan solas.
A4: DATOS DEL CONTRATO
A5: Propiedad (dirección) | N5: =IF(AND(N6>0,ISNUMBER(B9),ISNUMBER(B11),B11>0,ISNUMBER(B13),B13>=1,ISNUMBER(B10),B10>=1),1,0)
A6: Inquilino/a | N6: =IFERROR(MATCH(B8,IPC!$J$5:$J$16,0),0)
A7: Tu nombre (para el recibo y el aviso) | N7: =IF(N5=1,B9*12+N6-1,0)
A8: Mes de inicio del contrato | C8: El primer mes en que se cobró el valor inicial. | N8: =IF(N5=1,INT(B13),1)
A9: Año de inicio | N9: =IF(B14="Los últimos publicados",1,0)
A10: Duración (meses) | B10: 24 | N10: =IF(B12="Otro índice (cargo el %)",0,1)
A11: Alquiler inicial (el del primer mes) | N11: =IF(N5=1,MIN(INT((B10-1)/N8),60),0)
A12: Índice de ajuste | B12: IPC (INDEC) | C12: Si tu contrato ajusta por ICL, Casa Propia u otro índice, elegí «Otro» y cargá el % de cada ajuste en el cronograma (columna F). | N12: =IPC!$J$3
A13: Se ajusta cada (meses) | B13: 3 | C13: Trimestral = 3, cuatrimestral = 4, semestral = 6, anual = 12. | N13: =IPC!$J$2
A14: Meses del IPC que toma | B14: Los completos antes del ajuste | C14: «Completos»: un ajuste de julio usa el IPC de abril a junio (como la calculadora de calcular.ar). «Últimos publicados»: usa el de marzo a mayo, porque el de junio sale a mitad de julio. Fijate qué dice tu contrato. | N14: =IF(N5=0,0,IF(N10=0,1,IF(AND(N7-1-N9>=N13,N7-1-N9<=N12),1,0)))
N15: =COUNT(G29:G88)
A16: CÓMO VIENE EL CONTRATO | N16: =IF(N5=1,INDEX(G28:G88,N15+1),"")
A17: Alquiler que se cobra hoy | B17: =N16 | N17: =N15+1
A18: Rige desde | B18: =IF(N5=1,INDEX(B28:B88,N15+1),"") | N18: =IF(AND(N5=1,N17<=N11),1,0)
A19: Ajustes aplicados | B19: =IF(N5=1,N15,"") | N19: =N7+N17*N8-1-N9
A20: Aumento desde el inicio | B20: =IF(N5=1,N16/B11-1,"") | N20: =N19-N12
