Workbook

Sheet Cómo usarla
A1: Planilla Mi Sueldo 2026 — cómo usarla
A3: 1 | B3: En «Mis datos», elegí el mes de tu primer recibo y tu cuota sindical si estás afiliado. Tu nombre y tu puesto son opcionales: sólo salen en el resumen.
A4: 2 | B4: En «Mis recibos», cargá cada recibo en su mes: bruto remunerativo, lo no remunerativo y cada descuento tal cual figura. Al lado aparece si cuadra con la ley.
A5: 3 | B5: Si dice «Revisar», mirá la columna verde de ese concepto: es lo que marca la ley para tu sueldo. La diferencia te dice de cuánto es.
A6: 4 | B6: En «Sueldo vs inflación» ves cada sueldo en pesos de hoy: si la columna baja, tu sueldo compra menos.
A7: 5 | B7: «Para pedir aumento» resume todo en una hoja: cuánto perdiste desde tu último aumento y qué aumento lo recupera, con la fuente. Imprimila o guardala en PDF.
A8: 6 | B8: «Aguinaldo» proyecta el de cada semestre con tus recibos, y el resumen te avisa si te acercás al piso de Ganancias.
A10: COLORES
B11: Amarillo: lo completás vos.
B12: Verde: lo calcula la planilla. Está protegido para que no se pise sin querer (Revisar > Desproteger hoja, si alguna vez lo necesitás).
A14: LO QUE CONVIENE SABER
B15: • Los descuentos de ley son tres y suman 17%: jubilación 11%, Ley 19.032 (PAMI) 3% y obra social 3%. Se calculan sobre lo remunerativo, hasta un tope que cambia todos los meses (octubre de 2026: $4.769.631).
B16: • Lo no remunerativo no paga jubilación ni Ley 19.032. Algunos convenios sí le descuentan obra social o cuota sindical: lo indicás en «Mis datos».
B17: • La cuota sindical se descuenta sólo si estás afiliado. Desde la Ley 27.802 (marzo de 2026), las contribuciones solidarias que fijan los convenios para afiliados y no afiliados tienen un tope de 2% de la remuneración; la cuota de afiliación queda afuera de ese tope.
B18: • Desde junio de 2026 (Decreto 407/2026) el recibo también muestra lo que paga tu empleador por vos. Esta planilla controla tus descuentos, no las contribuciones del empleador.
B19: • La inflación se compone, no se suma: tres meses de 2% dan 6,12%. Por eso la planilla compara índices del INDEC y no suma porcentajes.
B20: • Los créditos laborales prescriben a los dos años (art. 256 de la Ley de Contrato de Trabajo). Si encontrás una diferencia, no la dejes pasar: consultala con el recibo en la mano.
A22: CÓMO SE MANTIENE AL DÍA
B23: • El INDEC publica el IPC de cada mes entre el 10 y el 15 del mes siguiente. Cada vez que sale, regeneramos la planilla y el mismo enlace de descarga te baja la versión al día, sin costo. Para pasar tus recibos: copiá las celdas amarillas de «Mis recibos» y «Mis datos» y pegalas en el mismo lugar.
B24: • ¿Preferís no cambiar de archivo? Cargá el % del mes nuevo en la columna amarilla de la hoja «IPC» y todo se recalcula.
A26: Da los mismos números que la calculadora gratuita de calcular.ar/sueldo-neto: son los mismos aportes, el mismo tope y la misma serie del IPC. Si alguna vez no coinciden, escribinos y lo corregimos. Es una referencia de cálculo, no asesoramiento legal ni contable.

Sheet Mis datos
A1: Mis datos
A2: Se completan una vez. Tu nombre y tu puesto sólo aparecen en el resumen para pedir aumento: no salen de este archivo.
A4: TUS DATOS | H4: =IFERROR(MATCH(B7,IPC!$J$5:$J$16,0),0)
A5: Tu nombre | C5: Opcional. Sale en el encabezado del resumen imprimible. | H5: =IF(AND(H4>0,ISNUMBER(B8)),B8*12+H4-1,"")
A6: Puesto o categoría | C6: Opcional. Por ejemplo: Vendedor B, Administrativa, Analista Sr. | H6: =IF(ISNUMBER(B9),B9/100,0)
A7: Mes del primer recibo que cargás | B7: septiembre | C7: «Mis recibos» arranca en este mes y sigue 24 meses. Conviene empezar un año antes de hoy: así ves la comparación interanual. | H7: =B25+B26+IF(B15="Sí",B27,0)+IF(ISNUMBER(B16),B16,0)*B28+IF(ISNUMBER(B17),B17,0)
A8: Año del primer recibo | B8: 2025 | H8: =IF(H7/(13*(1-(B21+B22+B23+H6)))<=B24,H7/(13*(1-(B21+B22+B23+H6))),(H7/13+(B21+B22+B23)*B24)/(1-H6))
A9: Cuota sindical (%) | B9: 2 | C9: Sólo si estás afiliado. Es el % que figura en tu recibo (suele ir de 1% a 3%). Si no, dejá 0.
A10: ¿Te descuentan obra social sobre lo no remunerativo? | B10: No | C10: Depende de tu convenio. En Comercio, por ejemplo, las sumas no remunerativas aportan a la obra social. Si tu recibo lo descuenta, poné Sí.
A11: ¿Y la cuota sindical sobre lo no remunerativo? | B11: No | C11: También depende del convenio. Si no sabés, dejá No y mirá si el control te marca la cuota sindical.
A12: Qué sueldo comparo con la inflación | B12: El bruto total | C12: Los aumentos se negocian sobre el bruto. Si preferís ver lo que te entra en el bolsillo, elegí «Lo que cobré en mano» (usa la columna J).
A14: PARA EL AVISO DE GANANCIAS
A15: Cónyuge a cargo | B15: No | C15: Sin ingresos propios por encima del mínimo no imponible.
A16: Hijos a cargo | B16: 0 | C16: Menores de 18 años.
A17: Otras deducciones del año | B17: 0 | C17: Prepaga, alquiler, servicio doméstico, etc., sumado en el año. Si no sabés, dejá 0.
A20: VALORES DE LEY QUE USA LA PLANILLA
A21: Jubilación (SIPA) | B21: 0.11 | C21: Ley 24.241, art. 11.
A22: Ley 19.032 (PAMI) | B22: 0.03 | C22: INSSJP.
A23: Obra social | B23: 0.03 | C23: Ley 23.660.
A24: Tope de la base para aportes (por mes) | B24: 4769631.5 | C24: Resolución ANSES 284/2026, art. 3 (Boletín Oficial del 23 de septiembre de 2026). Vigente en octubre de 2026: cambia todos los meses. Por encima, los aportes dejan de crecer.
A25: Ganancias: mínimo no imponible (anual) | B25: 5585736.9 | C25: ARCA, art. 30 LIG, 2do semestre 2026 (julio a diciembre).
A26: Ganancias: deducción especial (anual) | B26: 26811537 | C26: Relación de dependencia.
A27: Ganancias: cónyuge (anual) | B27: 5260643.9
A28: Ganancias: por hijo (anual) | B28: 2652961.9
A30: Si cambia uno de estos valores, el enlace de descarga que te llegó por mail te baja la versión al día. Un recibo viejo con un sueldo por encima del tope se compara con el tope de hoy: si la planilla lo marca, fijate el tope de ese mes.

Sheet Mis recibos
A1: Mis recibos — control mes a mes
A2: Viene con un ejemplo de 13 meses: reemplazalo con tus recibos (o borrá las celdas amarillas). Cargá cada importe tal cual figura en el recibo; las columnas verdes te dicen si cuadra con la ley.
B3: LO QUE DICE TU RECIBO (lo completás vos) | K3: CONTROL | M3: LO QUE MARCA LA LEY
A4: Mes | B4: Bruto remunerativo | C4: No remunerativo | D4: Jubilación | E4: Ley 19.032 | F4: Obra social | G4: Cuota sindical | H4: Ganancias | I4: Otros descuentos | J4: Neto que cobraste | K4: ¿Cuadra? | L4: Diferencia en aportes | M4: Jubilación 11% | N4: Ley 19.032 3% | O4: Obra social 3% | P4: Cuota sindical | Q4: Neto de ley
A5: =IF(S5="","",INDEX(IPC!$J$5:$J$16,MOD(S5,12)+1)&" de "&INT((S5)/12)) | B5: 1150000 | D5: 126500 | E5: 34500 | F5: 34500 | G5: 23000 | J5: 931500 | K5: =IF(V5=0,"",IF(AND(AB5=0,NOT(ISNUMBER(J5))),"Cargá los descuentos",IF(ABS(X5)>1,"Revisar jubilación",IF(ABS(Y5)>1,"Revisar Ley 19.032",IF(ABS(Z5)>1,"Revisar obra social",IF(ABS(AA5)>1,"Revisar cuota sindical",IF(ABS(AC5)>1,"El neto no da con los descuentos","Cuadra"))))))) | L5: =IF(OR(V5=0,AB5=0),"",X5+Y5+Z5+AA5) | M5: =IF(V5=1,MIN(B5,'Mis datos'!$B$24)*'Mis datos'!$B$21,"") | N5: =IF(V5=1,MIN(B5,'Mis datos'!$B$24)*'Mis datos'!$B$22,"") | O5: =IF(V5=1,MIN(B5,'Mis datos'!$B$24)*'Mis datos'!$B$23+IF('Mis datos'!$B$10="Sí",W5*'Mis datos'!$B$23,0),"") | P5: =IF(V5=1,(B5+IF('Mis datos'!$B$11="Sí",W5,0))*'Mis datos'!$H$6,"") | Q5: =IF(V5=1,B5+W5-M5-N5-O5-P5,"") | S5: =IF(ISNUMBER('Mis datos'!$H$5),'Mis datos'!$H$5+0,"") | T5: =IF(S5="","",INT(S5/12)*2+IF(MOD(S5,12)>=6,1,0)) | U5: =IF(V5=1,B5,0) | V5: =IF(AND(S5<>"",ISNUMBER(B5)),IF(B5>0,1,0),0) | W5: =IF(ISNUMBER(C5),C5,0) | X5: =IF(AND(V5=1,ISNUMBER(D5)),D5-M5,0) | Y5: =IF(AND(V5=1,ISNUMBER(E5)),E5-N5,0) | Z5: =IF(AND(V5=1,ISNUMBER(F5)),F5-O5,0) | AA5: =IF(AND(V5=1,ISNUMBER(G5)),G5-P5,0) | AB5: =COUNT(D5:G5) | AC5: =IF(AND(V5=1,ISNUMBER(J5)),B5+W5-SUM(D5:I5)-J5,0) | AD5: =IF(V5=1,1,"")
A6: =IF(S6="","",INDEX(IPC!$J$5:$J$16,MOD(S6,12)+1)&" de "&INT((S6)/12)) | B6: 1150000 | D6: 126500 | E6: 34500 | F6: 34500 | G6: 23000 | J6: 931500 | K6: =IF(V6=0,"",IF(AND(AB6=0,NOT(ISNUMBER(J6))),"Cargá los descuentos",IF(ABS(X6)>1,"Revisar jubilación",IF(ABS(Y6)>1,"Revisar Ley 19.032",IF(ABS(Z6)>1,"Revisar obra social",IF(ABS(AA6)>1,"Revisar cuota sindical",IF(ABS(AC6)>1,"El neto no da con los descuentos","Cuadra"))))))) | L6: =IF(OR(V6=0,AB6=0),"",X6+Y6+Z6+AA6) | M6: =IF(V6=1,MIN(B6,'Mis datos'!$B$24)*'Mis datos'!$B$21,"") | N6: =IF(V6=1,MIN(B6,'Mis datos'!$B$24)*'Mis datos'!$B$22,"") | O6: =IF(V6=1,MIN(B6,'Mis datos'!$B$24)*'Mis datos'!$B$23+IF('Mis datos'!$B$10="Sí",W6*'Mis datos'!$B$23,0),"") | P6: =IF(V6=1,(B6+IF('Mis datos'!$B$11="Sí",W6,0))*'Mis datos'!$H$6,"") | Q6: =IF(V6=1,B6+W6-M6-N6-O6-P6,"") | S6: =IF(ISNUMBER('Mis datos'!$H$5),'Mis datos'!$H$5+1,"") | T6: =IF(S6="","",INT(S6/12)*2+IF(MOD(S6,12)>=6,1,0)) | U6: =MAX(IF(V6=1,B6,0),IF(T6=T5,U5,0)) | V6: =IF(AND(S6<>"",ISNUMBER(B6)),IF(B6>0,1,0),0) | W6: =IF(ISNUMBER(C6),C6,0) | X6: =IF(AND(V6=1,ISNUMBER(D6)),D6-M6,0) | Y6: =IF(AND(V6=1,ISNUMBER(E6)),E6-N6,0) | Z6: =IF(AND(V6=1,ISNUMBER(F6)),F6-O6,0) | AA6: =IF(AND(V6=1,ISNUMBER(G6)),G6-P6,0) | AB6: =COUNT(D6:G6) | AC6: =IF(AND(V6=1,ISNUMBER(J6)),B6+W6-SUM(D6:I6)-J6,0) | AD6: =IF(V6=1,2,"")
A7: =IF(S7="","",INDEX(IPC!$J$5:$J$16,MOD(S7,12)+1)&" de "&INT((S7)/12)) | B7: 1150000 | D7: 126500 | E7: 34500 | F7: 34500 | G7: 23000 | J7: 931500 | K7: =IF(V7=0,"",IF(AND(AB7=0,NOT(ISNUMBER(J7))),"Cargá los descuentos",IF(ABS(X7)>1,"Revisar jubilación",IF(ABS(Y7)>1,"Revisar Ley 19.032",IF(ABS(Z7)>1,"Revisar obra social",IF(ABS(AA7)>1,"Revisar cuota sindical",IF(ABS(AC7)>1,"El neto no da con los descuentos","Cuadra"))))))) | L7: =IF(OR(V7=0,AB7=0),"",X7+Y7+Z7+AA7) | M7: =IF(V7=1,MIN(B7,'Mis datos'!$B$24)*'Mis datos'!$B$21,"") | N7: =IF(V7=1,MIN(B7,'Mis datos'!$B$24)*'Mis datos'!$B$22,"") | O7: =IF(V7=1,MIN(B7,'Mis datos'!$B$24)*'Mis datos'!$B$23+IF('Mis datos'!$B$10="Sí",W7*'Mis datos'!$B$23,0),"") | P7: =IF(V7=1,(B7+IF('Mis datos'!$B$11="Sí",W7,0))*'Mis datos'!$H$6,"") | Q7: =IF(V7=1,B7+W7-M7-N7-O7-P7,"") | S7: =IF(ISNUMBER('Mis datos'!$H$5),'Mis datos'!$H$5+2,"") | T7: =IF(S7="","",INT(S7/12)*2+IF(MOD(S7,12)>=6,1,0)) | U7: =MAX(IF(V7=1,B7,0),IF(T7=T6,U6,0)) | V7: =IF(AND(S7<>"",ISNUMBER(B7)),IF(B7>0,1,0),0) | W7: =IF(ISNUMBER(C7),C7,0) | X7: =IF(AND(V7=1,ISNUMBER(D7)),D7-M7,0) | Y7: =IF(AND(V7=1,ISNUMBER(E7)),E7-N7,0) | Z7: =IF(AND(V7=1,ISNUMBER(F7)),F7-O7,0) | AA7: =IF(AND(V7=1,ISNUMBER(G7)),G7-P7,0) | AB7: =COUNT(D7:G7) | AC7: =IF(AND(V7=1,ISNUMBER(J7)),B7+W7-SUM(D7:I7)-J7,0) | AD7: =IF(V7=1,3,"")
A8: =IF(S8="","",INDEX(IPC!$J$5:$J$16,MOD(S8,12)+1)&" de "&INT((S8)/12)) | B8: 1230500 | D8: 135355 | E8: 36915 | F8: 36915 | G8: 24610 | J8: 996705 | K8: =IF(V8=0,"",IF(AND(AB8=0,NOT(ISNUMBER(J8))),"Cargá los descuentos",IF(ABS(X8)>1,"Revisar jubilación",IF(ABS(Y8)>1,"Revisar Ley 19.032",IF(ABS(Z8)>1,"Revisar obra social",IF(ABS(AA8)>1,"Revisar cuota sindical",IF(ABS(AC8)>1,"El neto no da con los descuentos","Cuadra"))))))) | L8: =IF(OR(V8=0,AB8=0),"",X8+Y8+Z8+AA8) | M8: =IF(V8=1,MIN(B8,'Mis datos'!$B$24)*'Mis datos'!$B$21,"") | N8: =IF(V8=1,MIN(B8,'Mis datos'!$B$24)*'Mis datos'!$B$22,"") | O8: =IF(V8=1,MIN(B8,'Mis datos'!$B$24)*'Mis datos'!$B$23+IF('Mis datos'!$B$10="Sí",W8*'Mis datos'!$B$23,0),"") | P8: =IF(V8=1,(B8+IF('Mis datos'!$B$11="Sí",W8,0))*'Mis datos'!$H$6,"") | Q8: =IF(V8=1,B8+W8-M8-N8-O8-P8,"") | S8: =IF(ISNUMBER('Mis datos'!$H$5),'Mis datos'!$H$5+3,"") | T8: =IF(S8="","",INT(S8/12)*2+IF(MOD(S8,12)>=6,1,0)) | U8: =MAX(IF(V8=1,B8,0),IF(T8=T7,U7,0)) | V8: =IF(AND(S8<>"",ISNUMBER(B8)),IF(B8>0,1,0),0) | W8: =IF(ISNUMBER(C8),C8,0) | X8: =IF(AND(V8=1,ISNUMBER(D8)),D8-M8,0) | Y8: =IF(AND(V8=1,ISNUMBER(E8)),E8-N8,0) | Z8: =IF(AND(V8=1,ISNUMBER(F8)),F8-O8,0) | AA8: =IF(AND(V8=1,ISNUMBER(G8)),G8-P8,0) | AB8: =COUNT(D8:G8) | AC8: =IF(AND(V8=1,ISNUMBER(J8)),B8+W8-SUM(D8:I8)-J8,0) | AD8: =IF(V8=1,4,"")
A9: =IF(S9="","",INDEX(IPC!$J$5:$J$16,MOD(S9,12)+1)&" de "&INT((S9)/12)) | B9: 1230500 | D9: 135355 | E9: 36915 | F9: 36915 | G9: 24610 | J9: 996705 | K9: =IF(V9=0,"",IF(AND(AB9=0,NOT(ISNUMBER(J9))),"Cargá los descuentos",IF(ABS(X9)>1,"Revisar jubilación",IF(ABS(Y9)>1,"Revisar Ley 19.032",IF(ABS(Z9)>1,"Revisar obra social",IF(ABS(AA9)>1,"Revisar cuota sindical",IF(ABS(AC9)>1,"El neto no da con los descuentos","Cuadra"))))))) | L9: =IF(OR(V9=0,AB9=0),"",X9+Y9+Z9+AA9) | M9: =IF(V9=1,MIN(B9,'Mis datos'!$B$24)*'Mis datos'!$B$21,"") | N9: =IF(V9=1,MIN(B9,'Mis datos'!$B$24)*'Mis datos'!$B$22,"") | O9: =IF(V9=1,MIN(B9,'Mis datos'!$B$24)*'Mis datos'!$B$23+IF('Mis datos'!$B$10="Sí",W9*'Mis datos'!$B$23,0),"") | P9: =IF(V9=1,(B9+IF('Mis datos'!$B$11="Sí",W9,0))*'Mis datos'!$H$6,"") | Q9: =IF(V9=1,B9+W9-M9-N9-O9-P9,"") | S9: =IF(ISNUMBER('Mis datos'!$H$5),'Mis datos'!$H$5+4,"") | T9: =IF(S9="","",INT(S9/12)*2+IF(MOD(S9,12)>=6,1,0)) | U9: =MAX(IF(V9=1,B9,0),IF(T9=T8,U8,0)) | V9: =IF(AND(S9<>"",ISNUMBER(B9)),IF(B9>0,1,0),0) | W9: =IF(ISNUMBER(C9),C9,0) | X9: =IF(AND(V9=1,ISNUMBER(D9)),D9-M9,0) | Y9: =IF(AND(V9=1,ISNUMBER(E9)),E9-N9,0) | Z9: =IF(AND(V9=1,ISNUMBER(F9)),F9-O9,0) | AA9: =IF(AND(V9=1,ISNUMBER(G9)),G9-P9,0) | AB9: =COUNT(D9:G9) | AC9: =IF(AND(V9=1,ISNUMBER(J9)),B9+W9-SUM(D9:I9)-J9,0) | AD9: =IF(V9=1,5,"")
A10: =IF(S10="","",INDEX(IPC!$J$5:$J$16,MOD(S10,12)+1)&" de "&INT((S10)/12)) | B10: 1230500 | D10: 135355 | E10: 36915 | F10: 36915 | G10: 24610 | J10: 996705 | K10: =IF(V10=0,"",IF(AND(AB10=0,NOT(ISNUMBER(J10))),"Cargá los descuentos",IF(ABS(X10)>1,"Revisar jubilación",IF(ABS(Y10)>1,"Revisar Ley 19.032",IF(ABS(Z10)>1,"Revisar obra social",IF(ABS(AA10)>1,"Revisar cuota sindical",IF(ABS(AC10)>1,"El neto no da con los descuentos","Cuadra"))))))) | L10: =IF(OR(V10=0,AB10=0),"",X10+Y10+Z10+AA10) | M10: =IF(V10=1,MIN(B10,'Mis datos'!$B$24)*'Mis datos'!$B$21,"") | N10: =IF(V10=1,MIN(B10,'Mis datos'!$B$24)*'Mis datos'!$B$22,"") | O10: =IF(V10=1,MIN(B10,'Mis datos'!$B$24)*'Mis datos'!$B$23+IF('Mis datos'!$B$10="Sí",W10*'Mis datos'!$B$23,0),"") | P10: =IF(V10=1,(B10+IF('Mis datos'!$B$11="Sí",W10,0))*'Mis datos'!$H$6,"") | Q10: =IF(V10=1,B10+W10-M10-N10-O10-P10,"") | S10: =IF(ISNUMBER('Mis datos'!$H$5),'Mis datos'!$H$5+5,"") | T10: =IF(S10="","",INT(S10/12)*2+IF(MOD(S10,12)>=6,1,0)) | U10: =MAX(IF(V10=1,B10,0),IF(T10=T9,U9,0)) | V10: =IF(AND(S10<>"",ISNUMBER(B10)),IF(B10>0,1,0),0) | W10: =IF(ISNUMBER(C10),C10,0) | X10: =IF(AND(V10=1,ISNUMBER(D10)),D10-M10,0) | Y10: =IF(AND(V10=1,ISNUMBER(E10)),E10-N10,0) | Z10: =IF(AND(V10=1,ISNUMBER(F10)),F10-O10,0) | AA10: =IF(AND(V10=1,ISNUMBER(G10)),G10-P10,0) | AB10: =COUNT(D10:G10) | AC10: =IF(AND(V10=1,ISNUMBER(J10)),B10+W10-SUM(D10:I10)-J10,0) | AD10: =IF(V10=1,6,"")
A11: =IF(S11="","",INDEX(IPC!$J$5:$J$16,MOD(S11,12)+1)&" de "&INT((S11)/12)) | B11: 1310000 | D11: 144100 | E11: 39300 | F11: 39300 | G11: 26200 | J11: 1061100 | K11: =IF(V11=0,"",IF(AND(AB11=0,NOT(ISNUMBER(J11))),"Cargá los descuentos",IF(ABS(X11)>1,"Revisar jubilación",IF(ABS(Y11)>1,"Revisar Ley 19.032",IF(ABS(Z11)>1,"Revisar obra social",IF(ABS(AA11)>1,"Revisar cuota sindical",IF(ABS(AC11)>1,"El neto no da con los descuentos","Cuadra"))))))) | L11: =IF(OR(V11=0,AB11=0),"",X11+Y11+Z11+AA11) | M11: =IF(V11=1,MIN(B11,'Mis datos'!$B$24)*'Mis datos'!$B$21,"") | N11: =IF(V11=1,MIN(B11,'Mis datos'!$B$24)*'Mis datos'!$B$22,"") | O11: =IF(V11=1,MIN(B11,'Mis datos'!$B$24)*'Mis datos'!$B$23+IF('Mis datos'!$B$10="Sí",W11*'Mis datos'!$B$23,0),"") | P11: =IF(V11=1,(B11+IF('Mis datos'!$B$11="Sí",W11,0))*'Mis datos'!$H$6,"") | Q11: =IF(V11=1,B11+W11-M11-N11-O11-P11,"") | S11: =IF(ISNUMBER('Mis datos'!$H$5),'Mis datos'!$H$5+6,"") | T11: =IF(S11="","",INT(S11/12)*2+IF(MOD(S11,12)>=6,1,0)) | U11: =MAX(IF(V11=1,B11,0),IF(T11=T10,U10,0)) | V11: =IF(AND(S11<>"",ISNUMBER(B11)),IF(B11>0,1,0),0) | W11: =IF(ISNUMBER(C11),C11,0) | X11: =IF(AND(V11=1,ISNUMBER(D11)),D11-M11,0) | Y11: =IF(AND(V11=1,ISNUMBER(E11)),E11-N11,0) | Z11: =IF(AND(V11=1,ISNUMBER(F11)),F11-O11,0) | AA11: =IF(AND(V11=1,ISNUMBER(G11)),G11-P11,0) | AB11: =COUNT(D11:G11) | AC11: =IF(AND(V11=1,ISNUMBER(J11)),B11+W11-SUM(D11:I11)-J11,0) | AD11: =IF(V11=1,7,"")
A12: =IF(S12="","",INDEX(IPC!$J$5:$J$16,MOD(S12,12)+1)&" de "&INT((S12)/12)) | B12: 1310000 | D12: 144100 | E12: 39300 | F12: 39300 | G12: 26200 | J12: 1061100 | K12: =IF(V12=0,"",IF(AND(AB12=0,NOT(ISNUMBER(J12))),"Cargá los descuentos",IF(ABS(X12)>1,"Revisar jubilación",IF(ABS(Y12)>1,"Revisar Ley 19.032",IF(ABS(Z12)>1,"Revisar obra social",IF(ABS(AA12)>1,"Revisar cuota sindical",IF(ABS(AC12)>1,"El neto no da con los descuentos","Cuadra"))))))) | L12: =IF(OR(V12=0,AB12=0),"",X12+Y12+Z12+AA12) | M12: =IF(V12=1,MIN(B12,'Mis datos'!$B$24)*'Mis datos'!$B$21,"") | N12: =IF(V12=1,MIN(B12,'Mis datos'!$B$24)*'Mis datos'!$B$22,"") | O12: =IF(V12=1,MIN(B12,'Mis datos'!$B$24)*'Mis datos'!$B$23+IF('Mis datos'!$B$10="Sí",W12*'Mis datos'!$B$23,0),"") | P12: =IF(V12=1,(B12+IF('Mis datos'!$B$11="Sí",W12,0))*'Mis datos'!$H$6,"") | Q12: =IF(V12=1,B12+W12-M12-N12-O12-P12,"") | S12: =IF(ISNUMBER('Mis datos'!$H$5),'Mis datos'!$H$5+7,"") | T12: =IF(S12="","",INT(S12/12)*2+IF(MOD(S12,12)>=6,1,0)) | U12: =MAX(IF(V12=1,B12,0),IF(T12=T11,U11,0)) | V12: =IF(AND(S12<>"",ISNUMBER(B12)),IF(B12>0,1,0),0) | W12: =IF(ISNUMBER(C12),C12,0) | X12: =IF(AND(V12=1,ISNUMBER(D12)),D12-M12,0) | Y12: =IF(AND(V12=1,ISNUMBER(E12)),E12-N12,0) | Z12: =IF(AND(V12=1,ISNUMBER(F12)),F12-O12,0) | AA12: =IF(AND(V12=1,ISNUMBER(G12)),G12-P12,0) | AB12: =COUNT(D12:G12) | AC12: =IF(AND(V12=1,ISNUMBER(J12)),B12+W12-SUM(D12:I12)-J12,0) | AD12: =IF(V12=1,8,"")
A13: =IF(S13="","",INDEX(IPC!$J$5:$J$16,MOD(S13,12)+1)&" de "&INT((S13)/12)) | B13: 1310000 | D13: 144100 | E13: 39300 | F13: 36915 | G13: 26200 | J13: 1063485 | K13: =IF(V13=0,"",IF(AND(AB13=0,NOT(ISNUMBER(J13))),"Cargá los descuentos",IF(ABS(X13)>1,"Revisar jubilación",IF(ABS(Y13)>1,"Revisar Ley 19.032",IF(ABS(Z13)>1,"Revisar obra social",IF(ABS(AA13)>1,"Revisar cuota sindical",IF(ABS(AC13)>1,"El neto no da con los descuentos","Cuadra"))))))) | L13: =IF(OR(V13=0,AB13=0),"",X13+Y13+Z13+AA13) | M13: =IF(V13=1,MIN(B13,'Mis datos'!$B$24)*'Mis datos'!$B$21,"") | N13: =IF(V13=1,MIN(B13,'Mis datos'!$B$24)*'Mis datos'!$B$22,"") | O13: =IF(V13=1,MIN(B13,'Mis datos'!$B$24)*'Mis datos'!$B$23+IF('Mis datos'!$B$10="Sí",W13*'Mis datos'!$B$23,0),"") | P13: =IF(V13=1,(B13+IF('Mis datos'!$B$11="Sí",W13,0))*'Mis datos'!$H$6,"") | Q13: =IF(V13=1,B13+W13-M13-N13-O13-P13,"") | S13: =IF(ISNUMBER('Mis datos'!$H$5),'Mis datos'!$H$5+8,"") | T13: =IF(S13="","",INT(S13/12)*2+IF(MOD(S13,12)>=6,1,0)) | U13: =MAX(IF(V13=1,B13,0),IF(T13=T12,U12,0)) | V13: =IF(AND(S13<>"",ISNUMBER(B13)),IF(B13>0,1,0),0) | W13: =IF(ISNUMBER(C13),C13,0) | X13: =IF(AND(V13=1,ISNUMBER(D13)),D13-M13,0) | Y13: =IF(AND(V13=1,ISNUMBER(E13)),E13-N13,0) | Z13: =IF(AND(V13=1,ISNUMBER(F13)),F13-O13,0) | AA13: =IF(AND(V13=1,ISNUMBER(G13)),G13-P13,0) | AB13: =COUNT(D13:G13) | AC13: =IF(AND(V13=1,ISNUMBER(J13)),B13+W13-SUM(D13:I13)-J13,0) | AD13: =IF(V13=1,9,"")
A14: =IF(S14="","",INDEX(IPC!$J$5:$J$16,MOD(S14,12)+1)&" de "&INT((S14)/12)) | B14: 1310000 | D14: 144100 | E14: 39300 | F14: 39300 | G14: 26200 | J14: 1061100 | K14: =IF(V14=0,"",IF(AND(AB14=0,NOT(ISNUMBER(J14))),"Cargá los descuentos",IF(ABS(X14)>1,"Revisar jubilación",IF(ABS(Y14)>1,"Revisar Ley 19.032",IF(ABS(Z14)>1,"Revisar obra social",IF(ABS(AA14)>1,"Revisar cuota sindical",IF(ABS(AC14)>1,"El neto no da con los descuentos","Cuadra"))))))) | L14: =IF(OR(V14=0,AB14=0),"",X14+Y14+Z14+AA14) | M14: =IF(V14=1,MIN(B14,'Mis datos'!$B$24)*'Mis datos'!$B$21,"") | N14: =IF(V14=1,MIN(B14,'Mis datos'!$B$24)*'Mis datos'!$B$22,"") | O14: =IF(V14=1,MIN(B14,'Mis datos'!$B$24)*'Mis datos'!$B$23+IF('Mis datos'!$B$10="Sí",W14*'Mis datos'!$B$23,0),"") | P14: =IF(V14=1,(B14+IF('Mis datos'!$B$11="Sí",W14,0))*'Mis datos'!$H$6,"") | Q14: =IF(V14=1,B14+W14-M14-N14-O14-P14,"") | S14: =IF(ISNUMBER('Mis datos'!$H$5),'Mis datos'!$H$5+9,"") | T14: =IF(S14="","",INT(S14/12)*2+IF(MOD(S14,12)>=6,1,0)) | U14: =MAX(IF(V14=1,B14,0),IF(T14=T13,U13,0)) | V14: =IF(AND(S14<>"",ISNUMBER(B14)),IF(B14>0,1,0),0) | W14: =IF(ISNUMBER(C14),C14,0) | X14: =IF(AND(V14=1,ISNUMBER(D14)),D14-M14,0) | Y14: =IF(AND(V14=1,ISNUMBER(E14)),E14-N14,0) | Z14: =IF(AND(V14=1,ISNUMBER(F14)),F14-O14,0) | AA14: =IF(AND(V14=1,ISNUMBER(G14)),G14-P14,0) | AB14: =COUNT(D14:G14) | AC14: =IF(AND(V14=1,ISNUMBER(J14)),B14+W14-SUM(D14:I14)-J14,0) | AD14: =IF(V14=1,10,"")
A15: =IF(S15="","",INDEX(IPC!$J$5:$J$16,MOD(S15,12)+1)&" de "&INT((S15)/12)) | B15: 1310000 | D15: 144100 | E15: 39300 | F15: 39300 | G15: 26200 | J15: 1061100 | K15: =IF(V15=0,"",IF(AND(AB15=0,NOT(ISNUMBER(J15))),"Cargá los descuentos",IF(ABS(X15)>1,"Revisar jubilación",IF(ABS(Y15)>1,"Revisar Ley 19.032",IF(ABS(Z15)>1,"Revisar obra social",IF(ABS(AA15)>1,"Revisar cuota sindical",IF(ABS(AC15)>1,"El neto no da con los descuentos","Cuadra"))))))) | L15: =IF(OR(V15=0,AB15=0),"",X15+Y15+Z15+AA15) | M15: =IF(V15=1,MIN(B15,'Mis datos'!$B$24)*'Mis datos'!$B$21,"") | N15: =IF(V15=1,MIN(B15,'Mis datos'!$B$24)*'Mis datos'!$B$22,"") | O15: =IF(V15=1,MIN(B15,'Mis datos'!$B$24)*'Mis datos'!$B$23+IF('Mis datos'!$B$10="Sí",W15*'Mis datos'!$B$23,0),"") | P15: =IF(V15=1,(B15+IF('Mis datos'!$B$11="Sí",W15,0))*'Mis datos'!$H$6,"") | Q15: =IF(V15=1,B15+W15-M15-N15-O15-P15,"") | S15: =IF(ISNUMBER('Mis datos'!$H$5),'Mis datos'!$H$5+10,"") | T15: =IF(S15="","",INT(S15/12)*2+IF(MOD(S15,12)>=6,1,0)) | U15: =MAX(IF(V15=1,B15,0),IF(T15=T14,U14,0)) | V15: =IF(AND(S15<>"",ISNUMBER(B15)),IF(B15>0,1,0),0) | W15: =IF(ISNUMBER(C15),C15,0) | X15: =IF(AND(V15=1,ISNUMBER(D15)),D15-M15,0) | Y15: =IF(AND(V15=1,ISNUMBER(E15)),E15-N15,0) | Z15: =IF(AND(V15=1,ISNUMBER(F15)),F15-O15,0) | AA15: =IF(AND(V15=1,ISNUMBER(G15)),G15-P15,0) | AB15: =COUNT(D15:G15) | AC15: =IF(AND(V15=1,ISNUMBER(J15)),B15+W15-SUM(D15:I15)-J15,0) | AD15: =IF(V15=1,11,"")
A16: =IF(S16="","",INDEX(IPC!$J$5:$J$16,MOD(S16,12)+1)&" de "&INT((S16)/12)) | B16: 1310000 | D16: 144100 | E16: 39300 | F16: 39300 | G16: 26200 | J16: 1061100 | K16: =IF(V16=0,"",IF(AND(AB16=0,NOT(ISNUMBER(J16))),"Cargá los descuentos",IF(ABS(X16)>1,"Revisar jubilación",IF(ABS(Y16)>1,"Revisar Ley 19.032",IF(ABS(Z16)>1,"Revisar obra social",IF(ABS(AA16)>1,"Revisar cuota sindical",IF(ABS(AC16)>1,"El neto no da con los descuentos","Cuadra"))))))) | L16: =IF(OR(V16=0,AB16=0),"",X16+Y16+Z16+AA16) | M16: =IF(V16=1,MIN(B16,'Mis datos'!$B$24)*'Mis datos'!$B$21,"") | N16: =IF(V16=1,MIN(B16,'Mis datos'!$B$24)*'Mis datos'!$B$22,"") | O16: =IF(V16=1,MIN(B16,'Mis datos'!$B$24)*'Mis datos'!$B$23+IF('Mis datos'!$B$10="Sí",W16*'Mis datos'!$B$23,0),"") | P16: =IF(V16=1,(B16+IF('Mis datos'!$B$11="Sí",W16,0))*'Mis datos'!$H$6,"") | Q16: =IF(V16=1,B16+W16-M16-N16-O16-P16,"") | S16: =IF(ISNUMBER('Mis datos'!$H$5),'Mis datos'!$H$5+11,"") | T16: =IF(S16="","",INT(S16/12)*2+IF(MOD(S16,12)>=6,1,0)) | U16: =MAX(IF(V16=1,B16,0),IF(T16=T15,U15,0)) | V16: =IF(AND(S16<>"",ISNUMBER(B16)),IF(B16>0,1,0),0) | W16: =IF(ISNUMBER(C16),C16,0) | X16: =IF(AND(V16=1,ISNUMBER(D16)),D16-M16,0) | Y16: =IF(AND(V16=1,ISNUMBER(E16)),E16-N16,0) | Z16: =IF(AND(V16=1,ISNUMBER(F16)),F16-O16,0) | AA16: =IF(AND(V16=1,ISNUMBER(G16)),G16-P16,0) | AB16: =COUNT(D16:G16) | AC16: =IF(AND(V16=1,ISNUMBER(J16)),B16+W16-SUM(D16:I16)-J16,0) | AD16: =IF(V16=1,12,"")
A17: =IF(S17="","",INDEX(IPC!$J$5:$J$16,MOD(S17,12)+1)&" de "&INT((S17)/12)) | B17: 1310000 | D17: 144100 | E17: 39300 | F17: 39300 | G17: 26200 | J17: 1061100 | K17: =IF(V17=0,"",IF(AND(AB17=0,NOT(ISNUMBER(J17))),"Cargá los descuentos",IF(ABS(X17)>1,"Revisar jubilación",IF(ABS(Y17)>1,"Revisar Ley 19.032",IF(ABS(Z17)>1,"Revisar obra social",IF(ABS(AA17)>1,"Revisar cuota sindical",IF(ABS(AC17)>1,"El neto no da con los descuentos","Cuadra"))))))) | L17: =IF(OR(V17=0,AB17=0),"",X17+Y17+Z17+AA17) | M17: =IF(V17=1,MIN(B17,'Mis datos'!$B$24)*'Mis datos'!$B$21,"") | N17: =IF(V17=1,MIN(B17,'Mis datos'!$B$24)*'Mis datos'!$B$22,"") | O17: =IF(V17=1,MIN(B17,'Mis datos'!$B$24)*'Mis datos'!$B$23+IF('Mis datos'!$B$10="Sí",W17*'Mis datos'!$B$23,0),"") | P17: =IF(V17=1,(B17+IF('Mis datos'!$B$11="Sí",W17,0))*'Mis datos'!$H$6,"") | Q17: =IF(V17=1,B17+W17-M17-N17-O17-P17,"") | S17: =IF(ISNUMBER('Mis datos'!$H$5),'Mis datos'!$H$5+12,"") | T17: =IF(S17="","",INT(S17/12)*2+IF(MOD(S17,12)>=6,1,0)) | U17: =MAX(IF(V17=1,B17,0),IF(T17=T16,U16,0)) | V17: =IF(AND(S17<>"",ISNUMBER(B17)),IF(B17>0,1,0),0) | W17: =IF(ISNUMBER(C17),C17,0) | X17: =IF(AND(V17=1,ISNUMBER(D17)),D17-M17,0) | Y17: =IF(AND(V17=1,ISNUMBER(E17)),E17-N17,0) | Z17: =IF(AND(V17=1,ISNUMBER(F17)),F17-O17,0) | AA17: =IF(AND(V17=1,ISNUMBER(G17)),G17-P17,0) | AB17: =COUNT(D17:G17) | AC17: =IF(AND(V17=1,ISNUMBER(J17)),B17+W17-SUM(D17:I17)-J17,0) | AD17: =IF(V17=1,13,"")
A18: =IF(S18="","",INDEX(IPC!$J$5:$J$16,MOD(S18,12)+1)&" de "&INT((S18)/12)) | K18: =IF(V18=0,"",IF(AND(AB18=0,NOT(ISNUMBER(J18))),"Cargá los descuentos",IF(ABS(X18)>1,"Revisar jubilación",IF(ABS(Y18)>1,"Revisar Ley 19.032",IF(ABS(Z18)>1,"Revisar obra social",IF(ABS(AA18)>1,"Revisar cuota sindical",IF(ABS(AC18)>1,"El neto no da con los descuentos","Cuadra"))))))) | L18: =IF(OR(V18=0,AB18=0),"",X18+Y18+Z18+AA18) | M18: =IF(V18=1,MIN(B18,'Mis datos'!$B$24)*'Mis datos'!$B$21,"") | N18: =IF(V18=1,MIN(B18,'Mis datos'!$B$24)*'Mis datos'!$B$22,"") | O18: =IF(V18=1,MIN(B18,'Mis datos'!$B$24)*'Mis datos'!$B$23+IF('Mis datos'!$B$10="Sí",W18*'Mis datos'!$B$23,0),"") | P18: =IF(V18=1,(B18+IF('Mis datos'!$B$11="Sí",W18,0))*'Mis datos'!$H$6,"") | Q18: =IF(V18=1,B18+W18-M18-N18-O18-P18,"") | S18: =IF(ISNUMBER('Mis datos'!$H$5),'Mis datos'!$H$5+13,"") | T18: =IF(S18="","",INT(S18/12)*2+IF(MOD(S18,12)>=6,1,0)) | U18: =MAX(IF(V18=1,B18,0),IF(T18=T17,U17,0)) | V18: =IF(AND(S18<>"",ISNUMBER(B18)),IF(B18>0,1,0),0) | W18: =IF(ISNUMBER(C18),C18,0) | X18: =IF(AND(V18=1,ISNUMBER(D18)),D18-M18,0) | Y18: =IF(AND(V18=1,ISNUMBER(E18)),E18-N18,0) | Z18: =IF(AND(V18=1,ISNUMBER(F18)),F18-O18,0) | AA18: =IF(AND(V18=1,ISNUMBER(G18)),G18-P18,0) | AB18: =COUNT(D18:G18) | AC18: =IF(AND(V18=1,ISNUMBER(J18)),B18+W18-SUM(D18:I18)-J18,0) | AD18: =IF(V18=1,14,"")
A19: =IF(S19="","",INDEX(IPC!$J$5:$J$16,MOD(S19,12)+1)&" de "&INT((S19)/12)) | K19: =IF(V19=0,"",IF(AND(AB19=0,NOT(ISNUMBER(J19))),"Cargá los descuentos",IF(ABS(X19)>1,"Revisar jubilación",IF(ABS(Y19)>1,"Revisar Ley 19.032",IF(ABS(Z19)>1,"Revisar obra social",IF(ABS(AA19)>1,"Revisar cuota sindical",IF(ABS(AC19)>1,"El neto no da con los descuentos","Cuadra"))))))) | L19: =IF(OR(V19=0,AB19=0),"",X19+Y19+Z19+AA19) | M19: =IF(V19=1,MIN(B19,'Mis datos'!$B$24)*'Mis datos'!$B$21,"") | N19: =IF(V19=1,MIN(B19,'Mis datos'!$B$24)*'Mis datos'!$B$22,"") | O19: =IF(V19=1,MIN(B19,'Mis datos'!$B$24)*'Mis datos'!$B$23+IF('Mis datos'!$B$10="Sí",W19*'Mis datos'!$B$23,0),"") | P19: =IF(V19=1,(B19+IF('Mis datos'!$B$11="Sí",W19,0))*'Mis datos'!$H$6,"") | Q19: =IF(V19=1,B19+W19-M19-N19-O19-P19,"") | S19: =IF(ISNUMBER('Mis datos'!$H$5),'Mis datos'!$H$5+14,"") | T19: =IF(S19="","",INT(S19/12)*2+IF(MOD(S19,12)>=6,1,0)) | U19: =MAX(IF(V19=1,B19,0),IF(T19=T18,U18,0)) | V19: =IF(AND(S19<>"",ISNUMBER(B19)),IF(B19>0,1,0),0) | W19: =IF(ISNUMBER(C19),C19,0) | X19: =IF(AND(V19=1,ISNUMBER(D19)),D19-M19,0) | Y19: =IF(AND(V19=1,ISNUMBER(E19)),E19-N19,0) | Z19: =IF(AND(V19=1,ISNUMBER(F19)),F19-O19,0) | AA19: =IF(AND(V19=1,ISNUMBER(G19)),G19-P19,0) | AB19: =COUNT(D19:G19) | AC19: =IF(AND(V19=1,ISNUMBER(J19)),B19+W19-SUM(D19:I19)-J19,0) | AD19: =IF(V19=1,15,"")
A20: =IF(S20="","",INDEX(IPC!$J$5:$J$16,MOD(S20,12)+1)&" de "&INT((S20)/12)) | K20: =IF(V20=0,"",IF(AND(AB20=0,NOT(ISNUMBER(J20))),"Cargá los descuentos",IF(ABS(X20)>1,"Revisar jubilación",IF(ABS(Y20)>1,"Revisar Ley 19.032",IF(ABS(Z20)>1,"Revisar obra social",IF(ABS(AA20)>1,"Revisar cuota sindical",IF(ABS(AC20)>1,"El neto no da con los descuentos","Cuadra"))))))) | L20: =IF(OR(V20=0,AB20=0),"",X20+Y20+Z20+AA20) | M20: =IF(V20=1,MIN(B20,'Mis datos'!$B$24)*'Mis datos'!$B$21,"") | N20: =IF(V20=1,MIN(B20,'Mis datos'!$B$24)*'Mis datos'!$B$22,"") | O20: =IF(V20=1,MIN(B20,'Mis datos'!$B$24)*'Mis datos'!$B$23+IF('Mis datos'!$B$10="Sí",W20*'Mis datos'!$B$23,0),"") | P20: =IF(V20=1,(B20+IF('Mis datos'!$B$11="Sí",W20,0))*'Mis datos'!$H$6,"") | Q20: =IF(V20=1,B20+W20-M20-N20-O20-P20,"") | S20: =IF(ISNUMBER('Mis datos'!$H$5),'Mis datos'!$H$5+15,"") | T20: =IF(S20="","",INT(S20/12)*2+IF(MOD(S20,12)>=6,1,0)) | U20: =MAX(IF(V20=1,B20,0),IF(T20=T19,U19,0)) | V20: =IF(AND(S20<>"",ISNUMBER(B20)),IF(B20>0,1,0),0) | W20: =IF(ISNUMBER(C20),C20,0) | X20: =IF(AND(V20=1,ISNUMBER(D20)),D20-M20,0) | Y20: =IF(AND(V20=1,ISNUMBER(E20)),E20-N20,0) | Z20: =IF(AND(V20=1,ISNUMBER(F20)),F20-O20,0) | AA20: =IF(AND(V20=1,ISNUMBER(G20)),G20-P20,0) | AB20: =COUNT(D20:G20) | AC20: =IF(AND(V20=1,ISNUMBER(J20)),B20+W20-SUM(D20:I20)-J20,0) | AD20: =IF(V20=1,16,"")
A21: =IF(S21="","",INDEX(IPC!$J$5:$J$16,MOD(S21,12)+1)&" de "&INT((S21)/12)) | K21: =IF(V21=0,"",IF(AND(AB21=0,NOT(ISNUMBER(J21))),"Cargá los descuentos",IF(ABS(X21)>1,"Revisar jubilación",IF(ABS(Y21)>1,"Revisar Ley 19.032",IF(ABS(Z21)>1,"Revisar obra social",IF(ABS(AA21)>1,"Revisar cuota sindical",IF(ABS(AC21)>1,"El neto no da con los descuentos","Cuadra"))))))) | L21: =IF(OR(V21=0,AB21=0),"",X21+Y21+Z21+AA21) | M21: =IF(V21=1,MIN(B21,'Mis datos'!$B$24)*'Mis datos'!$B$21,"") | N21: =IF(V21=1,MIN(B21,'Mis datos'!$B$24)*'Mis datos'!$B$22,"") | O21: =IF(V21=1,MIN(B21,'Mis datos'!$B$24)*'Mis datos'!$B$23+IF('Mis datos'!$B$10="Sí",W21*'Mis datos'!$B$23,0),"") | P21: =IF(V21=1,(B21+IF('Mis datos'!$B$11="Sí",W21,0))*'Mis datos'!$H$6,"") | Q21: =IF(V21=1,B21+W21-M21-N21-O21-P21,"") | S21: =IF(ISNUMBER('Mis datos'!$H$5),'Mis datos'!$H$5+16,"") | T21: =IF(S21="","",INT(S21/12)*2+IF(MOD(S21,12)>=6,1,0)) | U21: =MAX(IF(V21=1,B21,0),IF(T21=T20,U20,0)) | V21: =IF(AND(S21<>"",ISNUMBER(B21)),IF(B21>0,1,0),0) | W21: =IF(ISNUMBER(C21),C21,0) | X21: =IF(AND(V21=1,ISNUMBER(D21)),D21-M21,0) | Y21: =IF(AND(V21=1,ISNUMBER(E21)),E21-N21,0) | Z21: =IF(AND(V21=1,ISNUMBER(F21)),F21-O21,0) | AA21: =IF(AND(V21=1,ISNUMBER(G21)),G21-P21,0) | AB21: =COUNT(D21:G21) | AC21: =IF(AND(V21=1,ISNUMBER(J21)),B21+W21-SUM(D21:I21)-J21,0) | AD21: =IF(V21=1,17,"")
A22: =IF(S22="","",INDEX(IPC!$J$5:$J$16,MOD(S22,12)+1)&" de "&INT((S22)/12)) | K22: =IF(V22=0,"",IF(AND(AB22=0,NOT(ISNUMBER(J22))),"Cargá los descuentos",IF(ABS(X22)>1,"Revisar jubilación",IF(ABS(Y22)>1,"Revisar Ley 19.032",IF(ABS(Z22)>1,"Revisar obra social",IF(ABS(AA22)>1,"Revisar cuota sindical",IF(ABS(AC22)>1,"El neto no da con los descuentos","Cuadra"))))))) | L22: =IF(OR(V22=0,AB22=0),"",X22+Y22+Z22+AA22) | M22: =IF(V22=1,MIN(B22,'Mis datos'!$B$24)*'Mis datos'!$B$21,"") | N22: =IF(V22=1,MIN(B22,'Mis datos'!$B$24)*'Mis datos'!$B$22,"") | O22: =IF(V22=1,MIN(B22,'Mis datos'!$B$24)*'Mis datos'!$B$23+IF('Mis datos'!$B$10="Sí",W22*'Mis datos'!$B$23,0),"") | P22: =IF(V22=1,(B22+IF('Mis datos'!$B$11="Sí",W22,0))*'Mis datos'!$H$6,"") | Q22: =IF(V22=1,B22+W22-M22-N22-O22-P22,"") | S22: =IF(ISNUMBER('Mis datos'!$H$5),'Mis datos'!$H$5+17,"") | T22: =IF(S22="","",INT(S22/12)*2+IF(MOD(S22,12)>=6,1,0)) | U22: =MAX(IF(V22=1,B22,0),IF(T22=T21,U21,0)) | V22: =IF(AND(S22<>"",ISNUMBER(B22)),IF(B22>0,1,0),0) | W22: =IF(ISNUMBER(C22),C22,0) | X22: =IF(AND(V22=1,ISNUMBER(D22)),D22-M22,0) | Y22: =IF(AND(V22=1,ISNUMBER(E22)),E22-N22,0) | Z22: =IF(AND(V22=1,ISNUMBER(F22)),F22-O22,0) | AA22: =IF(AND(V22=1,ISNUMBER(G22)),G22-P22,0) | AB22: =COUNT(D22:G22) | AC22: =IF(AND(V22=1,ISNUMBER(J22)),B22+W22-SUM(D22:I22)-J22,0) | AD22: =IF(V22=1,18,"")
A23: =IF(S23="","",INDEX(IPC!$J$5:$J$16,MOD(S23,12)+1)&" de "&INT((S23)/12)) | K23: =IF(V23=0,"",IF(AND(AB23=0,NOT(ISNUMBER(J23))),"Cargá los descuentos",IF(ABS(X23)>1,"Revisar jubilación",IF(ABS(Y23)>1,"Revisar Ley 19.032",IF(ABS(Z23)>1,"Revisar obra social",IF(ABS(AA23)>1,"Revisar cuota sindical",IF(ABS(AC23)>1,"El neto no da con los descuentos","Cuadra"))))))) | L23: =IF(OR(V23=0,AB23=0),"",X23+Y23+Z23+AA23) | M23: =IF(V23=1,MIN(B23,'Mis datos'!$B$24)*'Mis datos'!$B$21,"") | N23: =IF(V23=1,MIN(B23,'Mis datos'!$B$24)*'Mis datos'!$B$22,"") | O23: =IF(V23=1,MIN(B23,'Mis datos'!$B$24)*'Mis datos'!$B$23+IF('Mis datos'!$B$10="Sí",W23*'Mis datos'!$B$23,0),"") | P23: =IF(V23=1,(B23+IF('Mis datos'!$B$11="Sí",W23,0))*'Mis datos'!$H$6,"") | Q23: =IF(V23=1,B23+W23-M23-N23-O23-P23,"") | S23: =IF(ISNUMBER('Mis datos'!$H$5),'Mis datos'!$H$5+18,"") | T23: =IF(S23="","",INT(S23/12)*2+IF(MOD(S23,12)>=6,1,0)) | U23: =MAX(IF(V23=1,B23,0),IF(T23=T22,U22,0)) | V23: =IF(AND(S23<>"",ISNUMBER(B23)),IF(B23>0,1,0),0) | W23: =IF(ISNUMBER(C23),C23,0) | X23: =IF(AND(V23=1,ISNUMBER(D23)),D23-M23,0) | Y23: =IF(AND(V23=1,ISNUMBER(E23)),E23-N23,0) | Z23: =IF(AND(V23=1,ISNUMBER(F23)),F23-O23,0) | AA23: =IF(AND(V23=1,ISNUMBER(G23)),G23-P23,0) | AB23: =COUNT(D23:G23) | AC23: =IF(AND(V23=1,ISNUMBER(J23)),B23+W23-SUM(D23:I23)-J23,0) | AD23: =IF(V23=1,19,"")
A24: =IF(S24="","",INDEX(IPC!$J$5:$J$16,MOD(S24,12)+1)&" de "&INT((S24)/12)) | K24: =IF(V24=0,"",IF(AND(AB24=0,NOT(ISNUMBER(J24))),"Cargá los descuentos",IF(ABS(X24)>1,"Revisar jubilación",IF(ABS(Y24)>1,"Revisar Ley 19.032",IF(ABS(Z24)>1,"Revisar obra social",IF(ABS(AA24)>1,"Revisar cuota sindical",IF(ABS(AC24)>1,"El neto no da con los descuentos","Cuadra"))))))) | L24: =IF(OR(V24=0,AB24=0),"",X24+Y24+Z24+AA24) | M24: =IF(V24=1,MIN(B24,'Mis datos'!$B$24)*'Mis datos'!$B$21,"") | N24: =IF(V24=1,MIN(B24,'Mis datos'!$B$24)*'Mis datos'!$B$22,"") | O24: =IF(V24=1,MIN(B24,'Mis datos'!$B$24)*'Mis datos'!$B$23+IF('Mis datos'!$B$10="Sí",W24*'Mis datos'!$B$23,0),"") | P24: =IF(V24=1,(B24+IF('Mis datos'!$B$11="Sí",W24,0))*'Mis datos'!$H$6,"") | Q24: =IF(V24=1,B24+W24-M24-N24-O24-P24,"") | S24: =IF(ISNUMBER('Mis datos'!$H$5),'Mis datos'!$H$5+19,"") | T24: =IF(S24="","",INT(S24/12)*2+IF(MOD(S24,12)>=6,1,0)) | U24: =MAX(IF(V24=1,B24,0),IF(T24=T23,U23,0)) | V24: =IF(AND(S24<>"",ISNUMBER(B24)),IF(B24>0,1,0),0) | W24: =IF(ISNUMBER(C24),C24,0) | X24: =IF(AND(V24=1,ISNUMBER(D24)),D24-M24,0) | Y24: =IF(AND(V24=1,ISNUMBER(E24)),E24-N24,0) | Z24: =IF(AND(V24=1,ISNUMBER(F24)),F24-O24,0) | AA24: =IF(AND(V24=1,ISNUMBER(G24)),G24-P24,0) | AB24: =COUNT(D24:G24) | AC24: =IF(AND(V24=1,ISNUMBER(J24)),B24+W24-SUM(D24:I24)-J24,0) | AD24: =IF(V24=1,20,"")
A25: =IF(S25="","",INDEX(IPC!$J$5:$J$16,MOD(S25,12)+1)&" de "&INT((S25)/12)) | K25: =IF(V25=0,"",IF(AND(AB25=0,NOT(ISNUMBER(J25))),"Cargá los descuentos",IF(ABS(X25)>1,"Revisar jubilación",IF(ABS(Y25)>1,"Revisar Ley 19.032",IF(ABS(Z25)>1,"Revisar obra social",IF(ABS(AA25)>1,"Revisar cuota sindical",IF(ABS(AC25)>1,"El neto no da con los descuentos","Cuadra"))))))) | L25: =IF(OR(V25=0,AB25=0),"",X25+Y25+Z25+AA25) | M25: =IF(V25=1,MIN(B25,'Mis datos'!$B$24)*'Mis datos'!$B$21,"") | N25: =IF(V25=1,MIN(B25,'Mis datos'!$B$24)*'Mis datos'!$B$22,"") | O25: =IF(V25=1,MIN(B25,'Mis datos'!$B$24)*'Mis datos'!$B$23+IF('Mis datos'!$B$10="Sí",W25*'Mis datos'!$B$23,0),"") | P25: =IF(V25=1,(B25+IF('Mis datos'!$B$11="Sí",W25,0))*'Mis datos'!$H$6,"") | Q25: =IF(V25=1,B25+W25-M25-N25-O25-P25,"") | S25: =IF(ISNUMBER('Mis datos'!$H$5),'Mis datos'!$H$5+20,"") | T25: =IF(S25="","",INT(S25/12)*2+IF(MOD(S25,12)>=6,1,0)) | U25: =MAX(IF(V25=1,B25,0),IF(T25=T24,U24,0)) | V25: =IF(AND(S25<>"",ISNUMBER(B25)),IF(B25>0,1,0),0) | W25: =IF(ISNUMBER(C25),C25,0) | X25: =IF(AND(V25=1,ISNUMBER(D25)),D25-M25,0) | Y25: =IF(AND(V25=1,ISNUMBER(E25)),E25-N25,0) | Z25: =IF(AND(V25=1,ISNUMBER(F25)),F25-O25,0) | AA25: =IF(AND(V25=1,ISNUMBER(G25)),G25-P25,0) | AB25: =COUNT(D25:G25) | AC25: =IF(AND(V25=1,ISNUMBER(J25)),B25+W25-SUM(D25:I25)-J25,0) | AD25: =IF(V25=1,21,"")
A26: =IF(S26="","",INDEX(IPC!$J$5:$J$16,MOD(S26,12)+1)&" de "&INT((S26)/12)) | K26: =IF(V26=0,"",IF(AND(AB26=0,NOT(ISNUMBER(J26))),"Cargá los descuentos",IF(ABS(X26)>1,"Revisar jubilación",IF(ABS(Y26)>1,"Revisar Ley 19.032",IF(ABS(Z26)>1,"Revisar obra social",IF(ABS(AA26)>1,"Revisar cuota sindical",IF(ABS(AC26)>1,"El neto no da con los descuentos","Cuadra"))))))) | L26: =IF(OR(V26=0,AB26=0),"",X26+Y26+Z26+AA26) | M26: =IF(V26=1,MIN(B26,'Mis datos'!$B$24)*'Mis datos'!$B$21,"") | N26: =IF(V26=1,MIN(B26,'Mis datos'!$B$24)*'Mis datos'!$B$22,"") | O26: =IF(V26=1,MIN(B26,'Mis datos'!$B$24)*'Mis datos'!$B$23+IF('Mis datos'!$B$10="Sí",W26*'Mis datos'!$B$23,0),"") | P26: =IF(V26=1,(B26+IF('Mis datos'!$B$11="Sí",W26,0))*'Mis datos'!$H$6,"") | Q26: =IF(V26=1,B26+W26-M26-N26-O26-P26,"") | S26: =IF(ISNUMBER('Mis datos'!$H$5),'Mis datos'!$H$5+21,"") | T26: =IF(S26="","",INT(S26/12)*2+IF(MOD(S26,12)>=6,1,0)) | U26: =MAX(IF(V26=1,B26,0),IF(T26=T25,U25,0)) | V26: =IF(AND(S26<>"",ISNUMBER(B26)),IF(B26>0,1,0),0) | W26: =IF(ISNUMBER(C26),C26,0) | X26: =IF(AND(V26=1,ISNUMBER(D26)),D26-M26,0) | Y26: =IF(AND(V26=1,ISNUMBER(E26)),E26-N26,0) | Z26: =IF(AND(V26=1,ISNUMBER(F26)),F26-O26,0) | AA26: =IF(AND(V26=1,ISNUMBER(G26)),G26-P26,0) | AB26: =COUNT(D26:G26) | AC26: =IF(AND(V26=1,ISNUMBER(J26)),B26+W26-SUM(D26:I26)-J26,0) | AD26: =IF(V26=1,22,"")
A27: =IF(S27="","",INDEX(IPC!$J$5:$J$16,MOD(S27,12)+1)&" de "&INT((S27)/12)) | K27: =IF(V27=0,"",IF(AND(AB27=0,NOT(ISNUMBER(J27))),"Cargá los descuentos",IF(ABS(X27)>1,"Revisar jubilación",IF(ABS(Y27)>1,"Revisar Ley 19.032",IF(ABS(Z27)>1,"Revisar obra social",IF(ABS(AA27)>1,"Revisar cuota sindical",IF(ABS(AC27)>1,"El neto no da con los descuentos","Cuadra"))))))) | L27: =IF(OR(V27=0,AB27=0),"",X27+Y27+Z27+AA27) | M27: =IF(V27=1,MIN(B27,'Mis datos'!$B$24)*'Mis datos'!$B$21,"") | N27: =IF(V27=1,MIN(B27,'Mis datos'!$B$24)*'Mis datos'!$B$22,"") | O27: =IF(V27=1,MIN(B27,'Mis datos'!$B$24)*'Mis datos'!$B$23+IF('Mis datos'!$B$10="Sí",W27*'Mis datos'!$B$23,0),"") | P27: =IF(V27=1,(B27+IF('Mis datos'!$B$11="Sí",W27,0))*'Mis datos'!$H$6,"") | Q27: =IF(V27=1,B27+W27-M27-N27-O27-P27,"") | S27: =IF(ISNUMBER('Mis datos'!$H$5),'Mis datos'!$H$5+22,"") | T27: =IF(S27="","",INT(S27/12)*2+IF(MOD(S27,12)>=6,1,0)) | U27: =MAX(IF(V27=1,B27,0),IF(T27=T26,U26,0)) | V27: =IF(AND(S27<>"",ISNUMBER(B27)),IF(B27>0,1,0),0) | W27: =IF(ISNUMBER(C27),C27,0) | X27: =IF(AND(V27=1,ISNUMBER(D27)),D27-M27,0) | Y27: =IF(AND(V27=1,ISNUMBER(E27)),E27-N27,0) | Z27: =IF(AND(V27=1,ISNUMBER(F27)),F27-O27,0) | AA27: =IF(AND(V27=1,ISNUMBER(G27)),G27-P27,0) | AB27: =COUNT(D27:G27) | AC27: =IF(AND(V27=1,ISNUMBER(J27)),B27+W27-SUM(D27:I27)-J27,0) | AD27: =IF(V27=1,23,"")
A28: =IF(S28="","",INDEX(IPC!$J$5:$J$16,MOD(S28,12)+1)&" de "&INT((S28)/12)) | K28: =IF(V28=0,"",IF(AND(AB28=0,NOT(ISNUMBER(J28))),"Cargá los descuentos",IF(ABS(X28)>1,"Revisar jubilación",IF(ABS(Y28)>1,"Revisar Ley 19.032",IF(ABS(Z28)>1,"Revisar obra social",IF(ABS(AA28)>1,"Revisar cuota sindical",IF(ABS(AC28)>1,"El neto no da con los descuentos","Cuadra"))))))) | L28: =IF(OR(V28=0,AB28=0),"",X28+Y28+Z28+AA28) | M28: =IF(V28=1,MIN(B28,'Mis datos'!$B$24)*'Mis datos'!$B$21,"") | N28: =IF(V28=1,MIN(B28,'Mis datos'!$B$24)*'Mis datos'!$B$22,"") | O28: =IF(V28=1,MIN(B28,'Mis datos'!$B$24)*'Mis datos'!$B$23+IF('Mis datos'!$B$10="Sí",W28*'Mis datos'!$B$23,0),"") | P28: =IF(V28=1,(B28+IF('Mis datos'!$B$11="Sí",W28,0))*'Mis datos'!$H$6,"") | Q28: =IF(V28=1,B28+W28-M28-N28-O28-P28,"") | S28: =IF(ISNUMBER('Mis datos'!$H$5),'Mis datos'!$H$5+23,"") | T28: =IF(S28="","",INT(S28/12)*2+IF(MOD(S28,12)>=6,1,0)) | U28: =MAX(IF(V28=1,B28,0),IF(T28=T27,U27,0)) | V28: =IF(AND(S28<>"",ISNUMBER(B28)),IF(B28>0,1,0),0) | W28: =IF(ISNUMBER(C28),C28,0) | X28: =IF(AND(V28=1,ISNUMBER(D28)),D28-M28,0) | Y28: =IF(AND(V28=1,ISNUMBER(E28)),E28-N28,0) | Z28: =IF(AND(V28=1,ISNUMBER(F28)),F28-O28,0) | AA28: =IF(AND(V28=1,ISNUMBER(G28)),G28-P28,0) | AB28: =COUNT(D28:G28) | AC28: =IF(AND(V28=1,ISNUMBER(J28)),B28+W28-SUM(D28:I28)-J28,0) | AD28: =IF(V28=1,24,"")
A30: «Diferencia en aportes» = lo que te descontaron menos lo que marca la ley (positivo: te descontaron de más). Una diferencia de hasta $1 es redondeo. Si aparece «Revisar», no siempre es un error: mirá primero si el concepto es remunerativo, si tu convenio descuenta algo sobre lo no remunerativo (en «Mis datos») o si el tope de ese mes era otro. Si sigue sin cuadrar, consultalo con tu empleador o RR. HH. con el recibo en la mano.

Sheet Sueldo vs inflación
A1: Tu sueldo frente a la inflación
A2: ="Cada sueldo llevado a pesos de "&INDEX(IPC!$J$5:$J$16,MOD(IPC!$J$3,12)+1)&" de "&INT((IPC!$J$3)/12)&", el último IPC publicado por el INDEC. Si la columna E baja, tu sueldo compra menos que antes."
A4: Mes | B4: Tu sueldo | C4: Cambio del sueldo | D4: Inflación del mes | E4: ="En pesos de "&INDEX(IPC!$J$5:$J$16,MOD(IPC!$J$3,12)+1)&" de "&INT((IPC!$J$3)/12) | F4: Poder de compra vs. el primer mes
A5: ='Mis recibos'!A5 | B5: =IF('Mis recibos'!V5=1,IF('Mis datos'!$B$12="Lo que cobré en mano",IF(ISNUMBER('Mis recibos'!J5),'Mis recibos'!J5,""),'Mis recibos'!B5+'Mis recibos'!W5),"") | C5: ="" | D5: =IF(AND(ISNUMBER(H5),'Mis recibos'!S5>IPC!$J$2),H5/INDEX(IPC!$D$5:$D$197,('Mis recibos'!S5-1)-IPC!$J$2+1)-1,"") | E5: =IF(AND(ISNUMBER(B5),ISNUMBER(H5)),B5*INDEX(IPC!$D$5:$D$197,(IPC!$J$3)-IPC!$J$2+1)/H5,"") | F5: =IF(AND(ISNUMBER(E5),ISNUMBER(N25)),E5/N25-1,"") | H5: =IF('Mis recibos'!S5="","",IF(OR('Mis recibos'!S5>IPC!$J$3,'Mis recibos'!S5<IPC!$J$2),"",INDEX(IPC!$D$5:$D$197,('Mis recibos'!S5)-IPC!$J$2+1))) | I5: =IF(ISNUMBER(B5),1,"") | J5: ="" | K5: =IF(ISNUMBER(E5),1,"") | N5: =MAX(I5:I28)
A6: ='Mis recibos'!A6 | B6: =IF('Mis recibos'!V6=1,IF('Mis datos'!$B$12="Lo que cobré en mano",IF(ISNUMBER('Mis recibos'!J6),'Mis recibos'!J6,""),'Mis recibos'!B6+'Mis recibos'!W6),"") | C6: =IF(AND(ISNUMBER(B6),ISNUMBER(B5)),B6/B5-1,"") | D6: =IF(AND(ISNUMBER(H6),'Mis recibos'!S6>IPC!$J$2),H6/INDEX(IPC!$D$5:$D$197,('Mis recibos'!S6-1)-IPC!$J$2+1)-1,"") | E6: =IF(AND(ISNUMBER(B6),ISNUMBER(H6)),B6*INDEX(IPC!$D$5:$D$197,(IPC!$J$3)-IPC!$J$2+1)/H6,"") | F6: =IF(AND(ISNUMBER(E6),ISNUMBER(N25)),E6/N25-1,"") | H6: =IF('Mis recibos'!S6="","",IF(OR('Mis recibos'!S6>IPC!$J$3,'Mis recibos'!S6<IPC!$J$2),"",INDEX(IPC!$D$5:$D$197,('Mis recibos'!S6)-IPC!$J$2+1))) | I6: =IF(ISNUMBER(B6),2,"") | J6: =IF(AND(ISNUMBER(B6),ISNUMBER(B5)),IF(B6>B5+0.5,2,""),"") | K6: =IF(ISNUMBER(E6),2,"") | N6: =MAX(J5:J28)
A7: ='Mis recibos'!A7 | B7: =IF('Mis recibos'!V7=1,IF('Mis datos'!$B$12="Lo que cobré en mano",IF(ISNUMBER('Mis recibos'!J7),'Mis recibos'!J7,""),'Mis recibos'!B7+'Mis recibos'!W7),"") | C7: =IF(AND(ISNUMBER(B7),ISNUMBER(B6)),B7/B6-1,"") | D7: =IF(AND(ISNUMBER(H7),'Mis recibos'!S7>IPC!$J$2),H7/INDEX(IPC!$D$5:$D$197,('Mis recibos'!S7-1)-IPC!$J$2+1)-1,"") | E7: =IF(AND(ISNUMBER(B7),ISNUMBER(H7)),B7*INDEX(IPC!$D$5:$D$197,(IPC!$J$3)-IPC!$J$2+1)/H7,"") | F7: =IF(AND(ISNUMBER(E7),ISNUMBER(N25)),E7/N25-1,"") | H7: =IF('Mis recibos'!S7="","",IF(OR('Mis recibos'!S7>IPC!$J$3,'Mis recibos'!S7<IPC!$J$2),"",INDEX(IPC!$D$5:$D$197,('Mis recibos'!S7)-IPC!$J$2+1))) | I7: =IF(ISNUMBER(B7),3,"") | J7: =IF(AND(ISNUMBER(B7),ISNUMBER(B6)),IF(B7>B6+0.5,3,""),"") | K7: =IF(ISNUMBER(E7),3,"") | N7: =IF(COUNT(I5:I28)=0,0,MIN(I5:I28))
A8: ='Mis recibos'!A8 | B8: =IF('Mis recibos'!V8=1,IF('Mis datos'!$B$12="Lo que cobré en mano",IF(ISNUMBER('Mis recibos'!J8),'Mis recibos'!J8,""),'Mis recibos'!B8+'Mis recibos'!W8),"") | C8: =IF(AND(ISNUMBER(B8),ISNUMBER(B7)),B8/B7-1,"") | D8: =IF(AND(ISNUMBER(H8),'Mis recibos'!S8>IPC!$J$2),H8/INDEX(IPC!$D$5:$D$197,('Mis recibos'!S8-1)-IPC!$J$2+1)-1,"") | E8: =IF(AND(ISNUMBER(B8),ISNUMBER(H8)),B8*INDEX(IPC!$D$5:$D$197,(IPC!$J$3)-IPC!$J$2+1)/H8,"") | F8: =IF(AND(ISNUMBER(E8),ISNUMBER(N25)),E8/N25-1,"") | H8: =IF('Mis recibos'!S8="","",IF(OR('Mis recibos'!S8>IPC!$J$3,'Mis recibos'!S8<IPC!$J$2),"",INDEX(IPC!$D$5:$D$197,('Mis recibos'!S8)-IPC!$J$2+1))) | I8: =IF(ISNUMBER(B8),4,"") | J8: =IF(AND(ISNUMBER(B8),ISNUMBER(B7)),IF(B8>B7+0.5,4,""),"") | K8: =IF(ISNUMBER(E8),4,"") | N8: =IF(N6>0,N6,N7)
A9: ='Mis recibos'!A9 | B9: =IF('Mis recibos'!V9=1,IF('Mis datos'!$B$12="Lo que cobré en mano",IF(ISNUMBER('Mis recibos'!J9),'Mis recibos'!J9,""),'Mis recibos'!B9+'Mis recibos'!W9),"") | C9: =IF(AND(ISNUMBER(B9),ISNUMBER(B8)),B9/B8-1,"") | D9: =IF(AND(ISNUMBER(H9),'Mis recibos'!S9>IPC!$J$2),H9/INDEX(IPC!$D$5:$D$197,('Mis recibos'!S9-1)-IPC!$J$2+1)-1,"") | E9: =IF(AND(ISNUMBER(B9),ISNUMBER(H9)),B9*INDEX(IPC!$D$5:$D$197,(IPC!$J$3)-IPC!$J$2+1)/H9,"") | F9: =IF(AND(ISNUMBER(E9),ISNUMBER(N25)),E9/N25-1,"") | H9: =IF('Mis recibos'!S9="","",IF(OR('Mis recibos'!S9>IPC!$J$3,'Mis recibos'!S9<IPC!$J$2),"",INDEX(IPC!$D$5:$D$197,('Mis recibos'!S9)-IPC!$J$2+1))) | I9: =IF(ISNUMBER(B9),5,"") | J9: =IF(AND(ISNUMBER(B9),ISNUMBER(B8)),IF(B9>B8+0.5,5,""),"") | K9: =IF(ISNUMBER(E9),5,"") | N9: =IF(N5>0,INDEX(B5:B28,N5),"")
A10: ='Mis recibos'!A10 | B10: =IF('Mis recibos'!V10=1,IF('Mis datos'!$B$12="Lo que cobré en mano",IF(ISNUMBER('Mis recibos'!J10),'Mis recibos'!J10,""),'Mis recibos'!B10+'Mis recibos'!W10),"") | C10: =IF(AND(ISNUMBER(B10),ISNUMBER(B9)),B10/B9-1,"") | D10: =IF(AND(ISNUMBER(H10),'Mis recibos'!S10>IPC!$J$2),H10/INDEX(IPC!$D$5:$D$197,('Mis recibos'!S10-1)-IPC!$J$2+1)-1,"") | E10: =IF(AND(ISNUMBER(B10),ISNUMBER(H10)),B10*INDEX(IPC!$D$5:$D$197,(IPC!$J$3)-IPC!$J$2+1)/H10,"") | F10: =IF(AND(ISNUMBER(E10),ISNUMBER(N25)),E10/N25-1,"") | H10: =IF('Mis recibos'!S10="","",IF(OR('Mis recibos'!S10>IPC!$J$3,'Mis recibos'!S10<IPC!$J$2),"",INDEX(IPC!$D$5:$D$197,('Mis recibos'!S10)-IPC!$J$2+1))) | I10: =IF(ISNUMBER(B10),6,"") | J10: =IF(AND(ISNUMBER(B10),ISNUMBER(B9)),IF(B10>B9+0.5,6,""),"") | K10: =IF(ISNUMBER(E10),6,"") | N10: =IF(N8>0,INDEX(B5:B28,N8),"")
A11: ='Mis recibos'!A11 | B11: =IF('Mis recibos'!V11=1,IF('Mis datos'!$B$12="Lo que cobré en mano",IF(ISNUMBER('Mis recibos'!J11),'Mis recibos'!J11,""),'Mis recibos'!B11+'Mis recibos'!W11),"") | C11: =IF(AND(ISNUMBER(B11),ISNUMBER(B10)),B11/B10-1,"") | D11: =IF(AND(ISNUMBER(H11),'Mis recibos'!S11>IPC!$J$2),H11/INDEX(IPC!$D$5:$D$197,('Mis recibos'!S11-1)-IPC!$J$2+1)-1,"") | E11: =IF(AND(ISNUMBER(B11),ISNUMBER(H11)),B11*INDEX(IPC!$D$5:$D$197,(IPC!$J$3)-IPC!$J$2+1)/H11,"") | F11: =IF(AND(ISNUMBER(E11),ISNUMBER(N25)),E11/N25-1,"") | H11: =IF('Mis recibos'!S11="","",IF(OR('Mis recibos'!S11>IPC!$J$3,'Mis recibos'!S11<IPC!$J$2),"",INDEX(IPC!$D$5:$D$197,('Mis recibos'!S11)-IPC!$J$2+1))) | I11: =IF(ISNUMBER(B11),7,"") | J11: =IF(AND(ISNUMBER(B11),ISNUMBER(B10)),IF(B11>B10+0.5,7,""),"") | K11: =IF(ISNUMBER(E11),7,"") | N11: =IF(N8>0,INDEX('Mis recibos'!$S$5:$S$28,N8),"")
A12: ='Mis recibos'!A12 | B12: =IF('Mis recibos'!V12=1,IF('Mis datos'!$B$12="Lo que cobré en mano",IF(ISNUMBER('Mis recibos'!J12),'Mis recibos'!J12,""),'Mis recibos'!B12+'Mis recibos'!W12),"") | C12: =IF(AND(ISNUMBER(B12),ISNUMBER(B11)),B12/B11-1,"") | D12: =IF(AND(ISNUMBER(H12),'Mis recibos'!S12>IPC!$J$2),H12/INDEX(IPC!$D$5:$D$197,('Mis recibos'!S12-1)-IPC!$J$2+1)-1,"") | E12: =IF(AND(ISNUMBER(B12),ISNUMBER(H12)),B12*INDEX(IPC!$D$5:$D$197,(IPC!$J$3)-IPC!$J$2+1)/H12,"") | F12: =IF(AND(ISNUMBER(E12),ISNUMBER(N25)),E12/N25-1,"") | H12: =IF('Mis recibos'!S12="","",IF(OR('Mis recibos'!S12>IPC!$J$3,'Mis recibos'!S12<IPC!$J$2),"",INDEX(IPC!$D$5:$D$197,('Mis recibos'!S12)-IPC!$J$2+1))) | I12: =IF(ISNUMBER(B12),8,"") | J12: =IF(AND(ISNUMBER(B12),ISNUMBER(B11)),IF(B12>B11+0.5,8,""),"") | K12: =IF(ISNUMBER(E12),8,"") | N12: =IF(N5>0,INDEX('Mis recibos'!$S$5:$S$28,N5),"")
A13: ='Mis recibos'!A13 | B13: =IF('Mis recibos'!V13=1,IF('Mis datos'!$B$12="Lo que cobré en mano",IF(ISNUMBER('Mis recibos'!J13),'Mis recibos'!J13,""),'Mis recibos'!B13+'Mis recibos'!W13),"") | C13: =IF(AND(ISNUMBER(B13),ISNUMBER(B12)),B13/B12-1,"") | D13: =IF(AND(ISNUMBER(H13),'Mis recibos'!S13>IPC!$J$2),H13/INDEX(IPC!$D$5:$D$197,('Mis recibos'!S13-1)-IPC!$J$2+1)-1,"") | E13: =IF(AND(ISNUMBER(B13),ISNUMBER(H13)),B13*INDEX(IPC!$D$5:$D$197,(IPC!$J$3)-IPC!$J$2+1)/H13,"") | F13: =IF(AND(ISNUMBER(E13),ISNUMBER(N25)),E13/N25-1,"") | H13: =IF('Mis recibos'!S13="","",IF(OR('Mis recibos'!S13>IPC!$J$3,'Mis recibos'!S13<IPC!$J$2),"",INDEX(IPC!$D$5:$D$197,('Mis recibos'!S13)-IPC!$J$2+1))) | I13: =IF(ISNUMBER(B13),9,"") | J13: =IF(AND(ISNUMBER(B13),ISNUMBER(B12)),IF(B13>B12+0.5,9,""),"") | K13: =IF(ISNUMBER(E13),9,"") | N13: =IPC!$J$3
A14: ='Mis recibos'!A14 | B14: =IF('Mis recibos'!V14=1,IF('Mis datos'!$B$12="Lo que cobré en mano",IF(ISNUMBER('Mis recibos'!J14),'Mis recibos'!J14,""),'Mis recibos'!B14+'Mis recibos'!W14),"") | C14: =IF(AND(ISNUMBER(B14),ISNUMBER(B13)),B14/B13-1,"") | D14: =IF(AND(ISNUMBER(H14),'Mis recibos'!S14>IPC!$J$2),H14/INDEX(IPC!$D$5:$D$197,('Mis recibos'!S14-1)-IPC!$J$2+1)-1,"") | E14: =IF(AND(ISNUMBER(B14),ISNUMBER(H14)),B14*INDEX(IPC!$D$5:$D$197,(IPC!$J$3)-IPC!$J$2+1)/H14,"") | F14: =IF(AND(ISNUMBER(E14),ISNUMBER(N25)),E14/N25-1,"") | H14: =IF('Mis recibos'!S14="","",IF(OR('Mis recibos'!S14>IPC!$J$3,'Mis recibos'!S14<IPC!$J$2),"",INDEX(IPC!$D$5:$D$197,('Mis recibos'!S14)-IPC!$J$2+1))) | I14: =IF(ISNUMBER(B14),10,"") | J14: =IF(AND(ISNUMBER(B14),ISNUMBER(B13)),IF(B14>B13+0.5,10,""),"") | K14: =IF(ISNUMBER(E14),10,"") | N14: =IF(ISNUMBER(N11),IF(AND(N11<=N13,N11>=IPC!$J$2),INDEX(IPC!$D$5:$D$197,(N13)-IPC!$J$2+1)/INDEX(IPC!$D$5:$D$197,(N11)-IPC!$J$2+1),""),"")
A15: ='Mis recibos'!A15 | B15: =IF('Mis recibos'!V15=1,IF('Mis datos'!$B$12="Lo que cobré en mano",IF(ISNUMBER('Mis recibos'!J15),'Mis recibos'!J15,""),'Mis recibos'!B15+'Mis recibos'!W15),"") | C15: =IF(AND(ISNUMBER(B15),ISNUMBER(B14)),B15/B14-1,"") | D15: =IF(AND(ISNUMBER(H15),'Mis recibos'!S15>IPC!$J$2),H15/INDEX(IPC!$D$5:$D$197,('Mis recibos'!S15-1)-IPC!$J$2+1)-1,"") | E15: =IF(AND(ISNUMBER(B15),ISNUMBER(H15)),B15*INDEX(IPC!$D$5:$D$197,(IPC!$J$3)-IPC!$J$2+1)/H15,"") | F15: =IF(AND(ISNUMBER(E15),ISNUMBER(N25)),E15/N25-1,"") | H15: =IF('Mis recibos'!S15="","",IF(OR('Mis recibos'!S15>IPC!$J$3,'Mis recibos'!S15<IPC!$J$2),"",INDEX(IPC!$D$5:$D$197,('Mis recibos'!S15)-IPC!$J$2+1))) | I15: =IF(ISNUMBER(B15),11,"") | J15: =IF(AND(ISNUMBER(B15),ISNUMBER(B14)),IF(B15>B14+0.5,11,""),"") | K15: =IF(ISNUMBER(E15),11,"") | N15: =IF(ISNUMBER(N14),N9/(N10*N14)-1,"")
A16: ='Mis recibos'!A16 | B16: =IF('Mis recibos'!V16=1,IF('Mis datos'!$B$12="Lo que cobré en mano",IF(ISNUMBER('Mis recibos'!J16),'Mis recibos'!J16,""),'Mis recibos'!B16+'Mis recibos'!W16),"") | C16: =IF(AND(ISNUMBER(B16),ISNUMBER(B15)),B16/B15-1,"") | D16: =IF(AND(ISNUMBER(H16),'Mis recibos'!S16>IPC!$J$2),H16/INDEX(IPC!$D$5:$D$197,('Mis recibos'!S16-1)-IPC!$J$2+1)-1,"") | E16: =IF(AND(ISNUMBER(B16),ISNUMBER(H16)),B16*INDEX(IPC!$D$5:$D$197,(IPC!$J$3)-IPC!$J$2+1)/H16,"") | F16: =IF(AND(ISNUMBER(E16),ISNUMBER(N25)),E16/N25-1,"") | H16: =IF('Mis recibos'!S16="","",IF(OR('Mis recibos'!S16>IPC!$J$3,'Mis recibos'!S16<IPC!$J$2),"",INDEX(IPC!$D$5:$D$197,('Mis recibos'!S16)-IPC!$J$2+1))) | I16: =IF(ISNUMBER(B16),12,"") | J16: =IF(AND(ISNUMBER(B16),ISNUMBER(B15)),IF(B16>B15+0.5,12,""),"") | K16: =IF(ISNUMBER(E16),12,"") | N16: =IF(ISNUMBER(N14),MAX(0,N10*N14/N9-1),"")
A17: ='Mis recibos'!A17 | B17: =IF('Mis recibos'!V17=1,IF('Mis datos'!$B$12="Lo que cobré en mano",IF(ISNUMBER('Mis recibos'!J17),'Mis recibos'!J17,""),'Mis recibos'!B17+'Mis recibos'!W17),"") | C17: =IF(AND(ISNUMBER(B17),ISNUMBER(B16)),B17/B16-1,"") | D17: =IF(AND(ISNUMBER(H17),'Mis recibos'!S17>IPC!$J$2),H17/INDEX(IPC!$D$5:$D$197,('Mis recibos'!S17-1)-IPC!$J$2+1)-1,"") | E17: =IF(AND(ISNUMBER(B17),ISNUMBER(H17)),B17*INDEX(IPC!$D$5:$D$197,(IPC!$J$3)-IPC!$J$2+1)/H17,"") | F17: =IF(AND(ISNUMBER(E17),ISNUMBER(N25)),E17/N25-1,"") | H17: =IF('Mis recibos'!S17="","",IF(OR('Mis recibos'!S17>IPC!$J$3,'Mis recibos'!S17<IPC!$J$2),"",INDEX(IPC!$D$5:$D$197,('Mis recibos'!S17)-IPC!$J$2+1))) | I17: =IF(ISNUMBER(B17),13,"") | J17: =IF(AND(ISNUMBER(B17),ISNUMBER(B16)),IF(B17>B16+0.5,13,""),"") | K17: =IF(ISNUMBER(E17),13,"") | N17: =IF(ISNUMBER(N14),N10*N14,"")
A18: ='Mis recibos'!A18 | B18: =IF('Mis recibos'!V18=1,IF('Mis datos'!$B$12="Lo que cobré en mano",IF(ISNUMBER('Mis recibos'!J18),'Mis recibos'!J18,""),'Mis recibos'!B18+'Mis recibos'!W18),"") | C18: =IF(AND(ISNUMBER(B18),ISNUMBER(B17)),B18/B17-1,"") | D18: =IF(AND(ISNUMBER(H18),'Mis recibos'!S18>IPC!$J$2),H18/INDEX(IPC!$D$5:$D$197,('Mis recibos'!S18-1)-IPC!$J$2+1)-1,"") | E18: =IF(AND(ISNUMBER(B18),ISNUMBER(H18)),B18*INDEX(IPC!$D$5:$D$197,(IPC!$J$3)-IPC!$J$2+1)/H18,"") | F18: =IF(AND(ISNUMBER(E18),ISNUMBER(N25)),E18/N25-1,"") | H18: =IF('Mis recibos'!S18="","",IF(OR('Mis recibos'!S18>IPC!$J$3,'Mis recibos'!S18<IPC!$J$2),"",INDEX(IPC!$D$5:$D$197,('Mis recibos'!S18)-IPC!$J$2+1))) | I18: =IF(ISNUMBER(B18),14,"") | J18: =IF(AND(ISNUMBER(B18),ISNUMBER(B17)),IF(B18>B17+0.5,14,""),"") | K18: =IF(ISNUMBER(E18),14,"") | N18: =IF(N5>12,N5-12,0)
A19: ='Mis recibos'!A19 | B19: =IF('Mis recibos'!V19=1,IF('Mis datos'!$B$12="Lo que cobré en mano",IF(ISNUMBER('Mis recibos'!J19),'Mis recibos'!J19,""),'Mis recibos'!B19+'Mis recibos'!W19),"") | C19: =IF(AND(ISNUMBER(B19),ISNUMBER(B18)),B19/B18-1,"") | D19: =IF(AND(ISNUMBER(H19),'Mis recibos'!S19>IPC!$J$2),H19/INDEX(IPC!$D$5:$D$197,('Mis recibos'!S19-1)-IPC!$J$2+1)-1,"") | E19: =IF(AND(ISNUMBER(B19),ISNUMBER(H19)),B19*INDEX(IPC!$D$5:$D$197,(IPC!$J$3)-IPC!$J$2+1)/H19,"") | F19: =IF(AND(ISNUMBER(E19),ISNUMBER(N25)),E19/N25-1,"") | H19: =IF('Mis recibos'!S19="","",IF(OR('Mis recibos'!S19>IPC!$J$3,'Mis recibos'!S19<IPC!$J$2),"",INDEX(IPC!$D$5:$D$197,('Mis recibos'!S19)-IPC!$J$2+1))) | I19: =IF(ISNUMBER(B19),15,"") | J19: =IF(AND(ISNUMBER(B19),ISNUMBER(B18)),IF(B19>B18+0.5,15,""),"") | K19: =IF(ISNUMBER(E19),15,"") | N19: =IF(N18>0,IF(ISNUMBER(INDEX(B5:B28,N18)),INDEX(B5:B28,N18),""),"")
A20: ='Mis recibos'!A20 | B20: =IF('Mis recibos'!V20=1,IF('Mis datos'!$B$12="Lo que cobré en mano",IF(ISNUMBER('Mis recibos'!J20),'Mis recibos'!J20,""),'Mis recibos'!B20+'Mis recibos'!W20),"") | C20: =IF(AND(ISNUMBER(B20),ISNUMBER(B19)),B20/B19-1,"") | D20: =IF(AND(ISNUMBER(H20),'Mis recibos'!S20>IPC!$J$2),H20/INDEX(IPC!$D$5:$D$197,('Mis recibos'!S20-1)-IPC!$J$2+1)-1,"") | E20: =IF(AND(ISNUMBER(B20),ISNUMBER(H20)),B20*INDEX(IPC!$D$5:$D$197,(IPC!$J$3)-IPC!$J$2+1)/H20,"") | F20: =IF(AND(ISNUMBER(E20),ISNUMBER(N25)),E20/N25-1,"") | H20: =IF('Mis recibos'!S20="","",IF(OR('Mis recibos'!S20>IPC!$J$3,'Mis recibos'!S20<IPC!$J$2),"",INDEX(IPC!$D$5:$D$197,('Mis recibos'!S20)-IPC!$J$2+1))) | I20: =IF(ISNUMBER(B20),16,"") | J20: =IF(AND(ISNUMBER(B20),ISNUMBER(B19)),IF(B20>B19+0.5,16,""),"") | K20: =IF(ISNUMBER(E20),16,"") | N20: =IF(ISNUMBER(N19),INDEX('Mis recibos'!$S$5:$S$28,N18),"")
A21: ='Mis recibos'!A21 | B21: =IF('Mis recibos'!V21=1,IF('Mis datos'!$B$12="Lo que cobré en mano",IF(ISNUMBER('Mis recibos'!J21),'Mis recibos'!J21,""),'Mis recibos'!B21+'Mis recibos'!W21),"") | C21: =IF(AND(ISNUMBER(B21),ISNUMBER(B20)),B21/B20-1,"") | D21: =IF(AND(ISNUMBER(H21),'Mis recibos'!S21>IPC!$J$2),H21/INDEX(IPC!$D$5:$D$197,('Mis recibos'!S21-1)-IPC!$J$2+1)-1,"") | E21: =IF(AND(ISNUMBER(B21),ISNUMBER(H21)),B21*INDEX(IPC!$D$5:$D$197,(IPC!$J$3)-IPC!$J$2+1)/H21,"") | F21: =IF(AND(ISNUMBER(E21),ISNUMBER(N25)),E21/N25-1,"") | H21: =IF('Mis recibos'!S21="","",IF(OR('Mis recibos'!S21>IPC!$J$3,'Mis recibos'!S21<IPC!$J$2),"",INDEX(IPC!$D$5:$D$197,('Mis recibos'!S21)-IPC!$J$2+1))) | I21: =IF(ISNUMBER(B21),17,"") | J21: =IF(AND(ISNUMBER(B21),ISNUMBER(B20)),IF(B21>B20+0.5,17,""),"") | K21: =IF(ISNUMBER(E21),17,"") | N21: =IF(ISNUMBER(N20),IF(AND(N20<=N13,N20>=IPC!$J$2),INDEX(IPC!$D$5:$D$197,(N13)-IPC!$J$2+1)/INDEX(IPC!$D$5:$D$197,(N20)-IPC!$J$2+1),""),"")
A22: ='Mis recibos'!A22 | B22: =IF('Mis recibos'!V22=1,IF('Mis datos'!$B$12="Lo que cobré en mano",IF(ISNUMBER('Mis recibos'!J22),'Mis recibos'!J22,""),'Mis recibos'!B22+'Mis recibos'!W22),"") | C22: =IF(AND(ISNUMBER(B22),ISNUMBER(B21)),B22/B21-1,"") | D22: =IF(AND(ISNUMBER(H22),'Mis recibos'!S22>IPC!$J$2),H22/INDEX(IPC!$D$5:$D$197,('Mis recibos'!S22-1)-IPC!$J$2+1)-1,"") | E22: =IF(AND(ISNUMBER(B22),ISNUMBER(H22)),B22*INDEX(IPC!$D$5:$D$197,(IPC!$J$3)-IPC!$J$2+1)/H22,"") | F22: =IF(AND(ISNUMBER(E22),ISNUMBER(N25)),E22/N25-1,"") | H22: =IF('Mis recibos'!S22="","",IF(OR('Mis recibos'!S22>IPC!$J$3,'Mis recibos'!S22<IPC!$J$2),"",INDEX(IPC!$D$5:$D$197,('Mis recibos'!S22)-IPC!$J$2+1))) | I22: =IF(ISNUMBER(B22),18,"") | J22: =IF(AND(ISNUMBER(B22),ISNUMBER(B21)),IF(B22>B21+0.5,18,""),"") | K22: =IF(ISNUMBER(E22),18,"") | N22: =IF(ISNUMBER(N19),N9/N19-1,"")
A23: ='Mis recibos'!A23 | B23: =IF('Mis recibos'!V23=1,IF('Mis datos'!$B$12="Lo que cobré en mano",IF(ISNUMBER('Mis recibos'!J23),'Mis recibos'!J23,""),'Mis recibos'!B23+'Mis recibos'!W23),"") | C23: =IF(AND(ISNUMBER(B23),ISNUMBER(B22)),B23/B22-1,"") | D23: =IF(AND(ISNUMBER(H23),'Mis recibos'!S23>IPC!$J$2),H23/INDEX(IPC!$D$5:$D$197,('Mis recibos'!S23-1)-IPC!$J$2+1)-1,"") | E23: =IF(AND(ISNUMBER(B23),ISNUMBER(H23)),B23*INDEX(IPC!$D$5:$D$197,(IPC!$J$3)-IPC!$J$2+1)/H23,"") | F23: =IF(AND(ISNUMBER(E23),ISNUMBER(N25)),E23/N25-1,"") | H23: =IF('Mis recibos'!S23="","",IF(OR('Mis recibos'!S23>IPC!$J$3,'Mis recibos'!S23<IPC!$J$2),"",INDEX(IPC!$D$5:$D$197,('Mis recibos'!S23)-IPC!$J$2+1))) | I23: =IF(ISNUMBER(B23),19,"") | J23: =IF(AND(ISNUMBER(B23),ISNUMBER(B22)),IF(B23>B22+0.5,19,""),"") | K23: =IF(ISNUMBER(E23),19,"") | N23: =IF(ISNUMBER(N21),N9/(N19*N21)-1,"")
A24: ='Mis recibos'!A24 | B24: =IF('Mis recibos'!V24=1,IF('Mis datos'!$B$12="Lo que cobré en mano",IF(ISNUMBER('Mis recibos'!J24),'Mis recibos'!J24,""),'Mis recibos'!B24+'Mis recibos'!W24),"") | C24: =IF(AND(ISNUMBER(B24),ISNUMBER(B23)),B24/B23-1,"") | D24: =IF(AND(ISNUMBER(H24),'Mis recibos'!S24>IPC!$J$2),H24/INDEX(IPC!$D$5:$D$197,('Mis recibos'!S24-1)-IPC!$J$2+1)-1,"") | E24: =IF(AND(ISNUMBER(B24),ISNUMBER(H24)),B24*INDEX(IPC!$D$5:$D$197,(IPC!$J$3)-IPC!$J$2+1)/H24,"") | F24: =IF(AND(ISNUMBER(E24),ISNUMBER(N25)),E24/N25-1,"") | H24: =IF('Mis recibos'!S24="","",IF(OR('Mis recibos'!S24>IPC!$J$3,'Mis recibos'!S24<IPC!$J$2),"",INDEX(IPC!$D$5:$D$197,('Mis recibos'!S24)-IPC!$J$2+1))) | I24: =IF(ISNUMBER(B24),20,"") | J24: =IF(AND(ISNUMBER(B24),ISNUMBER(B23)),IF(B24>B23+0.5,20,""),"") | K24: =IF(ISNUMBER(E24),20,"") | N24: =IF(COUNT(K5:K28)=0,0,MIN(K5:K28))
A25: ='Mis recibos'!A25 | B25: =IF('Mis recibos'!V25=1,IF('Mis datos'!$B$12="Lo que cobré en mano",IF(ISNUMBER('Mis recibos'!J25),'Mis recibos'!J25,""),'Mis recibos'!B25+'Mis recibos'!W25),"") | C25: =IF(AND(ISNUMBER(B25),ISNUMBER(B24)),B25/B24-1,"") | D25: =IF(AND(ISNUMBER(H25),'Mis recibos'!S25>IPC!$J$2),H25/INDEX(IPC!$D$5:$D$197,('Mis recibos'!S25-1)-IPC!$J$2+1)-1,"") | E25: =IF(AND(ISNUMBER(B25),ISNUMBER(H25)),B25*INDEX(IPC!$D$5:$D$197,(IPC!$J$3)-IPC!$J$2+1)/H25,"") | F25: =IF(AND(ISNUMBER(E25),ISNUMBER(N25)),E25/N25-1,"") | H25: =IF('Mis recibos'!S25="","",IF(OR('Mis recibos'!S25>IPC!$J$3,'Mis recibos'!S25<IPC!$J$2),"",INDEX(IPC!$D$5:$D$197,('Mis recibos'!S25)-IPC!$J$2+1))) | I25: =IF(ISNUMBER(B25),21,"") | J25: =IF(AND(ISNUMBER(B25),ISNUMBER(B24)),IF(B25>B24+0.5,21,""),"") | K25: =IF(ISNUMBER(E25),21,"") | N25: =IF(N24>0,INDEX(E5:E28,N24),"")
A26: ='Mis recibos'!A26 | B26: =IF('Mis recibos'!V26=1,IF('Mis datos'!$B$12="Lo que cobré en mano",IF(ISNUMBER('Mis recibos'!J26),'Mis recibos'!J26,""),'Mis recibos'!B26+'Mis recibos'!W26),"") | C26: =IF(AND(ISNUMBER(B26),ISNUMBER(B25)),B26/B25-1,"") | D26: =IF(AND(ISNUMBER(H26),'Mis recibos'!S26>IPC!$J$2),H26/INDEX(IPC!$D$5:$D$197,('Mis recibos'!S26-1)-IPC!$J$2+1)-1,"") | E26: =IF(AND(ISNUMBER(B26),ISNUMBER(H26)),B26*INDEX(IPC!$D$5:$D$197,(IPC!$J$3)-IPC!$J$2+1)/H26,"") | F26: =IF(AND(ISNUMBER(E26),ISNUMBER(N25)),E26/N25-1,"") | H26: =IF('Mis recibos'!S26="","",IF(OR('Mis recibos'!S26>IPC!$J$3,'Mis recibos'!S26<IPC!$J$2),"",INDEX(IPC!$D$5:$D$197,('Mis recibos'!S26)-IPC!$J$2+1))) | I26: =IF(ISNUMBER(B26),22,"") | J26: =IF(AND(ISNUMBER(B26),ISNUMBER(B25)),IF(B26>B25+0.5,22,""),"") | K26: =IF(ISNUMBER(E26),22,"") | N26: =IF(ISNUMBER(N17),ROUND(N17,0),"")
