Workbook

Sheet Instrucciones
A1: Planilla de sueldo y liquidación Uruguay 2026
A3: 1 | B3: Las celdas amarillas son para tus datos. Las verdes se calculan solas, con las fórmulas de la ley. A la derecha de cada hoja está el paso a paso de la cuenta.
A4: 2 | B4: «Sueldo líquido»: ponés tu nominal y te dice los aportes, el IRPF que te retienen y tu sueldo líquido.
A5: 3 | B5: «Aguinaldo y vacacional»: calcula la cuota de aguinaldo de junio o diciembre y el salario vacacional de tu licencia.
A6: 4 | B6: «Liquidación por egreso»: ponés tus fechas y tu sueldo, y te dice el aguinaldo, la licencia, el salario vacacional y, si te despidieron, la indemnización.
A7: 5 | B7: «Tablas oficiales» tiene cada valor oficial que usan las fórmulas, con el enlace a su fuente y la fecha en que lo verificamos. Los valores son los vigentes al 9/10/2026.
A8: 6 | B8: Cuando cambia un valor oficial, actualizamos la planilla y el mismo enlace de descarga te baja la versión nueva.
A10: Da los mismos números que las calculadoras gratuitas de calcularya.com. Antes de publicar cada versión, una verificación automática recalcula este archivo y lo compara con ellas.
A11: Es una referencia de cálculo con sus fuentes, no asesoramiento legal. Tu contrato o tu empresa pueden darte más que el mínimo de ley.
A12: Las fechas van como dd/mm/aaaa. Si tu Excel está en inglés y las lee al revés, escribilas como aaaa-mm-dd.

Sheet Sueldo líquido
A1: Sueldo líquido: montepío, Fonasa, FRL e IRPF
E3: Paso a paso
A4: TUS DATOS
A5: Sueldo nominal del mes | B5: 60000 | C5: Todo lo que cobrás antes de descuentos. Sin aguinaldo ni salario vacacional. | E5: Aportes
A6: Hijos menores de 18 a tu cargo | B6: 0 | E6: Montepío | F6: =ROUND(MIN(B5,'Tablas oficiales'!$C$5)*'Tablas oficiales'!$C$6/100,2)
A7: Hijos con discapacidad a tu cargo | B7: 0 | C7: De cualquier edad. Para el IRPF se deducen el doble que un hijo menor. | E7: Tasa de Fonasa | F7: =IF(B5>'Tablas oficiales'!$C$7*'Tablas oficiales'!$C$4,IF(B8="Sí",IF((B6+B7)>0,'Tablas oficiales'!$C$11,'Tablas oficiales'!$C$10),IF((B6+B7)>0,'Tablas oficiales'!$C$9,'Tablas oficiales'!$C$8)),IF(B8="Sí",IF((B6+B7)>0,'Tablas oficiales'!$C$15,'Tablas oficiales'!$C$14),IF((B6+B7)>0,'Tablas oficiales'!$C$13,'Tablas oficiales'!$C$12)))
A8: Tenés cónyuge o concubino a cargo en el Fonasa | B8: No | C8: Marcalo si tu pareja se atiende por tu Fonasa porque no tiene cobertura propia. | E8: Fonasa | F8: =ROUND(B5*F7/100,2)
A9: Deducción de los hijos en el IRPF | B9: La uso entera | E9: Fondo de Reconversión Laboral | F9: =ROUND(B5*'Tablas oficiales'!$C$16/100,2)
A11: TU RECIBO | E11: IRPF
A12: Sueldo nominal | B12: =B5 | E12: Renta computable (con el 6 % si pasa 10 BPC) | F12: =ROUND(IF(B5>'Tablas oficiales'!$C$17*'Tablas oficiales'!$C$4,B5+B5*'Tablas oficiales'!$C$18/100,B5),2)
A13: Aporte jubilatorio (montepío) | B13: =F6 | E13: Impuesto por la escala: tramo 1 | F13: =MAX(0,MIN(F12,'Tablas oficiales'!$C$21*'Tablas oficiales'!$C$4)-'Tablas oficiales'!$B$21*'Tablas oficiales'!$C$4)*'Tablas oficiales'!$D$21/100
A14: Fonasa | B14: =F8 | E14: Impuesto por la escala: tramo 2 | F14: =MAX(0,MIN(F12,'Tablas oficiales'!$C$22*'Tablas oficiales'!$C$4)-'Tablas oficiales'!$B$22*'Tablas oficiales'!$C$4)*'Tablas oficiales'!$D$22/100
A15: Tasa de Fonasa que te corresponde | B15: =F7 | E15: Impuesto por la escala: tramo 3 | F15: =MAX(0,MIN(F12,'Tablas oficiales'!$C$23*'Tablas oficiales'!$C$4)-'Tablas oficiales'!$B$23*'Tablas oficiales'!$C$4)*'Tablas oficiales'!$D$23/100
A16: Fondo de Reconversión Laboral | B16: =F9 | E16: Impuesto por la escala: tramo 4 | F16: =MAX(0,MIN(F12,'Tablas oficiales'!$C$24*'Tablas oficiales'!$C$4)-'Tablas oficiales'!$B$24*'Tablas oficiales'!$C$4)*'Tablas oficiales'!$D$24/100
A17: IRPF | B17: =F27 | E17: Impuesto por la escala: tramo 5 | F17: =MAX(0,MIN(F12,'Tablas oficiales'!$C$25*'Tablas oficiales'!$C$4)-'Tablas oficiales'!$B$25*'Tablas oficiales'!$C$4)*'Tablas oficiales'!$D$25/100
A18: Total de descuentos | B18: =ROUND(F6+F8+F9+F27,2) | E18: Impuesto por la escala: tramo 6 | F18: =MAX(0,MIN(F12,'Tablas oficiales'!$C$26*'Tablas oficiales'!$C$4)-'Tablas oficiales'!$B$26*'Tablas oficiales'!$C$4)*'Tablas oficiales'!$D$26/100
A19: Sueldo líquido | B19: =F28 | E19: Impuesto por la escala: tramo 7 | F19: =MAX(0,MIN(F12,'Tablas oficiales'!$C$27*'Tablas oficiales'!$C$4)-'Tablas oficiales'!$B$27*'Tablas oficiales'!$C$4)*'Tablas oficiales'!$D$27/100
E20: Impuesto por la escala: tramo 8 | F20: =MAX(0,MIN(F12,'Tablas oficiales'!$C$28*'Tablas oficiales'!$C$4)-'Tablas oficiales'!$B$28*'Tablas oficiales'!$C$4)*'Tablas oficiales'!$D$28/100
A21: Si tu nominal pasa 10 BPC, para el IRPF se le suma un 6 %, como manda el decreto de la retención. El montepío se calcula hasta el tope de aportación. | E21: Impuesto por la escala: total | F21: =SUM(F13,F14,F15,F16,F17,F18,F19,F20)
E22: Impuesto de la escala | F22: =ROUND(F21,2)
E23: Deducción por hijos del mes | F23: =ROUND((B6*'Tablas oficiales'!$C$30+B7*'Tablas oficiales'!$C$31)*'Tablas oficiales'!$C$4*IF(B9="La comparto con el otro progenitor",0.5,1)/12,2)
E24: Deducciones | F24: =ROUND(F6+F8+F9+F23,2)
E25: Tasa sobre las deducciones | F25: =IF(B5<='Tablas oficiales'!$C$32*'Tablas oficiales'!$C$4,'Tablas oficiales'!$C$33,'Tablas oficiales'!$C$34)
E26: Descuento por deducciones | F26: =ROUND(F24*F25/100,2)
E27: IRPF | F27: =MAX(0,ROUND(F22-F26,2))
E28: Sueldo líquido | F28: =ROUND(B5-F6-F8-F9-F27,2)

Sheet Aguinaldo y vacacional
A1: Aguinaldo y salario vacacional
E3: Paso a paso
A4: AGUINALDO | E4: Total cobrado en el período | F4: =ROUND(B6*B7+B8,2)
A5: Qué aguinaldo querés calcular | B5: Diciembre (de junio a noviembre)
A6: Sueldo nominal mensual | B6: 60000 | C6: Si tu sueldo cambió en el período, poné el promedio. | E6: Salario vacacional
A7: Meses trabajados en el período | B7: 6 | C7: Hasta 6. Se aceptan fracciones: medio mes es 0,5. | E7: Días extra por antigüedad | F7: =IF(B16>=5,INT(B16/4),0)
A8: Otros cobros en dinero del período | B8: 0 | C8: Horas extra, comisiones y primas que cobraste en esos meses. Si no tuviste, dejá 0. | E8: Días de licencia por año | F8: ='Tablas oficiales'!$C$35+F7
A9: Total cobrado en el período | B9: =F4 | E9: Días de licencia | F9: =ROUND(F8*B17/12,2)
A10: Aguinaldo nominal | B10: =ROUND(F4/12,2)
E11: Aportes
A12: El aguinaldo es la doceava parte de lo cobrado en el período. Es nominal: lleva aportes e IRPF. | E12: Montepío | F12: =ROUND(MIN(B15,'Tablas oficiales'!$C$5)*'Tablas oficiales'!$C$6/100,2)
E13: Tasa de Fonasa | F13: =IF(B15>'Tablas oficiales'!$C$7*'Tablas oficiales'!$C$4,IF(B19="Sí",IF((B18+0)>0,'Tablas oficiales'!$C$11,'Tablas oficiales'!$C$10),IF((B18+0)>0,'Tablas oficiales'!$C$9,'Tablas oficiales'!$C$8)),IF(B19="Sí",IF((B18+0)>0,'Tablas oficiales'!$C$15,'Tablas oficiales'!$C$14),IF((B18+0)>0,'Tablas oficiales'!$C$13,'Tablas oficiales'!$C$12)))
A14: SALARIO VACACIONAL | E14: Fonasa | F14: =ROUND(B15*F13/100,2)
A15: Sueldo nominal mensual para la licencia | B15: 60000 | C15: Si hacés horas extra, sumá el promedio mensual del año: también cuentan para la licencia. | E15: Fondo de Reconversión Laboral | F15: =ROUND(B15*'Tablas oficiales'!$C$16/100,2)
A16: Años cumplidos en la empresa | B16: 1 | C16: Desde los 5 años se suman días de licencia por antigüedad.
A17: Meses trabajados en el año que genera la licencia | B17: 12 | E17: IRPF
A18: Hijos menores de 18 a tu cargo | B18: 0 | E18: Renta computable (con el 6 % si pasa 10 BPC) | F18: =ROUND(IF(B15>'Tablas oficiales'!$C$17*'Tablas oficiales'!$C$4,B15+B15*'Tablas oficiales'!$C$18/100,B15),2)
A19: Tenés cónyuge o concubino a cargo en el Fonasa | B19: No | E19: Impuesto por la escala: tramo 1 | F19: =MAX(0,MIN(F18,'Tablas oficiales'!$C$21*'Tablas oficiales'!$C$4)-'Tablas oficiales'!$B$21*'Tablas oficiales'!$C$4)*'Tablas oficiales'!$D$21/100
A20: Días de licencia por año | B20: =F8 | E20: Impuesto por la escala: tramo 2 | F20: =MAX(0,MIN(F18,'Tablas oficiales'!$C$22*'Tablas oficiales'!$C$4)-'Tablas oficiales'!$B$22*'Tablas oficiales'!$C$4)*'Tablas oficiales'!$D$22/100
A21: Días extra por antigüedad | B21: =F7 | E21: Impuesto por la escala: tramo 3 | F21: =MAX(0,MIN(F18,'Tablas oficiales'!$C$23*'Tablas oficiales'!$C$4)-'Tablas oficiales'!$B$23*'Tablas oficiales'!$C$4)*'Tablas oficiales'!$D$23/100
A22: Días de licencia que te tocan | B22: =F9 | E22: Impuesto por la escala: tramo 4 | F22: =MAX(0,MIN(F18,'Tablas oficiales'!$C$24*'Tablas oficiales'!$C$4)-'Tablas oficiales'!$B$24*'Tablas oficiales'!$C$4)*'Tablas oficiales'!$D$24/100
A23: Jornal nominal | B23: =F35 | E23: Impuesto por la escala: tramo 5 | F23: =MAX(0,MIN(F18,'Tablas oficiales'!$C$25*'Tablas oficiales'!$C$4)-'Tablas oficiales'!$B$25*'Tablas oficiales'!$C$4)*'Tablas oficiales'!$D$25/100
A24: Pago de la licencia | B24: =ROUND(F35*F9,2) | E24: Impuesto por la escala: tramo 6 | F24: =MAX(0,MIN(F18,'Tablas oficiales'!$C$26*'Tablas oficiales'!$C$4)-'Tablas oficiales'!$B$26*'Tablas oficiales'!$C$4)*'Tablas oficiales'!$D$26/100
A25: Jornal líquido | B25: =F36 | E25: Impuesto por la escala: tramo 7 | F25: =MAX(0,MIN(F18,'Tablas oficiales'!$C$27*'Tablas oficiales'!$C$4)-'Tablas oficiales'!$B$27*'Tablas oficiales'!$C$4)*'Tablas oficiales'!$D$27/100
A26: Salario vacacional | B26: =ROUND(F36*F9*'Tablas oficiales'!$C$36/100,2) | E26: Impuesto por la escala: tramo 8 | F26: =MAX(0,MIN(F18,'Tablas oficiales'!$C$28*'Tablas oficiales'!$C$4)-'Tablas oficiales'!$B$28*'Tablas oficiales'!$C$4)*'Tablas oficiales'!$D$28/100
E27: Impuesto por la escala: total | F27: =SUM(F19,F20,F21,F22,F23,F24,F25,F26)
A28: El salario vacacional se cobra antes de salir de licencia y se calcula sobre el jornal líquido. Tu laudo o convenio puede mejorarlo. | E28: Impuesto de la escala | F28: =ROUND(F27,2)
E29: Deducción por hijos del mes | F29: =ROUND((B18*'Tablas oficiales'!$C$30+0*'Tablas oficiales'!$C$31)*'Tablas oficiales'!$C$4*IF(FALSE(),0.5,1)/12,2)
E30: Deducciones | F30: =ROUND(F12+F14+F15+F29,2)
E31: Tasa sobre las deducciones | F31: =IF(B15<='Tablas oficiales'!$C$32*'Tablas oficiales'!$C$4,'Tablas oficiales'!$C$33,'Tablas oficiales'!$C$34)
E32: Descuento por deducciones | F32: =ROUND(F30*F31/100,2)
E33: IRPF | F33: =MAX(0,ROUND(F28-F32,2))
E34: Sueldo líquido | F34: =ROUND(B15-F12-F14-F15-F33,2)
E35: Jornal nominal | F35: =ROUND(B15/30,2)
E36: Jornal líquido | F36: =ROUND(F34/30,2)

Sheet Liquidación por egreso
A1: Liquidación por egreso e indemnización por despido
E3: Paso a paso
A4: TUS DATOS
A5: Fecha de ingreso | B5: 44621 | E5: Aguinaldo del semestre en curso
A6: Último día de trabajo | B6: 46304 | E6: Empieza el período | F6: =IF(AND(MONTH(B6)>=6,MONTH(B6)<=11),DATE(YEAR(B6),6,1),IF(MONTH(B6)=12,DATE(YEAR(B6),12,1),DATE(YEAR(B6)-1,12,1)))
A7: Por qué termina el trabajo | B7: Renuncia | E7: Termina el período | F7: =IF(AND(MONTH(B6)>=6,MONTH(B6)<=11),DATE(YEAR(B6),11,30),IF(MONTH(B6)=12,DATE(YEAR(B6)+1,5,31),DATE(YEAR(B6),5,31)))
A8: Sueldo nominal mensual | B8: 60000 | C8: Si cobrás horas extra o comisiones, sumá el promedio mensual del último año. | E8: Días trabajados en el período | F8: =B6-MAX(F6,B5)+1
A9: Días de licencia de años anteriores sin gozar | B9: 0 | E9: Aguinaldo | F9: =ROUND(B8/2*F8/(F7-F6+1),2)
A10: Hijos menores de 18 a tu cargo | B10: 0
A11: Tenés cónyuge o concubino a cargo en el Fonasa | B11: No | C11: Cambia tus descuentos, y el salario vacacional se paga sobre el sueldo líquido. | E11: Licencia
E12: Días trabajados este año | F12: =B6-MAX(DATE(YEAR(B6),1,1),B5)+1
A13: TU LIQUIDACIÓN | E13: Días de licencia por año | F13: ='Tablas oficiales'!$C$35+IF(MAX(0,YEAR(B6)-YEAR(B5)-IF(OR(MONTH(B6)<MONTH(B5),AND(MONTH(B6)=MONTH(B5),DAY(B6)<DAY(B5))),1,0))>=5,INT(MAX(0,YEAR(B6)-YEAR(B5)-IF(OR(MONTH(B6)<MONTH(B5),AND(MONTH(B6)=MONTH(B5),DAY(B6)<DAY(B5))),1,0))/4),0)
A14: =IF(B6<B5,"El último día de trabajo tiene que ser posterior al ingreso.","") | E14: Días de licencia generados este año | F14: =ROUND(F13*F12/(DATE(YEAR(B6),12,31)-DATE(YEAR(B6),1,1)+1),2)
A15: Aguinaldo proporcional | B15: =F9 | E15: Días de licencia a pagar | F15: =ROUND(F14+B9,2)
A16: Días de licencia generados este año | B16: =F14
A17: Días de licencia a pagar | B17: =F15 | E17: Aportes
A18: Licencia no gozada | B18: =F43 | E18: Montepío | F18: =ROUND(MIN(B8,'Tablas oficiales'!$C$5)*'Tablas oficiales'!$C$6/100,2)
A19: Salario vacacional | B19: =F44 | E19: Tasa de Fonasa | F19: =IF(B8>'Tablas oficiales'!$C$7*'Tablas oficiales'!$C$4,IF(B11="Sí",IF((B10+0)>0,'Tablas oficiales'!$C$11,'Tablas oficiales'!$C$10),IF((B10+0)>0,'Tablas oficiales'!$C$9,'Tablas oficiales'!$C$8)),IF(B11="Sí",IF((B10+0)>0,'Tablas oficiales'!$C$15,'Tablas oficiales'!$C$14),IF((B10+0)>0,'Tablas oficiales'!$C$13,'Tablas oficiales'!$C$12)))
A20: Indemnización por despido | B20: =F55 | E20: Fonasa | F20: =ROUND(B8*F19/100,2)
A21: Total | B21: =ROUND(F9+F43+F44+F55,2) | E21: Fondo de Reconversión Laboral | F21: =ROUND(B8*'Tablas oficiales'!$C$16/100,2)
A23: Aguinaldo, licencia y salario vacacional se pagan también si renunciás. La indemnización suma a la base el aguinaldo y la licencia, como indica el MTSS. | E23: IRPF
E24: Renta computable (con el 6 % si pasa 10 BPC) | F24: =ROUND(IF(B8>'Tablas oficiales'!$C$17*'Tablas oficiales'!$C$4,B8+B8*'Tablas oficiales'!$C$18/100,B8),2)
A25: INDEMNIZACIÓN POR DESPIDO (MENSUALES Y JORNALEROS) | E25: Impuesto por la escala: tramo 1 | F25: =MAX(0,MIN(F24,'Tablas oficiales'!$C$21*'Tablas oficiales'!$C$4)-'Tablas oficiales'!$B$21*'Tablas oficiales'!$C$4)*'Tablas oficiales'!$D$21/100
A26: Cómo cobrás | B26: Mensual | E26: Impuesto por la escala: tramo 2 | F26: =MAX(0,MIN(F24,'Tablas oficiales'!$C$22*'Tablas oficiales'!$C$4)-'Tablas oficiales'!$B$22*'Tablas oficiales'!$C$4)*'Tablas oficiales'!$D$22/100
A27: Sueldo mensual o jornal | B27: 60000 | C27: Mensuales: el nominal más el promedio de horas extra y comisiones del último año. Jornaleros: el jornal del último día trabajado. | E27: Impuesto por la escala: tramo 3 | F27: =MAX(0,MIN(F24,'Tablas oficiales'!$C$23*'Tablas oficiales'!$C$4)-'Tablas oficiales'!$B$23*'Tablas oficiales'!$C$4)*'Tablas oficiales'!$D$23/100
A28: Sumar aguinaldo y licencia a la base | B28: Sí | C28: Es lo que indica el MTSS para calcular la remuneración total del mes. Solo para mensuales. | E28: Impuesto por la escala: tramo 4 | F28: =MAX(0,MIN(F24,'Tablas oficiales'!$C$24*'Tablas oficiales'!$C$4)-'Tablas oficiales'!$B$24*'Tablas oficiales'!$C$4)*'Tablas oficiales'!$D$24/100
A29: Años en los que trabajaste 240 jornales o más | B29: 0 | C29: Solo para jornaleros. | E29: Impuesto por la escala: tramo 5 | F29: =MAX(0,MIN(F24,'Tablas oficiales'!$C$25*'Tablas oficiales'!$C$4)-'Tablas oficiales'!$B$25*'Tablas oficiales'!$C$4)*'Tablas oficiales'!$D$25/100
A30: Jornales trabajados en los años que no llegaron a 240 | B30: 0 | C30: Solo para jornaleros. Incluí la fracción del último año. | E30: Impuesto por la escala: tramo 6 | F30: =MAX(0,MIN(F24,'Tablas oficiales'!$C$26*'Tablas oficiales'!$C$4)-'Tablas oficiales'!$B$26*'Tablas oficiales'!$C$4)*'Tablas oficiales'!$D$26/100
A31: Años o fracción que se indemnizan | B31: =IF(B26="Jornalero o destajista","",F59) | E31: Impuesto por la escala: tramo 7 | F31: =MAX(0,MIN(F24,'Tablas oficiales'!$C$27*'Tablas oficiales'!$C$4)-'Tablas oficiales'!$B$27*'Tablas oficiales'!$C$4)*'Tablas oficiales'!$D$27/100
A32: Sueldos de indemnización | B32: =IF(B26="Jornalero o destajista","",F60) | E32: Impuesto por la escala: tramo 8 | F32: =MAX(0,MIN(F24,'Tablas oficiales'!$C$28*'Tablas oficiales'!$C$4)-'Tablas oficiales'!$B$28*'Tablas oficiales'!$C$4)*'Tablas oficiales'!$D$28/100
A33: Remuneración total del mes | B33: =IF(B26="Jornalero o destajista","",F64) | E33: Impuesto por la escala: total | F33: =SUM(F25,F26,F27,F28,F29,F30,F31,F32)
A34: Jornales de indemnización | B34: =IF(B26="Jornalero o destajista",F70,"") | E34: Impuesto de la escala | F34: =ROUND(F33,2)
A35: Indemnización por despido | B35: =IF(B26="Jornalero o destajista",ROUND(F70*B27,2),F65) | E35: Deducción por hijos del mes | F35: =ROUND((B10*'Tablas oficiales'!$C$30+0*'Tablas oficiales'!$C$31)*'Tablas oficiales'!$C$4*IF(FALSE(),0.5,1)/12,2)
E36: Deducciones | F36: =ROUND(F18+F20+F21+F35,2)
A37: Mensuales: un sueldo por año o fracción, con tope de seis. Jornaleros: 2 jornales cada 25 trabajados, con tope de 150. La indemnización legal no paga aportes ni IRPF. | E37: Tasa sobre las deducciones | F37: =IF(B8<='Tablas oficiales'!$C$32*'Tablas oficiales'!$C$4,'Tablas oficiales'!$C$33,'Tablas oficiales'!$C$34)
E38: Descuento por deducciones | F38: =ROUND(F36*F37/100,2)
E39: IRPF | F39: =MAX(0,ROUND(F34-F38,2))
E40: Sueldo líquido | F40: =ROUND(B8-F18-F20-F21-F39,2)
E42: Licencia y salario vacacional
E43: Licencia no gozada | F43: =ROUND(B8/30*F15,2)
...

Sheet Tablas oficiales
A1: Tablas oficiales de Uruguay
A2: Son los valores que usan las fórmulas de esta planilla, vigentes al 9/10/2026. Cada uno trae el enlace a la norma o al organismo que lo publica y la fecha en que lo verificamos.
A3: Dato | B3: Detalle | C3: Valor | D3: Unidad | E3: Vigente desde | F3: Fuente oficial | G3: Verificado el
A4: Base de Prestaciones y Contribuciones (BPC) | C4: 6864 | D4: UYU | E4: 1/1/2026 | F4: https://www.impo.com.uy/bases/decretos/11-2026 | G4: 7/10/2026
A5: Tope de aportación jubilatoria (tope C, Ley 16.713) | C5: 288836 | D5: UYU | E5: 1/9/2026 | F5: https://www.bps.gub.uy/5478/valores-actuales.html | G5: 7/10/2026
A6: Aporte jubilatorio personal (montepío) | C6: 15 | D6: % | E6: 1/1/2026 | F6: https://www.bps.gub.uy/835/tasas.html | G6: 7/10/2026
A7: Fonasa: remuneración que separa las dos tablas de aporte | C7: 2.5 | D7: BPC | E7: 1/1/2026 | F7: https://www.bps.gub.uy/10314/tasas-fonasa.html | G7: 7/10/2026
A8: Aporte personal al Fonasa con remuneración de más de 2,5 BPC | B8: Sin cónyuge ni hijos | C8: 4.5 | D8: % | E8: 1/1/2026 | F8: https://www.bps.gub.uy/10314/tasas-fonasa.html | G8: 7/10/2026
A9: Aporte personal al Fonasa con remuneración de más de 2,5 BPC | B9: Con hijos | C9: 6 | D9: % | E9: 1/1/2026 | F9: https://www.bps.gub.uy/10314/tasas-fonasa.html | G9: 7/10/2026
A10: Aporte personal al Fonasa con remuneración de más de 2,5 BPC | B10: Con cónyuge | C10: 6.5 | D10: % | E10: 1/1/2026 | F10: https://www.bps.gub.uy/10314/tasas-fonasa.html | G10: 7/10/2026
A11: Aporte personal al Fonasa con remuneración de más de 2,5 BPC | B11: Con cónyuge e hijos | C11: 8 | D11: % | E11: 1/1/2026 | F11: https://www.bps.gub.uy/10314/tasas-fonasa.html | G11: 7/10/2026
A12: Aporte personal al Fonasa con remuneración de hasta 2,5 BPC | B12: Sin cónyuge ni hijos | C12: 3 | D12: % | E12: 1/1/2026 | F12: https://www.bps.gub.uy/10314/tasas-fonasa.html | G12: 7/10/2026
A13: Aporte personal al Fonasa con remuneración de hasta 2,5 BPC | B13: Con hijos | C13: 3 | D13: % | E13: 1/1/2026 | F13: https://www.bps.gub.uy/10314/tasas-fonasa.html | G13: 7/10/2026
A14: Aporte personal al Fonasa con remuneración de hasta 2,5 BPC | B14: Con cónyuge | C14: 5 | D14: % | E14: 1/1/2026 | F14: https://www.bps.gub.uy/10314/tasas-fonasa.html | G14: 7/10/2026
A15: Aporte personal al Fonasa con remuneración de hasta 2,5 BPC | B15: Con cónyuge e hijos | C15: 5 | D15: % | E15: 1/1/2026 | F15: https://www.bps.gub.uy/10314/tasas-fonasa.html | G15: 7/10/2026
A16: Fondo de Reconversión Laboral, aporte personal | C16: 0.1 | D16: % | E16: 1/1/2026 | F16: https://www.bps.gub.uy/10322/fondo-reconversion-laboral-frl.html | G16: 7/10/2026
A17: IRPF: renta mensual desde la que se aplica el incremento | C17: 10 | D17: BPC | E17: 1/1/2026 | F17: https://www.impo.com.uy/bases/decretos/148-2007/63 | G17: 7/10/2026
A18: IRPF: incremento de la renta gravada por aportes | C18: 6 | D18: % | E18: 1/1/2026 | F18: https://www.impo.com.uy/bases/decretos/148-2007/63 | G18: 7/10/2026
A19: IRPF categoría II: escala mensual de retención (en BPC) | D19: BPC | E19: 1/1/2026 | F19: https://www.impo.com.uy/bases/decretos/148-2007/63 | G19: 7/10/2026
B20: Desde | C20: Hasta | D20: Tasa % | E20: Cuota fija
B21: 0 | C21: 7 | D21: 0 | E21: 0
B22: 7 | C22: 10 | D22: 10 | E22: 0
B23: 10 | C23: 15 | D23: 15 | E23: 0
B24: 15 | C24: 30 | D24: 24 | E24: 0
B25: 30 | C25: 50 | D25: 25 | E25: 0
B26: 50 | C26: 75 | D26: 27 | E26: 0
B27: 75 | C27: 115 | D27: 31 | E27: 0
B28: 115 | C28: 1e+15 | D28: 36 | E28: 0
A30: IRPF: deducción anual por hijo menor a cargo | C30: 20 | D30: BPC | E30: 1/1/2026 | F30: https://www.impo.com.uy/bases/todgi2023/101-2024/49_T7 | G30: 7/10/2026
A31: IRPF: deducción anual por hijo con discapacidad | C31: 40 | D31: BPC | E31: 1/1/2026 | F31: https://www.impo.com.uy/bases/todgi2023/101-2024/49_T7 | G31: 7/10/2026
A32: IRPF: ingresos mensuales hasta los que las deducciones van al 14 % | C32: 15 | D32: BPC | E32: 1/1/2026 | F32: https://www.impo.com.uy/bases/decretos/148-2007/63 | G32: 7/10/2026
A33: IRPF: tasa sobre deducciones con ingresos hasta 15 BPC | C33: 14 | D33: % | E33: 1/1/2026 | F33: https://www.impo.com.uy/bases/decretos/148-2007/63 | G33: 7/10/2026
A34: IRPF: tasa sobre deducciones con ingresos de más de 15 BPC | C34: 8 | D34: % | E34: 1/1/2026 | F34: https://www.impo.com.uy/bases/decretos/148-2007/63 | G34: 7/10/2026
A35: Licencia anual mínima | C35: 20 | D35: días | E35: 1/1/2026 | F35: https://www.impo.com.uy/bases/leyes/12590-1958 | G35: 7/10/2026
A36: Salario vacacional (porcentaje del jornal líquido de licencia) | C36: 100 | D36: % | E36: 1/1/2026 | F36: https://www.impo.com.uy/bases/leyes/16101-1989/4 | G36: 7/10/2026
A37: Indemnización por despido de mensuales: tope | C37: 6 | D37: meses | E37: 1/1/2026 | F37: https://www.impo.com.uy/bases/leyes/10489-1944/4 | G37: 7/10/2026
A38: Indemnización por despido de jornaleros: jornales por año | C38: 25 | D38: días | E38: 1/1/2026 | F38: https://www.impo.com.uy/bases/leyes/10570-1944/1 | G38: 7/10/2026
A39: Indemnización por despido de jornaleros: tope | C39: 150 | D39: días | E39: 1/1/2026 | F39: https://www.gub.uy/ministerio-trabajo-seguridad-social/politicas-y-gestion/derecho-reglamentacion-laboral/derecho-laboral-uruguayo/despido-regimen-comun | G39: 7/10/2026
